Workbook
Name in_rate: Parameters!$B$4
Name in_poa: Parameters!$B$5
Name in_ppy: Parameters!$B$6
Name in_idc_method: Parameters!$B$7
Name in_timing: Parameters!$B$8
Name in_cost_dp: Parameters!$B$9
Name in_out_dp: Parameters!$B$10
Name calc_crf: Parameters!$B$11
Name out_status: 'Read me'!$B$10
Name out_changed: 'Read me'!$B$11
Name out_mismatch: 'Read me'!$B$12

Sheet Read me
A1: Utoy Creek Section 206: CE/ICA calculator
A2: Cost-effectiveness and incremental cost analysis, as live formulas.
A4: Study | B4: Utoy Creek Section 206
A5: Generated by | B5: CEICA 1.0.0 (engine 1)
A6: Project digest | B6: 082a32b302c7
A7: Discount rate | B7: 3 percent
A8: Period of analysis | B8: 50 years
A10: Status | B10: =IF(B11=0,IF(B12=0,"Unchanged: matches the CEICA export","ERROR: results differ from the export although no input changed"),"Edited: "&B11&" input cells changed since the export")
A11: Inputs changed | B11: =(SUMPRODUCT(1*(Parameters!B4:B10<>'snap Parameters'!B4:B10))+SUMPRODUCT(1*(Parameters!B14:E14<>'snap Parameters'!B14:E14))+SUMPRODUCT(1*(Benefits!F6:M36<>'snap Benefits'!F6:M36))+SUMPRODUCT(1*(Benefits!F37:M67<>'snap Benefits'!F37:M67))+SUMPRODUCT(1*(Benefits!F68:M98<>'snap Benefits'!F68:M98))+SUMPRODUCT(1*(Costs!D6:G36<>'snap Costs'!D6:G36))+SUMPRODUCT(1*(Costs!L6:L36<>'snap Costs'!L6:L36))+SUMPRODUCT(1*(OMRRR!F5:M96<>'snap OMRRR'!F5:M96))+SUMPRODUCT(1*(Sites!C5:C12<>'snap Sites'!C5:C12))+SUMPRODUCT(1*('Watershed plans'!AF12:AF267<>'snap Watershed plans'!AF12:AF267))+SUMPRODUCT(1*('Watershed summary'!K50:L89<>'snap Watershed summary'!K50:L89))+SUMPRODUCT(1*('Watershed summary'!B93:B93<>'snap Watershed summary'!B93:B93)))
A12: Results that differ from the export | B12: =(SUMPRODUCT(1*(ABS(Summary!G5:G35-'snap Summary'!G5:G35)>1e-06))+SUMPRODUCT(1*(ABS(Summary!L5:L35-'snap Summary'!L5:L35)>0.0001))+SUMPRODUCT(1*('Site CE-ICA'!L6:L9<>'snap Site CE-ICA'!L6:L9))+SUMPRODUCT(1*('Site CE-ICA'!P6:P9<>'snap Site CE-ICA'!P6:P9))+SUMPRODUCT(1*('Site CE-ICA'!L12:L15<>'snap Site CE-ICA'!L12:L15))+SUMPRODUCT(1*('Site CE-ICA'!P12:P15<>'snap Site CE-ICA'!P12:P15))+SUMPRODUCT(1*('Site CE-ICA'!L18:L21<>'snap Site CE-ICA'!L18:L21))+SUMPRODUCT(1*('Site CE-ICA'!P18:P21<>'snap Site CE-ICA'!P18:P21))+SUMPRODUCT(1*('Site CE-ICA'!L24:L27<>'snap Site CE-ICA'!L24:L27))+SUMPRODUCT(1*('Site CE-ICA'!P24:P27<>'snap Site CE-ICA'!P24:P27))+SUMPRODUCT(1*('Site CE-ICA'!L30:L33<>'snap Site CE-ICA'!L30:L33))+SUMPRODUCT(1*('Site CE-ICA'!P30:P33<>'snap Site CE-ICA'!P30:P33))+SUMPRODUCT(1*('Site CE-ICA'!L36:L39<>'snap Site CE-ICA'!L36:L39))+SUMPRODUCT(1*('Site CE-ICA'!P36:P39<>'snap Site CE-ICA'!P36:P39))+SUMPRODUCT(1*('Site CE-ICA'!L42:L45<>'snap Site CE-ICA'!L42:L45))+SUMPRODUCT(1*('Site CE-ICA'!P42:P45<>'snap Site CE-ICA'!P42:P45))+SUMPRODUCT(1*('Site CE-ICA'!L48:L50<>'snap Site CE-ICA'!L48:L50))+SUMPRODUCT(1*('Site CE-ICA'!P48:P50<>'snap Site CE-ICA'!P48:P50))+SUMPRODUCT(1*('Watershed plans'!T12:T267<>'snap Watershed plans'!T12:T267))+SUMPRODUCT(1*('Watershed plans'!X12:X267<>'snap Watershed plans'!X12:X267)))
A14: How to use
A15: - Orange cells are inputs; grey cells are formulas. Sheets are protected (password 'ceica') only to prevent accidental edits.
A16: - Change any orange cell: annualization, site CE/ICA, the watershed plans and the summary update. Changed inputs turn yellow.
A17: - To add sites, alternatives or years, make the change in CEICA and export again.
A18: - Import this workbook in CEICA to bring your changes back into the project.
A20: Legend
A21: Input
A22: Formula
A23: Changed since export

Sheet Parameters
A1: Parameters
A2: Economics and conventions. Orange cells are inputs.
A3: Parameter | B3: Value
A4: Discount rate | B4: 0.03
A5: Period of analysis (years) | B5: 50
A6: Interest during construction: periods per year | B6: 12
A7: Interest during construction: spending in each period (END, MIDDLE or START) | B7: END
A8: OMRRR discounting (END_OF_YEAR or MID_YEAR) | B8: END_OF_YEAR
A9: Cost decimals kept for CE/ICA | B9: 4
A10: Output decimals kept for CE/ICA | B10: 6
A11: Capital recovery factor | B11: =IF(in_rate=0,1/in_poa,in_rate*(1+in_rate)^in_poa/((1+in_rate)^in_poa-1))
A13: Target years | B13: Year 1 | C13: Year 2 | D13: Year 3 | E13: Year 4
A14: Years (first to last) | B14: 0 | C14: 2 | D14: 10 | E14: 50

Sheet Benefits
A1: Benefits: habitat units by module
A2: One row per module, site and alternative; the Summary adds the modules' averages. Riparian, left bank: index x quantity at each target year; Riparian, right bank: index x quantity at each target year; Instream: index x quantity at each target year. Averages are the area under straight lines between target years.
A4: Key | B4: Site | C4: Alternative | D4: Module | E4: Method | F4: Index (0 to 1) | J4: Quantity | N4: Habitat units (HU) | R4: Average (AAHU)
F5: =Parameters!$B$14 | G5: =Parameters!$C$14 | H5: =Parameters!$D$14 | I5: =Parameters!$E$14 | J5: =Parameters!$B$14 | K5: =Parameters!$C$14 | L5: =Parameters!$D$14 | M5: =Parameters!$E$14 | N5: =Parameters!$B$14 | O5: =Parameters!$C$14 | P5: =Parameters!$D$14 | Q5: =Parameters!$E$14
A6: =B6&"|"&C6 | B6: 17F2M | C6: FWOP | D6: Riparian, left bank | E6: Index x quantity | F6: 0.071111111 | G6: 0.071111111 | H6: 0.071111111 | I6: 0.071111111 | J6: 0 | K6: 0 | L6: 0 | M6: 0 | N6: =F6*J6 | O6: =G6*K6 | P6: =H6*L6 | Q6: =I6*M6 | R6: =SUMPRODUCT($O$5:$Q$5-$N$5:$P$5,(O6:Q6+N6:P6)/2)/($Q$5-$N$5)
A7: =B7&"|"&C7 | B7: 17F2M | C7: Alternative1 | D7: Riparian, left bank | E7: Index x quantity | F7: 0.071111111 | G7: 0.73333333 | H7: 0.79555556 | I7: 0.83555556 | J7: 0 | K7: 1.0806933 | L7: 1.0806933 | M7: 1.0806933 | N7: =F7*J7 | O7: =G7*K7 | P7: =H7*L7 | Q7: =I7*M7 | R7: =SUMPRODUCT($O$5:$Q$5-$N$5:$P$5,(O7:Q7+N7:P7)/2)/($Q$5-$N$5)
A8: =B8&"|"&C8 | B8: 17F2M | C8: Alternative2 | D8: Riparian, left bank | E8: Index x quantity | F8: 0.071111111 | G8: 0.66666667 | H8: 0.77777778 | I8: 0.77777778 | J8: 0 | K8: 0.38904959 | L8: 0.38904959 | M8: 0.38904959 | N8: =F8*J8 | O8: =G8*K8 | P8: =H8*L8 | Q8: =I8*M8 | R8: =SUMPRODUCT($O$5:$Q$5-$N$5:$P$5,(O8:Q8+N8:P8)/2)/($Q$5-$N$5)
A9: =B9&"|"&C9 | B9: 17F2M | C9: Alternative3 | D9: Riparian, left bank | E9: Index x quantity | F9: 0.071111111 | G9: 0.73333333 | H9: 0.79555556 | I9: 0.83555556 | J9: 0 | K9: 2.6723141 | L9: 2.6723141 | M9: 2.6723141 | N9: =F9*J9 | O9: =G9*K9 | P9: =H9*L9 | Q9: =I9*M9 | R9: =SUMPRODUCT($O$5:$Q$5-$N$5:$P$5,(O9:Q9+N9:P9)/2)/($Q$5-$N$5)
A10: =B10&"|"&C10 | B10: 17D2E | C10: FWOP | D10: Riparian, left bank | E10: Index x quantity | F10: 0.30222222 | G10: 0.30222222 | H10: 0.30222222 | I10: 0.30222222 | J10: 6.6331462 | K10: 6.6331462 | L10: 6.6331462 | M10: 6.6331462 | N10: =F10*J10 | O10: =G10*K10 | P10: =H10*L10 | Q10: =I10*M10 | R10: =SUMPRODUCT($O$5:$Q$5-$N$5:$P$5,(O10:Q10+N10:P10)/2)/($Q$5-$N$5)
A11: =B11&"|"&C11 | B11: 17D2E | C11: Alternative1 | D11: Riparian, left bank | E11: Index x quantity | F11: 0.30222222 | G11: 0.80888889 | H11: 0.90666667 | I11: 0.88 | J11: 6.6331462 | K11: 10.871323 | L11: 10.871323 | M11: 10.871323 | N11: =F11*J11 | O11: =G11*K11 | P11: =H11*L11 | Q11: =I11*M11 | R11: =SUMPRODUCT($O$5:$Q$5-$N$5:$P$5,(O11:Q11+N11:P11)/2)/($Q$5-$N$5)
A12: =B12&"|"&C12 | B12: 17D2E | C12: Alternative2 | D12: Riparian, left bank | E12: Index x quantity | F12: 0.30222222 | G12: 0.73777778 | H12: 0.80888889 | I12: 0.83111111 | J12: 6.6331462 | K12: 8.2401251 | L12: 8.2401251 | M12: 8.2401251 | N12: =F12*J12 | O12: =G12*K12 | P12: =H12*L12 | Q12: =I12*M12 | R12: =SUMPRODUCT($O$5:$Q$5-$N$5:$P$5,(O12:Q12+N12:P12)/2)/($Q$5-$N$5)
A13: =B13&"|"&C13 | B13: 17D2E | C13: Alternative3 | D13: Riparian, left bank | E13: Index x quantity | F13: 0.30222222 | G13: 0.61111111 | H13: 0.69111111 | I13: 0.69555556 | J13: 6.6331462 | K13: 6.6331462 | L13: 6.6331462 | M13: 6.6331462 | N13: =F13*J13 | O13: =G13*K13 | P13: =H13*L13 | Q13: =I13*M13 | R13: =SUMPRODUCT($O$5:$Q$5-$N$5:$P$5,(O13:Q13+N13:P13)/2)/($Q$5-$N$5)
A14: =B14&"|"&C14 | B14: 17B | C14: FWOP | D14: Riparian, left bank | E14: Index x quantity | F14: 0.72 | G14: 0.72 | H14: 0.72 | I14: 0.72 | J14: 74.757139 | K14: 74.757139 | L14: 74.757139 | M14: 74.757139 | N14: =F14*J14 | O14: =G14*K14 | P14: =H14*L14 | Q14: =I14*M14 | R14: =SUMPRODUCT($O$5:$Q$5-$N$5:$P$5,(O14:Q14+N14:P14)/2)/($Q$5-$N$5)
A15: =B15&"|"&C15 | B15: 17B | C15: Alternative1 | D15: Riparian, left bank | E15: Index x quantity | F15: 0.72 | G15: 0.80222222 | H15: 0.80666667 | I15: 0.80666667 | J15: 74.757139 | K15: 74.961879 | L15: 74.961879 | M15: 74.961879 | N15: =F15*J15 | O15: =G15*K15 | P15: =H15*L15 | Q15: =I15*M15 | R15: =SUMPRODUCT($O$5:$Q$5-$N$5:$P$5,(O15:Q15+N15:P15)/2)/($Q$5-$N$5)
A16: =B16&"|"&C16 | B16: 17B | C16: Alternative2 | D16: Riparian, left bank | E16: Index x quantity | F16: 0.72 | G16: 0.80222222 | H16: 0.82666667 | I16: 0.82666667 | J16: 74.757139 | K16: 74.961879 | L16: 74.961879 | M16: 74.961879 | N16: =F16*J16 | O16: =G16*K16 | P16: =H16*L16 | Q16: =I16*M16 | R16: =SUMPRODUCT($O$5:$Q$5-$N$5:$P$5,(O16:Q16+N16:P16)/2)/($Q$5-$N$5)
A17: =B17&"|"&C17 | B17: 17B | C17: Alternative3 | D17: Riparian, left bank | E17: Index x quantity | F17: 0.72 | G17: 0.72888889 | H17: 0.73333333 | I17: 0.73333333 | J17: 74.757139 | K17: 74.757139 | L17: 74.757139 | M17: 74.757139 | N17: =F17*J17 | O17: =G17*K17 | P17: =H17*L17 | Q17: =I17*M17 | R17: =SUMPRODUCT($O$5:$Q$5-$N$5:$P$5,(O17:Q17+N17:P17)/2)/($Q$5-$N$5)
... A98: =B98&"|"&C98 | B98: 19A | C98: Alternative3 | D98: Instream | E98: Index x quantity | F98: 0.57923284 | G98: 0.70839951 | H98: 0.70839951 | I98: 0.70839951 | J98: 5.6340055 | K98: 12.337803 | L98: 12.337803 | M98: 12.337803 | N98: =F98*J98 | O98: =G98*K98 | P98: =H98*L98 | Q98: =I98*M98 | R98: =SUMPRODUCT($O$5:$Q$5-$N$5:$P$5,(O98:Q98+N98:P98)/2)/($Q$5-$N$5)

Sheet Costs
A1: Costs: first costs, interest during construction and OMRRR
A2: First costs are base-year lump sums. Interest during construction accrues on the categories marked *, spent evenly over the construction months.
N3: Average annual cost by part
A4: Key | B4: Site | C4: Alternative | D4: Construction * | E4: Monitoring | F4: Adaptive management | G4: Construction months | H4: IDC base | I4: Interest during construction | J4: OMRRR present value | K4: Total present value | L4: Average annual cost entered | M4: Average annual cost | N4: Construction | O4: Monitoring | P4: Adaptive management | Q4: Interest during construction | R4: OMRRR
D5: construction | E5: monitoring | F5: adaptive_management
A6: =B6&"|"&C6 | B6: 17F2M | C6: FWOP | D6: 0 | E6: 0 | F6: 0 | G6: 0 | H6: =D6 | I6: =IF(OR(G6=0,in_rate=0,H6=0),0,H6/G6*(IF(in_idc_method="START",1+((1+in_rate)^(1/in_ppy)-1),IF(in_idc_method="MIDDLE",1+((1+in_rate)^(1/in_ppy)-1)/2,1))*((1+in_rate)^(G6/in_ppy)-1)/((1+in_rate)^(1/in_ppy)-1)-G6)) | J6: =SUMIFS(OMRRR!$S$5:$S$96,OMRRR!$A$5:$A$96,A6) | K6: =SUM(D6:F6)+I6+J6 | M6: =IF(ISNUMBER(L6),L6,calc_crf*K6) | N6: =calc_crf*D6 | O6: =calc_crf*E6 | P6: =calc_crf*F6 | Q6: =calc_crf*I6 | R6: =calc_crf*J6
A7: =B7&"|"&C7 | B7: 17F2M | C7: Alternative1 | D7: 776047 | E7: 60000 | F7: 77605 | G7: 10 | H7: =D7 | I7: =IF(OR(G7=0,in_rate=0,H7=0),0,H7/G7*(IF(in_idc_method="START",1+((1+in_rate)^(1/in_ppy)-1),IF(in_idc_method="MIDDLE",1+((1+in_rate)^(1/in_ppy)-1)/2,1))*((1+in_rate)^(G7/in_ppy)-1)/((1+in_rate)^(1/in_ppy)-1)-G7)) | J7: =SUMIFS(OMRRR!$S$5:$S$96,OMRRR!$A$5:$A$96,A7) | K7: =SUM(D7:F7)+I7+J7 | M7: =IF(ISNUMBER(L7),L7,calc_crf*K7) | N7: =calc_crf*D7 | O7: =calc_crf*E7 | P7: =calc_crf*F7 | Q7: =calc_crf*I7 | R7: =calc_crf*J7
A8: =B8&"|"&C8 | B8: 17F2M | C8: Alternative2 | D8: 691092 | E8: 56000 | F8: 69109 | G8: 9 | H8: =D8 | I8: =IF(OR(G8=0,in_rate=0,H8=0),0,H8/G8*(IF(in_idc_method="START",1+((1+in_rate)^(1/in_ppy)-1),IF(in_idc_method="MIDDLE",1+((1+in_rate)^(1/in_ppy)-1)/2,1))*((1+in_rate)^(G8/in_ppy)-1)/((1+in_rate)^(1/in_ppy)-1)-G8)) | J8: =SUMIFS(OMRRR!$S$5:$S$96,OMRRR!$A$5:$A$96,A8) | K8: =SUM(D8:F8)+I8+J8 | M8: =IF(ISNUMBER(L8),L8,calc_crf*K8) | N8: =calc_crf*D8 | O8: =calc_crf*E8 | P8: =calc_crf*F8 | Q8: =calc_crf*I8 | R8: =calc_crf*J8
A9: =B9&"|"&C9 | B9: 17F2M | C9: Alternative3 | D9: 798779 | E9: 48000 | F9: 79878 | G9: 11 | H9: =D9 | I9: =IF(OR(G9=0,in_rate=0,H9=0),0,H9/G9*(IF(in_idc_method="START",1+((1+in_rate)^(1/in_ppy)-1),IF(in_idc_method="MIDDLE",1+((1+in_rate)^(1/in_ppy)-1)/2,1))*((1+in_rate)^(G9/in_ppy)-1)/((1+in_rate)^(1/in_ppy)-1)-G9)) | J9: =SUMIFS(OMRRR!$S$5:$S$96,OMRRR!$A$5:$A$96,A9) | K9: =SUM(D9:F9)+I9+J9 | M9: =IF(ISNUMBER(L9),L9,calc_crf*K9) | N9: =calc_crf*D9 | O9: =calc_crf*E9 | P9: =calc_crf*F9 | Q9: =calc_crf*I9 | R9: =calc_crf*J9
A10: =B10&"|"&C10 | B10: 17D2E | C10: FWOP | D10: 0 | E10: 0 | F10: 0 | G10: 0 | H10: =D10 | I10: =IF(OR(G10=0,in_rate=0,H10=0),0,H10/G10*(IF(in_idc_method="START",1+((1+in_rate)^(1/in_ppy)-1),IF(in_idc_method="MIDDLE",1+((1+in_rate)^(1/in_ppy)-1)/2,1))*((1+in_rate)^(G10/in_ppy)-1)/((1+in_rate)^(1/in_ppy)-1)-G10)) | J10: =SUMIFS(OMRRR!$S$5:$S$96,OMRRR!$A$5:$A$96,A10) | K10: =SUM(D10:F10)+I10+J10 | M10: =IF(ISNUMBER(L10),L10,calc_crf*K10) | N10: =calc_crf*D10 | O10: =calc_crf*E10 | P10: =calc_crf*F10 | Q10: =calc_crf*I10 | R10: =calc_crf*J10
A11: =B11&"|"&C11 | B11: 17D2E | C11: Alternative1 | D11: 1070854 | E11: 48000 | F11: 160628 | G11: 14 | H11: =D11 | I11: =IF(OR(G11=0,in_rate=0,H11=0),0,H11/G11*(IF(in_idc_method="START",1+((1+in_rate)^(1/in_ppy)-1),IF(in_idc_method="MIDDLE",1+((1+in_rate)^(1/in_ppy)-1)/2,1))*((1+in_rate)^(G11/in_ppy)-1)/((1+in_rate)^(1/in_ppy)-1)-G11)) | J11: =SUMIFS(OMRRR!$S$5:$S$96,OMRRR!$A$5:$A$96,A11) | K11: =SUM(D11:F11)+I11+J11 | M11: =IF(ISNUMBER(L11),L11,calc_crf*K11) | N11: =calc_crf*D11 | O11: =calc_crf*E11 | P11: =calc_crf*F11 | Q11: =calc_crf*I11 | R11: =calc_crf*J11
A12: =B12&"|"&C12 | B12: 17D2E | C12: Alternative2 | D12: 1065670 | E12: 48000 | F12: 106567 | G12: 14 | H12: =D12 | I12: =IF(OR(G12=0,in_rate=0,H12=0),0,H12/G12*(IF(in_idc_method="START",1+((1+in_rate)^(1/in_ppy)-1),IF(in_idc_method="MIDDLE",1+((1+in_rate)^(1/in_ppy)-1)/2,1))*((1+in_rate)^(G12/in_ppy)-1)/((1+in_rate)^(1/in_ppy)-1)-G12)) | J12: =SUMIFS(OMRRR!$S$5:$S$96,OMRRR!$A$5:$A$96,A12) | K12: =SUM(D12:F12)+I12+J12 | M12: =IF(ISNUMBER(L12),L12,calc_crf*K12) | N12: =calc_crf*D12 | O12: =calc_crf*E12 | P12: =calc_crf*F12 | Q12: =calc_crf*I12 | R12: =calc_crf*J12
A13: =B13&"|"&C13 | B13: 17D2E | C13: Alternative3 | D13: 276233 | E13: 48000 | F13: 27623 | G13: 2 | H13: =D13 | I13: =IF(OR(G13=0,in_rate=0,H13=0),0,H13/G13*(IF(in_idc_method="START",1+((1+in_rate)^(1/in_ppy)-1),IF(in_idc_method="MIDDLE",1+((1+in_rate)^(1/in_ppy)-1)/2,1))*((1+in_rate)^(G13/in_ppy)-1)/((1+in_rate)^(1/in_ppy)-1)-G13)) | J13: =SUMIFS(OMRRR!$S$5:$S$96,OMRRR!$A$5:$A$96,A13) | K13: =SUM(D13:F13)+I13+J13 | M13: =IF(ISNUMBER(L13),L13,calc_crf*K13) | N13: =calc_crf*D13 | O13: =calc_crf*E13 | P13: =calc_crf*F13 | Q13: =calc_crf*I13 | R13: =calc_crf*J13
A14: =B14&"|"&C14 | B14: 17B | C14: FWOP | D14: 0 | E14: 0 | F14: 0 | G14: 0 | H14: =D14 | I14: =IF(OR(G14=0,in_rate=0,H14=0),0,H14/G14*(IF(in_idc_method="START",1+((1+in_rate)^(1/in_ppy)-1),IF(in_idc_method="MIDDLE",1+((1+in_rate)^(1/in_ppy)-1)/2,1))*((1+in_rate)^(G14/in_ppy)-1)/((1+in_rate)^(1/in_ppy)-1)-G14)) | J14: =SUMIFS(OMRRR!$S$5:$S$96,OMRRR!$A$5:$A$96,A14) | K14: =SUM(D14:F14)+I14+J14 | M14: =IF(ISNUMBER(L14),L14,calc_crf*K14) | N14: =calc_crf*D14 | O14: =calc_crf*E14 | P14: =calc_crf*F14 | Q14: =calc_crf*I14 | R14: =calc_crf*J14
A15: =B15&"|"&C15 | B15: 17B | C15: Alternative1 | D15: 1002697 | E15: 48000 | F15: 150405 | G15: 12 | H15: =D15 | I15: =IF(OR(G15=0,in_rate=0,H15=0),0,H15/G15*(IF(in_idc_method="START",1+((1+in_rate)^(1/in_ppy)-1),IF(in_idc_method="MIDDLE",1+((1+in_rate)^(1/in_ppy)-1)/2,1))*((1+in_rate)^(G15/in_ppy)-1)/((1+in_rate)^(1/in_ppy)-1)-G15)) | J15: =SUMIFS(OMRRR!$S$5:$S$96,OMRRR!$A$5:$A$96,A15) | K15: =SUM(D15:F15)+I15+J15 | M15: =IF(ISNUMBER(L15),L15,calc_crf*K15) | N15: =calc_crf*D15 | O15: =calc_crf*E15 | P15: =calc_crf*F15 | Q15: =calc_crf*I15 | R15: =calc_crf*J15
A16: =B16&"|"&C16 | B16: 17B | C16: Alternative2 | D16: 880983 | E16: 48000 | F16: 132147 | G16: 12 | H16: =D16 | I16: =IF(OR(G16=0,in_rate=0,H16=0),0,H16/G16*(IF(in_idc_method="START",1+((1+in_rate)^(1/in_ppy)-1),IF(in_idc_method="MIDDLE",1+((1+in_rate)^(1/in_ppy)-1)/2,1))*((1+in_rate)^(G16/in_ppy)-1)/((1+in_rate)^(1/in_ppy)-1)-G16)) | J16: =SUMIFS(OMRRR!$S$5:$S$96,OMRRR!$A$5:$A$96,A16) | K16: =SUM(D16:F16)+I16+J16 | M16: =IF(ISNUMBER(L16),L16,calc_crf*K16) | N16: =calc_crf*D16 | O16: =calc_crf*E16 | P16: =calc_crf*F16 | Q16: =calc_crf*I16 | R16: =calc_crf*J16
A17: =B17&"|"&C17 | B17: 17B | C17: Alternative3 | D17: 257611 | E17: 48000 | F17: 38642 | G17: 2 | H17: =D17 | I17: =IF(OR(G17=0,in_rate=0,H17=0),0,H17/G17*(IF(in_idc_method="START",1+((1+in_rate)^(1/in_ppy)-1),IF(in_idc_method="MIDDLE",1+((1+in_rate)^(1/in_ppy)-1)/2,1))*((1+in_rate)^(G17/in_ppy)-1)/((1+in_rate)^(1/in_ppy)-1)-G17)) | J17: =SUMIFS(OMRRR!$S$5:$S$96,OMRRR!$A$5:$A$96,A17) | K17: =SUM(D17:F17)+I17+J17 | M17: =IF(ISNUMBER(L17),L17,calc_crf*K17) | N17: =calc_crf*D17 | O17: =calc_crf*E17 | P17: =calc_crf*F17 | Q17: =calc_crf*I17 | R17: =calc_crf*J17
... A36: =B36&"|"&C36 | B36: 19A | C36: Alternative3 | D36: 228693 | E36: 48000 | F36: 45739 | G36: 3 | H36: =D36 | I36: =IF(OR(G36=0,in_rate=0,H36=0),0,H36/G36*(IF(in_idc_method="START",1+((1+in_rate)^(1/in_ppy)-1),IF(in_idc_method="MIDDLE",1+((1+in_rate)^(1/in_ppy)-1)/2,1))*((1+in_rate)^(G36/in_ppy)-1)/((1+in_rate)^(1/in_ppy)-1)-G36)) | J36: =SUMIFS(OMRRR!$S$5:$S$96,OMRRR!$A$5:$A$96,A36) | K36: =SUM(D36:F36)+I36+J36 | M36: =IF(ISNUMBER(L36),L36,calc_crf*K36) | N36: =calc_crf*D36 | O36: =calc_crf*E36 | P36: =calc_crf*F36 | Q36: =calc_crf*I36 | R36: =calc_crf*J36

Sheet OMRRR
A1: OMRRR: recurring operation, maintenance, repair, replacement and rehabilitation
A2: Each item costs the amount per occurrence every N years from the first year to the last (blank: every N years through the period of analysis). Basis: FIXED amount, PERCENT of a first-cost category, or RATE x quantity.
A4: Key | B4: Site | C4: Alternative | D4: Item | E4: Basis | F4: Amount | G4: Percent | H4: Category | I4: Unit rate | J4: Quantity | K4: Every N years | L4: First year | M4: Last year | N4: Amount per occurrence | O4: First | P4: Last | Q4: Occurrences | R4: Present value, end of year | S4: Present value
A5: =B5&"|"&C5 | B5: 17F2M | C5: Alternative1 | D5: General maintenance | E5: FIXED | F5: 10000 | K5: 1 | N5: =IF(E5="FIXED",F5,IF(E5="PERCENT",G5*IFERROR(INDEX(Costs!$D$6:$F$36,MATCH(A5,Costs!$A$6:$A$36,0),MATCH(H5,Costs!$D$5:$F$5,0)),0),I5*J5)) | O5: =IF(ISNUMBER(L5),L5,K5) | P5: =IF(ISNUMBER(M5),MIN(M5,in_poa),in_poa) | Q5: =IF(P5<O5,0,INT((P5-O5)/K5)+1) | R5: =IF(Q5=0,0,IF(in_rate=0,N5*Q5,N5*(1+in_rate)^(-O5)*(1-(1+in_rate)^(-K5*Q5))/(1-(1+in_rate)^(-K5)))) | S5: =IF(in_timing="MID_YEAR",IF(O5=0,IF(Q5=0,0,N5+(R5-N5)*(1+in_rate)^0.5),R5*(1+in_rate)^0.5),R5)
A6: =B6&"|"&C6 | B6: 17F2M | C6: Alternative1 | D6: Inspection and trash removal | E6: RATE | I6: 4 | J6: 2639.11 | K6: 2 | N6: =IF(E6="FIXED",F6,IF(E6="PERCENT",G6*IFERROR(INDEX(Costs!$D$6:$F$36,MATCH(A6,Costs!$A$6:$A$36,0),MATCH(H6,Costs!$D$5:$F$5,0)),0),I6*J6)) | O6: =IF(ISNUMBER(L6),L6,K6) | P6: =IF(ISNUMBER(M6),MIN(M6,in_poa),in_poa) | Q6: =IF(P6<O6,0,INT((P6-O6)/K6)+1) | R6: =IF(Q6=0,0,IF(in_rate=0,N6*Q6,N6*(1+in_rate)^(-O6)*(1-(1+in_rate)^(-K6*Q6))/(1-(1+in_rate)^(-K6)))) | S6: =IF(in_timing="MID_YEAR",IF(O6=0,IF(Q6=0,0,N6+(R6-N6)*(1+in_rate)^0.5),R6*(1+in_rate)^0.5),R6)
A7: =B7&"|"&C7 | B7: 17F2M | C7: Alternative1 | D7: Invasive species control | E7: FIXED | F7: 15000 | K7: 10 | N7: =IF(E7="FIXED",F7,IF(E7="PERCENT",G7*IFERROR(INDEX(Costs!$D$6:$F$36,MATCH(A7,Costs!$A$6:$A$36,0),MATCH(H7,Costs!$D$5:$F$5,0)),0),I7*J7)) | O7: =IF(ISNUMBER(L7),L7,K7) | P7: =IF(ISNUMBER(M7),MIN(M7,in_poa),in_poa) | Q7: =IF(P7<O7,0,INT((P7-O7)/K7)+1) | R7: =IF(Q7=0,0,IF(in_rate=0,N7*Q7,N7*(1+in_rate)^(-O7)*(1-(1+in_rate)^(-K7*Q7))/(1-(1+in_rate)^(-K7)))) | S7: =IF(in_timing="MID_YEAR",IF(O7=0,IF(Q7=0,0,N7+(R7-N7)*(1+in_rate)^0.5),R7*(1+in_rate)^0.5),R7)
A8: =B8&"|"&C8 | B8: 17F2M | C8: Alternative1 | D8: Wood, rock and earth repair | E8: PERCENT | G8: 0.1 | H8: construction | K8: 25 | N8: =IF(E8="FIXED",F8,IF(E8="PERCENT",G8*IFERROR(INDEX(Costs!$D$6:$F$36,MATCH(A8,Costs!$A$6:$A$36,0),MATCH(H8,Costs!$D$5:$F$5,0)),0),I8*J8)) | O8: =IF(ISNUMBER(L8),L8,K8) | P8: =IF(ISNUMBER(M8),MIN(M8,in_poa),in_poa) | Q8: =IF(P8<O8,0,INT((P8-O8)/K8)+1) | R8: =IF(Q8=0,0,IF(in_rate=0,N8*Q8,N8*(1+in_rate)^(-O8)*(1-(1+in_rate)^(-K8*Q8))/(1-(1+in_rate)^(-K8)))) | S8: =IF(in_timing="MID_YEAR",IF(O8=0,IF(Q8=0,0,N8+(R8-N8)*(1+in_rate)^0.5),R8*(1+in_rate)^0.5),R8)
A9: =B9&"|"&C9 | B9: 17F2M | C9: Alternative2 | D9: General maintenance | E9: FIXED | F9: 10000 | K9: 1 | N9: =IF(E9="FIXED",F9,IF(E9="PERCENT",G9*IFERROR(INDEX(Costs!$D$6:$F$36,MATCH(A9,Costs!$A$6:$A$36,0),MATCH(H9,Costs!$D$5:$F$5,0)),0),I9*J9)) | O9: =IF(ISNUMBER(L9),L9,K9) | P9: =IF(ISNUMBER(M9),MIN(M9,in_poa),in_poa) | Q9: =IF(P9<O9,0,INT((P9-O9)/K9)+1) | R9: =IF(Q9=0,0,IF(in_rate=0,N9*Q9,N9*(1+in_rate)^(-O9)*(1-(1+in_rate)^(-K9*Q9))/(1-(1+in_rate)^(-K9)))) | S9: =IF(in_timing="MID_YEAR",IF(O9=0,IF(Q9=0,0,N9+(R9-N9)*(1+in_rate)^0.5),R9*(1+in_rate)^0.5),R9)
A10: =B10&"|"&C10 | B10: 17F2M | C10: Alternative2 | D10: Inspection and trash removal | E10: RATE | I10: 4 | J10: 2378.1542 | K10: 2 | N10: =IF(E10="FIXED",F10,IF(E10="PERCENT",G10*IFERROR(INDEX(Costs!$D$6:$F$36,MATCH(A10,Costs!$A$6:$A$36,0),MATCH(H10,Costs!$D$5:$F$5,0)),0),I10*J10)) | O10: =IF(ISNUMBER(L10),L10,K10) | P10: =IF(ISNUMBER(M10),MIN(M10,in_poa),in_poa) | Q10: =IF(P10<O10,0,INT((P10-O10)/K10)+1) | R10: =IF(Q10=0,0,IF(in_rate=0,N10*Q10,N10*(1+in_rate)^(-O10)*(1-(1+in_rate)^(-K10*Q10))/(1-(1+in_rate)^(-K10)))) | S10: =IF(in_timing="MID_YEAR",IF(O10=0,IF(Q10=0,0,N10+(R10-N10)*(1+in_rate)^0.5),R10*(1+in_rate)^0.5),R10)
A11: =B11&"|"&C11 | B11: 17F2M | C11: Alternative2 | D11: Invasive species control | E11: FIXED | F11: 15000 | K11: 10 | N11: =IF(E11="FIXED",F11,IF(E11="PERCENT",G11*IFERROR(INDEX(Costs!$D$6:$F$36,MATCH(A11,Costs!$A$6:$A$36,0),MATCH(H11,Costs!$D$5:$F$5,0)),0),I11*J11)) | O11: =IF(ISNUMBER(L11),L11,K11) | P11: =IF(ISNUMBER(M11),MIN(M11,in_poa),in_poa) | Q11: =IF(P11<O11,0,INT((P11-O11)/K11)+1) | R11: =IF(Q11=0,0,IF(in_rate=0,N11*Q11,N11*(1+in_rate)^(-O11)*(1-(1+in_rate)^(-K11*Q11))/(1-(1+in_rate)^(-K11)))) | S11: =IF(in_timing="MID_YEAR",IF(O11=0,IF(Q11=0,0,N11+(R11-N11)*(1+in_rate)^0.5),R11*(1+in_rate)^0.5),R11)
A12: =B12&"|"&C12 | B12: 17F2M | C12: Alternative2 | D12: Wood, rock and earth repair | E12: PERCENT | G12: 0.1 | H12: construction | K12: 25 | N12: =IF(E12="FIXED",F12,IF(E12="PERCENT",G12*IFERROR(INDEX(Costs!$D$6:$F$36,MATCH(A12,Costs!$A$6:$A$36,0),MATCH(H12,Costs!$D$5:$F$5,0)),0),I12*J12)) | O12: =IF(ISNUMBER(L12),L12,K12) | P12: =IF(ISNUMBER(M12),MIN(M12,in_poa),in_poa) | Q12: =IF(P12<O12,0,INT((P12-O12)/K12)+1) | R12: =IF(Q12=0,0,IF(in_rate=0,N12*Q12,N12*(1+in_rate)^(-O12)*(1-(1+in_rate)^(-K12*Q12))/(1-(1+in_rate)^(-K12)))) | S12: =IF(in_timing="MID_YEAR",IF(O12=0,IF(Q12=0,0,N12+(R12-N12)*(1+in_rate)^0.5),R12*(1+in_rate)^0.5),R12)
A13: =B13&"|"&C13 | B13: 17F2M | C13: Alternative3 | D13: General maintenance | E13: FIXED | F13: 10000 | K13: 1 | N13: =IF(E13="FIXED",F13,IF(E13="PERCENT",G13*IFERROR(INDEX(Costs!$D$6:$F$36,MATCH(A13,Costs!$A$6:$A$36,0),MATCH(H13,Costs!$D$5:$F$5,0)),0),I13*J13)) | O13: =IF(ISNUMBER(L13),L13,K13) | P13: =IF(ISNUMBER(M13),MIN(M13,in_poa),in_poa) | Q13: =IF(P13<O13,0,INT((P13-O13)/K13)+1) | R13: =IF(Q13=0,0,IF(in_rate=0,N13*Q13,N13*(1+in_rate)^(-O13)*(1-(1+in_rate)^(-K13*Q13))/(1-(1+in_rate)^(-K13)))) | S13: =IF(in_timing="MID_YEAR",IF(O13=0,IF(Q13=0,0,N13+(R13-N13)*(1+in_rate)^0.5),R13*(1+in_rate)^0.5),R13)
A14: =B14&"|"&C14 | B14: 17F2M | C14: Alternative3 | D14: Inspection and trash removal | E14: RATE | I14: 4 | J14: 2639.11 | K14: 2 | N14: =IF(E14="FIXED",F14,IF(E14="PERCENT",G14*IFERROR(INDEX(Costs!$D$6:$F$36,MATCH(A14,Costs!$A$6:$A$36,0),MATCH(H14,Costs!$D$5:$F$5,0)),0),I14*J14)) | O14: =IF(ISNUMBER(L14),L14,K14) | P14: =IF(ISNUMBER(M14),MIN(M14,in_poa),in_poa) | Q14: =IF(P14<O14,0,INT((P14-O14)/K14)+1) | R14: =IF(Q14=0,0,IF(in_rate=0,N14*Q14,N14*(1+in_rate)^(-O14)*(1-(1+in_rate)^(-K14*Q14))/(1-(1+in_rate)^(-K14)))) | S14: =IF(in_timing="MID_YEAR",IF(O14=0,IF(Q14=0,0,N14+(R14-N14)*(1+in_rate)^0.5),R14*(1+in_rate)^0.5),R14)
A15: =B15&"|"&C15 | B15: 17F2M | C15: Alternative3 | D15: Invasive species control | E15: FIXED | F15: 15000 | K15: 10 | N15: =IF(E15="FIXED",F15,IF(E15="PERCENT",G15*IFERROR(INDEX(Costs!$D$6:$F$36,MATCH(A15,Costs!$A$6:$A$36,0),MATCH(H15,Costs!$D$5:$F$5,0)),0),I15*J15)) | O15: =IF(ISNUMBER(L15),L15,K15) | P15: =IF(ISNUMBER(M15),MIN(M15,in_poa),in_poa) | Q15: =IF(P15<O15,0,INT((P15-O15)/K15)+1) | R15: =IF(Q15=0,0,IF(in_rate=0,N15*Q15,N15*(1+in_rate)^(-O15)*(1-(1+in_rate)^(-K15*Q15))/(1-(1+in_rate)^(-K15)))) | S15: =IF(in_timing="MID_YEAR",IF(O15=0,IF(Q15=0,0,N15+(R15-N15)*(1+in_rate)^0.5),R15*(1+in_rate)^0.5),R15)
A16: =B16&"|"&C16 | B16: 17F2M | C16: Alternative3 | D16: Wood, rock and earth repair | E16: PERCENT | G16: 0.1 | H16: construction | K16: 25 | N16: =IF(E16="FIXED",F16,IF(E16="PERCENT",G16*IFERROR(INDEX(Costs!$D$6:$F$36,MATCH(A16,Costs!$A$6:$A$36,0),MATCH(H16,Costs!$D$5:$F$5,0)),0),I16*J16)) | O16: =IF(ISNUMBER(L16),L16,K16) | P16: =IF(ISNUMBER(M16),MIN(M16,in_poa),in_poa) | Q16: =IF(P16<O16,0,INT((P16-O16)/K16)+1) | R16: =IF(Q16=0,0,IF(in_rate=0,N16*Q16,N16*(1+in_rate)^(-O16)*(1-(1+in_rate)^(-K16*Q16))/(1-(1+in_rate)^(-K16)))) | S16: =IF(in_timing="MID_YEAR",IF(O16=0,IF(Q16=0,0,N16+(R16-N16)*(1+in_rate)^0.5),R16*(1+in_rate)^0.5),R16)
A17: =B17&"|"&C17 | B17: 17D2E | C17: Alternative1 | D17: General maintenance | E17: FIXED | F17: 10000 | K17: 1 | N17: =IF(E17="FIXED",F17,IF(E17="PERCENT",G17*IFERROR(INDEX(Costs!$D$6:$F$36,MATCH(A17,Costs!$A$6:$A$36,0),MATCH(H17,Costs!$D$5:$F$5,0)),0),I17*J17)) | O17: =IF(ISNUMBER(L17),L17,K17) | P17: =IF(ISNUMBER(M17),MIN(M17,in_poa),in_poa) | Q17: =IF(P17<O17,0,INT((P17-O17)/K17)+1) | R17: =IF(Q17=0,0,IF(in_rate=0,N17*Q17,N17*(1+in_rate)^(-O17)*(1-(1+in_rate)^(-K17*Q17))/(1-(1+in_rate)^(-K17)))) | S17: =IF(in_timing="MID_YEAR",IF(O17=0,IF(Q17=0,0,N17+(R17-N17)*(1+in_rate)^0.5),R17*(1+in_rate)^0.5),R17)
A18: =B18&"|"&C18 | B18: 17D2E | C18: Alternative1 | D18: Inspection and trash removal | E18: RATE | I18: 4 | J18: 3610.5749 | K18: 2 | N18: =IF(E18="FIXED",F18,IF(E18="PERCENT",G18*IFERROR(INDEX(Costs!$D$6:$F$36,MATCH(A18,Costs!$A$6:$A$36,0),MATCH(H18,Costs!$D$5:$F$5,0)),0),I18*J18)) | O18: =IF(ISNUMBER(L18),L18,K18) | P18: =IF(ISNUMBER(M18),MIN(M18,in_poa),in_poa) | Q18: =IF(P18<O18,0,INT((P18-O18)/K18)+1) | R18: =IF(Q18=0,0,IF(in_rate=0,N18*Q18,N18*(1+in_rate)^(-O18)*(1-(1+in_rate)^(-K18*Q18))/(1-(1+in_rate)^(-K18)))) | S18: =IF(in_timing="MID_YEAR",IF(O18=0,IF(Q18=0,0,N18+(R18-N18)*(1+in_rate)^0.5),R18*(1+in_rate)^0.5),R18)
A19: =B19&"|"&C19 | B19: 17D2E | C19: Alternative1 | D19: Invasive species control | E19: FIXED | F19: 15000 | K19: 10 | N19: =IF(E19="FIXED",F19,IF(E19="PERCENT",G19*IFERROR(INDEX(Costs!$D$6:$F$36,MATCH(A19,Costs!$A$6:$A$36,0),MATCH(H19,Costs!$D$5:$F$5,0)),0),I19*J19)) | O19: =IF(ISNUMBER(L19),L19,K19) | P19: =IF(ISNUMBER(M19),MIN(M19,in_poa),in_poa) | Q19: =IF(P19<O19,0,INT((P19-O19)/K19)+1) | R19: =IF(Q19=0,0,IF(in_rate=0,N19*Q19,N19*(1+in_rate)^(-O19)*(1-(1+in_rate)^(-K19*Q19))/(1-(1+in_rate)^(-K19)))) | S19: =IF(in_timing="MID_YEAR",IF(O19=0,IF(Q19=0,0,N19+(R19-N19)*(1+in_rate)^0.5),R19*(1+in_rate)^0.5),R19)
A20: =B20&"|"&C20 | B20: 17D2E | C20: Alternative1 | D20: Wood, rock and earth repair | E20: PERCENT | G20: 0.1 | H20: construction | K20: 25 | N20: =IF(E20="FIXED",F20,IF(E20="PERCENT",G20*IFERROR(INDEX(Costs!$D$6:$F$36,MATCH(A20,Costs!$A$6:$A$36,0),MATCH(H20,Costs!$D$5:$F$5,0)),0),I20*J20)) | O20: =IF(ISNUMBER(L20),L20,K20) | P20: =IF(ISNUMBER(M20),MIN(M20,in_poa),in_poa) | Q20: =IF(P20<O20,0,INT((P20-O20)/K20)+1) | R20: =IF(Q20=0,0,IF(in_rate=0,N20*Q20,N20*(1+in_rate)^(-O20)*(1-(1+in_rate)^(-K20*Q20))/(1-(1+in_rate)^(-K20)))) | S20: =IF(in_timing="MID_YEAR",IF(O20=0,IF(Q20=0,0,N20+(R20-N20)*(1+in_rate)^0.5),R20*(1+in_rate)^0.5),R20)
A21: =B21&"|"&C21 | B21: 17D2E | C21: Alternative2 | D21: General maintenance | E21: FIXED | F21: 10000 | K21: 1 | N21: =IF(E21="FIXED",F21,IF(E21="PERCENT",G21*IFERROR(INDEX(Costs!$D$6:$F$36,MATCH(A21,Costs!$A$6:$A$36,0),MATCH(H21,Costs!$D$5:$F$5,0)),0),I21*J21)) | O21: =IF(ISNUMBER(L21),L21,K21) | P21: =IF(ISNUMBER(M21),MIN(M21,in_poa),in_poa) | Q21: =IF(P21<O21,0,INT((P21-O21)/K21)+1) | R21: =IF(Q21=0,0,IF(in_rate=0,N21*Q21,N21*(1+in_rate)^(-O21)*(1-(1+in_rate)^(-K21*Q21))/(1-(1+in_rate)^(-K21)))) | S21: =IF(in_timing="MID_YEAR",IF(O21=0,IF(Q21=0,0,N21+(R21-N21)*(1+in_rate)^0.5),R21*(1+in_rate)^0.5),R21)
A22: =B22&"|"&C22 | B22: 17D2E | C22: Alternative2 | D22: Inspection and trash removal | E22: RATE | I22: 4 | J22: 3610.5749 | K22: 2 | N22: =IF(E22="FIXED",F22,IF(E22="PERCENT",G22*IFERROR(INDEX(Costs!$D$6:$F$36,MATCH(A22,Costs!$A$6:$A$36,0),MATCH(H22,Costs!$D$5:$F$5,0)),0),I22*J22)) | O22: =IF(ISNUMBER(L22),L22,K22) | P22: =IF(ISNUMBER(M22),MIN(M22,in_poa),in_poa) | Q22: =IF(P22<O22,0,INT((P22-O22)/K22)+1) | R22: =IF(Q22=0,0,IF(in_rate=0,N22*Q22,N22*(1+in_rate)^(-O22)*(1-(1+in_rate)^(-K22*Q22))/(1-(1+in_rate)^(-K22)))) | S22: =IF(in_timing="MID_YEAR",IF(O22=0,IF(Q22=0,0,N22+(R22-N22)*(1+in_rate)^0.5),R22*(1+in_rate)^0.5),R22)
A23: =B23&"|"&C23 | B23: 17D2E | C23: Alternative2 | D23: Invasive species control | E23: FIXED | F23: 15000 | K23: 10 | N23: =IF(E23="FIXED",F23,IF(E23="PERCENT",G23*IFERROR(INDEX(Costs!$D$6:$F$36,MATCH(A23,Costs!$A$6:$A$36,0),MATCH(H23,Costs!$D$5:$F$5,0)),0),I23*J23)) | O23: =IF(ISNUMBER(L23),L23,K23) | P23: =IF(ISNUMBER(M23),MIN(M23,in_poa),in_poa) | Q23: =IF(P23<O23,0,INT((P23-O23)/K23)+1) | R23: =IF(Q23=0,0,IF(in_rate=0,N23*Q23,N23*(1+in_rate)^(-O23)*(1-(1+in_rate)^(-K23*Q23))/(1-(1+in_rate)^(-K23)))) | S23: =IF(in_timing="MID_YEAR",IF(O23=0,IF(Q23=0,0,N23+(R23-N23)*(1+in_rate)^0.5),R23*(1+in_rate)^0.5),R23)
A24: =B24&"|"&C24 | B24: 17D2E | C24: Alternative2 | D24: Wood, rock and earth repair | E24: PERCENT | G24: 0.1 | H24: construction | K24: 25 | N24: =IF(E24="FIXED",F24,IF(E24="PERCENT",G24*IFERROR(INDEX(Costs!$D$6:$F$36,MATCH(A24,Costs!$A$6:$A$36,0),MATCH(H24,Costs!$D$5:$F$5,0)),0),I24*J24)) | O24: =IF(ISNUMBER(L24),L24,K24) | P24: =IF(ISNUMBER(M24),MIN(M24,in_poa),in_poa) | Q24: =IF(P24<O24,0,INT((P24-O24)/K24)+1) | R24: =IF(Q24=0,0,IF(in_rate=0,N24*Q24,N24*(1+in_rate)^(-O24)*(1-(1+in_rate)^(-K24*Q24))/(1-(1+in_rate)^(-K24)))) | S24: =IF(in_timing="MID_YEAR",IF(O24=0,IF(Q24=0,0,N24+(R24-N24)*(1+in_rate)^0.5),R24*(1+in_rate)^0.5),R24)
A25: =B25&"|"&C25 | B25: 17D2E | C25: Alternative3 | D25: General maintenance | E25: FIXED | F25: 10000 | K25: 1 | N25: =IF(E25="FIXED",F25,IF(E25="PERCENT",G25*IFERROR(INDEX(Costs!$D$6:$F$36,MATCH(A25,Costs!$A$6:$A$36,0),MATCH(H25,Costs!$D$5:$F$5,0)),0),I25*J25)) | O25: =IF(ISNUMBER(L25),L25,K25) | P25: =IF(ISNUMBER(M25),MIN(M25,in_poa),in_poa) | Q25: =IF(P25<O25,0,INT((P25-O25)/K25)+1) | R25: =IF(Q25=0,0,IF(in_rate=0,N25*Q25,N25*(1+in_rate)^(-O25)*(1-(1+in_rate)^(-K25*Q25))/(1-(1+in_rate)^(-K25)))) | S25: =IF(in_timing="MID_YEAR",IF(O25=0,IF(Q25=0,0,N25+(R25-N25)*(1+in_rate)^0.5),R25*(1+in_rate)^0.5),R25)
A26: =B26&"|"&C26 | B26: 17D2E | C26: Alternative3 | D26: Inspection and trash removal | E26: RATE | I26: 4 | J26: 3610.5749 | K26: 2 | N26: =IF(E26="FIXED",F26,IF(E26="PERCENT",G26*IFERROR(INDEX(Costs!$D$6:$F$36,MATCH(A26,Costs!$A$6:$A$36,0),MATCH(H26,Costs!$D$5:$F$5,0)),0),I26*J26)) | O26: =IF(ISNUMBER(L26),L26,K26) | P26: =IF(ISNUMBER(M26),MIN(M26,in_poa),in_poa) | Q26: =IF(P26<O26,0,INT((P26-O26)/K26)+1) | R26: =IF(Q26=0,0,IF(in_rate=0,N26*Q26,N26*(1+in_rate)^(-O26)*(1-(1+in_rate)^(-K26*Q26))/(1-(1+in_rate)^(-K26)))) | S26: =IF(in_timing="MID_YEAR",IF(O26=0,IF(Q26=0,0,N26+(R26-N26)*(1+in_rate)^0.5),R26*(1+in_rate)^0.5),R26)
A27: =B27&"|"&C27 | B27: 17D2E | C27: Alternative3 | D27: Invasive species control | E27: FIXED | F27: 15000 | K27: 10 | N27: =IF(E27="FIXED",F27,IF(E27="PERCENT",G27*IFERROR(INDEX(Costs!$D$6:$F$36,MATCH(A27,Costs!$A$6:$A$36,0),MATCH(H27,Costs!$D$5:$F$5,0)),0),I27*J27)) | O27: =IF(ISNUMBER(L27),L27,K27) | P27: =IF(ISNUMBER(M27),MIN(M27,in_poa),in_poa) | Q27: =IF(P27<O27,0,INT((P27-O27)/K27)+1) | R27: =IF(Q27=0,0,IF(in_rate=0,N27*Q27,N27*(1+in_rate)^(-O27)*(1-(1+in_rate)^(-K27*Q27))/(1-(1+in_rate)^(-K27)))) | S27: =IF(in_timing="MID_YEAR",IF(O27=0,IF(Q27=0,0,N27+(R27-N27)*(1+in_rate)^0.5),R27*(1+in_rate)^0.5),R27)
A28: =B28&"|"&C28 | B28: 17D2E | C28: Alternative3 | D28: Wood, rock and earth repair | E28: PERCENT | G28: 0.1 | H28: construction | K28: 25 | N28: =IF(E28="FIXED",F28,IF(E28="PERCENT",G28*IFERROR(INDEX(Costs!$D$6:$F$36,MATCH(A28,Costs!$A$6:$A$36,0),MATCH(H28,Costs!$D$5:$F$5,0)),0),I28*J28)) | O28: =IF(ISNUMBER(L28),L28,K28) | P28: =IF(ISNUMBER(M28),MIN(M28,in_poa),in_poa) | Q28: =IF(P28<O28,0,INT((P28-O28)/K28)+1) | R28: =IF(Q28=0,0,IF(in_rate=0,N28*Q28,N28*(1+in_rate)^(-O28)*(1-(1+in_rate)^(-K28*Q28))/(1-(1+in_rate)^(-K28)))) | S28: =IF(in_timing="MID_YEAR",IF(O28=0,IF(Q28=0,0,N28+(R28-N28)*(1+in_rate)^0.5),R28*(1+in_rate)^0.5),R28)
A29: =B29&"|"&C29 | B29: 17B | C29: Alternative1 | D29: General maintenance | E29: FIXED | F29: 10000 | K29: 1 | N29: =IF(E29="FIXED",F29,IF(E29="PERCENT",G29*IFERROR(INDEX(Costs!$D$6:$F$36,MATCH(A29,Costs!$A$6:$A$36,0),MATCH(H29,Costs!$D$5:$F$5,0)),0),I29*J29)) | O29: =IF(ISNUMBER(L29),L29,K29) | P29: =IF(ISNUMBER(M29),MIN(M29,in_poa),in_poa) | Q29: =IF(P29<O29,0,INT((P29-O29)/K29)+1) | R29: =IF(Q29=0,0,IF(in_rate=0,N29*Q29,N29*(1+in_rate)^(-O29)*(1-(1+in_rate)^(-K29*Q29))/(1-(1+in_rate)^(-K29)))) | S29: =IF(in_timing="MID_YEAR",IF(O29=0,IF(Q29=0,0,N29+(R29-N29)*(1+in_rate)^0.5),R29*(1+in_rate)^0.5),R29)
A30: =B30&"|"&C30 | B30: 17B | C30: Alternative1 | D30: Inspection and trash removal | E30: RATE | I30: 4 | J30: 6461.9861 | K30: 2 | N30: =IF(E30="FIXED",F30,IF(E30="PERCENT",G30*IFERROR(INDEX(Costs!$D$6:$F$36,MATCH(A30,Costs!$A$6:$A$36,0),MATCH(H30,Costs!$D$5:$F$5,0)),0),I30*J30)) | O30: =IF(ISNUMBER(L30),L30,K30) | P30: =IF(ISNUMBER(M30),MIN(M30,in_poa),in_poa) | Q30: =IF(P30<O30,0,INT((P30-O30)/K30)+1) | R30: =IF(Q30=0,0,IF(in_rate=0,N30*Q30,N30*(1+in_rate)^(-O30)*(1-(1+in_rate)^(-K30*Q30))/(1-(1+in_rate)^(-K30)))) | S30: =IF(in_timing="MID_YEAR",IF(O30=0,IF(Q30=0,0,N30+(R30-N30)*(1+in_rate)^0.5),R30*(1+in_rate)^0.5),R30)
A31: =B31&"|"&C31 | B31: 17B | C31: Alternative1 | D31: Invasive species control | E31: FIXED | F31: 15000 | K31: 10 | N31: =IF(E31="FIXED",F31,IF(E31="PERCENT",G31*IFERROR(INDEX(Costs!$D$6:$F$36,MATCH(A31,Costs!$A$6:$A$36,0),MATCH(H31,Costs!$D$5:$F$5,0)),0),I31*J31)) | O31: =IF(ISNUMBER(L31),L31,K31) | P31: =IF(ISNUMBER(M31),MIN(M31,in_poa),in_poa) | Q31: =IF(P31<O31,0,INT((P31-O31)/K31)+1) | R31: =IF(Q31=0,0,IF(in_rate=0,N31*Q31,N31*(1+in_rate)^(-O31)*(1-(1+in_rate)^(-K31*Q31))/(1-(1+in_rate)^(-K31)))) | S31: =IF(in_timing="MID_YEAR",IF(O31=0,IF(Q31=0,0,N31+(R31-N31)*(1+in_rate)^0.5),R31*(1+in_rate)^0.5),R31)
A32: =B32&"|"&C32 | B32: 17B | C32: Alternative1 | D32: Wood, rock and earth repair | E32: PERCENT | G32: 0.1 | H32: construction | K32: 25 | N32: =IF(E32="FIXED",F32,IF(E32="PERCENT",G32*IFERROR(INDEX(Costs!$D$6:$F$36,MATCH(A32,Costs!$A$6:$A$36,0),MATCH(H32,Costs!$D$5:$F$5,0)),0),I32*J32)) | O32: =IF(ISNUMBER(L32),L32,K32) | P32: =IF(ISNUMBER(M32),MIN(M32,in_poa),in_poa) | Q32: =IF(P32<O32,0,INT((P32-O32)/K32)+1) | R32: =IF(Q32=0,0,IF(in_rate=0,N32*Q32,N32*(1+in_rate)^(-O32)*(1-(1+in_rate)^(-K32*Q32))/(1-(1+in_rate)^(-K32)))) | S32: =IF(in_timing="MID_YEAR",IF(O32=0,IF(Q32=0,0,N32+(R32-N32)*(1+in_rate)^0.5),R32*(1+in_rate)^0.5),R32)
A33: =B33&"|"&C33 | B33: 17B | C33: Alternative2 | D33: General maintenance | E33: FIXED | F33: 10000 | K33: 1 | N33: =IF(E33="FIXED",F33,IF(E33="PERCENT",G33*IFERROR(INDEX(Costs!$D$6:$F$36,MATCH(A33,Costs!$A$6:$A$36,0),MATCH(H33,Costs!$D$5:$F$5,0)),0),I33*J33)) | O33: =IF(ISNUMBER(L33),L33,K33) | P33: =IF(ISNUMBER(M33),MIN(M33,in_poa),in_poa) | Q33: =IF(P33<O33,0,INT((P33-O33)/K33)+1) | R33: =IF(Q33=0,0,IF(in_rate=0,N33*Q33,N33*(1+in_rate)^(-O33)*(1-(1+in_rate)^(-K33*Q33))/(1-(1+in_rate)^(-K33)))) | S33: =IF(in_timing="MID_YEAR",IF(O33=0,IF(Q33=0,0,N33+(R33-N33)*(1+in_rate)^0.5),R33*(1+in_rate)^0.5),R33)
A34: =B34&"|"&C34 | B34: 17B | C34: Alternative2 | D34: Inspection and trash removal | E34: RATE | I34: 4 | J34: 6461.9861 | K34: 2 | N34: =IF(E34="FIXED",F34,IF(E34="PERCENT",G34*IFERROR(INDEX(Costs!$D$6:$F$36,MATCH(A34,Costs!$A$6:$A$36,0),MATCH(H34,Costs!$D$5:$F$5,0)),0),I34*J34)) | O34: =IF(ISNUMBER(L34),L34,K34) | P34: =IF(ISNUMBER(M34),MIN(M34,in_poa),in_poa) | Q34: =IF(P34<O34,0,INT((P34-O34)/K34)+1) | R34: =IF(Q34=0,0,IF(in_rate=0,N34*Q34,N34*(1+in_rate)^(-O34)*(1-(1+in_rate)^(-K34*Q34))/(1-(1+in_rate)^(-K34)))) | S34: =IF(in_timing="MID_YEAR",IF(O34=0,IF(Q34=0,0,N34+(R34-N34)*(1+in_rate)^0.5),R34*(1+in_rate)^0.5),R34)
A35: =B35&"|"&C35 | B35: 17B | C35: Alternative2 | D35: Invasive species control | E35: FIXED | F35: 15000 | K35: 10 | N35: =IF(E35="FIXED",F35,IF(E35="PERCENT",G35*IFERROR(INDEX(Costs!$D$6:$F$36,MATCH(A35,Costs!$A$6:$A$36,0),MATCH(H35,Costs!$D$5:$F$5,0)),0),I35*J35)) | O35: =IF(ISNUMBER(L35),L35,K35) | P35: =IF(ISNUMBER(M35),MIN(M35,in_poa),in_poa) | Q35: =IF(P35<O35,0,INT((P35-O35)/K35)+1) | R35: =IF(Q35=0,0,IF(in_rate=0,N35*Q35,N35*(1+in_rate)^(-O35)*(1-(1+in_rate)^(-K35*Q35))/(1-(1+in_rate)^(-K35)))) | S35: =IF(in_timing="MID_YEAR",IF(O35=0,IF(Q35=0,0,N35+(R35-N35)*(1+in_rate)^0.5),R35*(1+in_rate)^0.5),R35)
A36: =B36&"|"&C36 | B36: 17B | C36: Alternative2 | D36: Wood, rock and earth repair | E36: PERCENT | G36: 0.1 | H36: construction | K36: 25 | N36: =IF(E36="FIXED",F36,IF(E36="PERCENT",G36*IFERROR(INDEX(Costs!$D$6:$F$36,MATCH(A36,Costs!$A$6:$A$36,0),MATCH(H36,Costs!$D$5:$F$5,0)),0),I36*J36)) | O36: =IF(ISNUMBER(L36),L36,K36) | P36: =IF(ISNUMBER(M36),MIN(M36,in_poa),in_poa) | Q36: =IF(P36<O36,0,INT((P36-O36)/K36)+1) | R36: =IF(Q36=0,0,IF(in_rate=0,N36*Q36,N36*(1+in_rate)^(-O36)*(1-(1+in_rate)^(-K36*Q36))/(1-(1+in_rate)^(-K36)))) | S36: =IF(in_timing="MID_YEAR",IF(O36=0,IF(Q36=0,0,N36+(R36-N36)*(1+in_rate)^0.5),R36*(1+in_rate)^0.5),R36)
A37: =B37&"|"&C37 | B37: 17B | C37: Alternative3 | D37: General maintenance | E37: FIXED | F37: 10000 | K37: 1 | N37: =IF(E37="FIXED",F37,IF(E37="PERCENT",G37*IFERROR(INDEX(Costs!$D$6:$F$36,MATCH(A37,Costs!$A$6:$A$36,0),MATCH(H37,Costs!$D$5:$F$5,0)),0),I37*J37)) | O37: =IF(ISNUMBER(L37),L37,K37) | P37: =IF(ISNUMBER(M37),MIN(M37,in_poa),in_poa) | Q37: =IF(P37<O37,0,INT((P37-O37)/K37)+1) | R37: =IF(Q37=0,0,IF(in_rate=0,N37*Q37,N37*(1+in_rate)^(-O37)*(1-(1+in_rate)^(-K37*Q37))/(1-(1+in_rate)^(-K37)))) | S37: =IF(in_timing="MID_YEAR",IF(O37=0,IF(Q37=0,0,N37+(R37-N37)*(1+in_rate)^0.5),R37*(1+in_rate)^0.5),R37)
A38: =B38&"|"&C38 | B38: 17B | C38: Alternative3 | D38: Inspection and trash removal | E38: RATE | I38: 4 | J38: 6461.9861 | K38: 2 | N38: =IF(E38="FIXED",F38,IF(E38="PERCENT",G38*IFERROR(INDEX(Costs!$D$6:$F$36,MATCH(A38,Costs!$A$6:$A$36,0),MATCH(H38,Costs!$D$5:$F$5,0)),0),I38*J38)) | O38: =IF(ISNUMBER(L38),L38,K38) | P38: =IF(ISNUMBER(M38),MIN(M38,in_poa),in_poa) | Q38: =IF(P38<O38,0,INT((P38-O38)/K38)+1) | R38: =IF(Q38=0,0,IF(in_rate=0,N38*Q38,N38*(1+in_rate)^(-O38)*(1-(1+in_rate)^(-K38*Q38))/(1-(1+in_rate)^(-K38)))) | S38: =IF(in_timing="MID_YEAR",IF(O38=0,IF(Q38=0,0,N38+(R38-N38)*(1+in_rate)^0.5),R38*(1+in_rate)^0.5),R38)
A39: =B39&"|"&C39 | B39: 17B | C39: Alternative3 | D39: Invasive species control | E39: FIXED | F39: 15000 | K39: 10 | N39: =IF(E39="FIXED",F39,IF(E39="PERCENT",G39*IFERROR(INDEX(Costs!$D$6:$F$36,MATCH(A39,Costs!$A$6:$A$36,0),MATCH(H39,Costs!$D$5:$F$5,0)),0),I39*J39)) | O39: =IF(ISNUMBER(L39),L39,K39) | P39: =IF(ISNUMBER(M39),MIN(M39,in_poa),in_poa) | Q39: =IF(P39<O39,0,INT((P39-O39)/K39)+1) | R39: =IF(Q39=0,0,IF(in_rate=0,N39*Q39,N39*(1+in_rate)^(-O39)*(1-(1+in_rate)^(-K39*Q39))/(1-(1+in_rate)^(-K39)))) | S39: =IF(in_timing="MID_YEAR",IF(O39=0,IF(Q39=0,0,N39+(R39-N39)*(1+in_rate)^0.5),R39*(1+in_rate)^0.5),R39)
A40: =B40&"|"&C40 | B40: 17B | C40: Alternative3 | D40: Wood, rock and earth repair | E40: PERCENT | G40: 0.1 | H40: construction | K40: 25 | N40: =IF(E40="FIXED",F40,IF(E40="PERCENT",G40*IFERROR(INDEX(Costs!$D$6:$F$36,MATCH(A40,Costs!$A$6:$A$36,0),MATCH(H40,Costs!$D$5:$F$5,0)),0),I40*J40)) | O40: =IF(ISNUMBER(L40),L40,K40) | P40: =IF(ISNUMBER(M40),MIN(M40,in_poa),in_poa) | Q40: =IF(P40<O40,0,INT((P40-O40)/K40)+1) | R40: =IF(Q40=0,0,IF(in_rate=0,N40*Q40,N40*(1+in_rate)^(-O40)*(1-(1+in_rate)^(-K40*Q40))/(1-(1+in_rate)^(-K40)))) | S40: =IF(in_timing="MID_YEAR",IF(O40=0,IF(Q40=0,0,N40+(R40-N40)*(1+in_rate)^0.5),R40*(1+in_rate)^0.5),R40)
A41: =B41&"|"&C41 | B41: 2A | C41: Alternative1 | D41: General maintenance | E41: FIXED | F41: 10000 | K41: 1 | N41: =IF(E41="FIXED",F41,IF(E41="PERCENT",G41*IFERROR(INDEX(Costs!$D$6:$F$36,MATCH(A41,Costs!$A$6:$A$36,0),MATCH(H41,Costs!$D$5:$F$5,0)),0),I41*J41)) | O41: =IF(ISNUMBER(L41),L41,K41) | P41: =IF(ISNUMBER(M41),MIN(M41,in_poa),in_poa) | Q41: =IF(P41<O41,0,INT((P41-O41)/K41)+1) | R41: =IF(Q41=0,0,IF(in_rate=0,N41*Q41,N41*(1+in_rate)^(-O41)*(1-(1+in_rate)^(-K41*Q41))/(1-(1+in_rate)^(-K41)))) | S41: =IF(in_timing="MID_YEAR",IF(O41=0,IF(Q41=0,0,N41+(R41-N41)*(1+in_rate)^0.5),R41*(1+in_rate)^0.5),R41)
...

Sheet Summary
A1: Summary of inputs to CE/ICA
A2: Lift is each alternative's AAHU above No Action; the CE/ICA cost is its average annual cost above No Action.
A4: Key | B4: Site | C4: Alternative | D4: Name | E4: No Action | F4: Outputs (AAHU) | G4: Lift (AAHU) | H4: Construction cost | I4: First costs | J4: Interest during construction | K4: OMRRR present value | L4: Average annual cost | M4: Cost above No Action | N4: Unit cost ($/AAHU)
A5: =B5&"|"&C5 | B5: 17F2M | C5: FWOP | D5: No Action | E5: 1 | F5: =SUMIFS(Benefits!$R$6:$R$98,Benefits!$A$6:$A$98,A5) | G5: =F5-$F$5 | H5: =Costs!D6 | I5: =SUM(Costs!D6:F6) | J5: =Costs!I6 | K5: =Costs!J6 | L5: =Costs!M6 | M5: =L5-$L$5 | N5: =IF(G5>0,M5/G5,"n/a")
A6: =B6&"|"&C6 | B6: 17F2M | C6: Alternative1 | D6: Alternative 1 | E6: 0 | F6: =SUMIFS(Benefits!$R$6:$R$98,Benefits!$A$6:$A$98,A6) | G6: =F6-$F$5 | H6: =Costs!D7 | I6: =SUM(Costs!D7:F7) | J6: =Costs!I7 | K6: =Costs!J7 | L6: =Costs!M7 | M6: =L6-$L$5 | N6: =IF(G6>0,M6/G6,"n/a")
A7: =B7&"|"&C7 | B7: 17F2M | C7: Alternative2 | D7: Alternative 2 | E7: 0 | F7: =SUMIFS(Benefits!$R$6:$R$98,Benefits!$A$6:$A$98,A7) | G7: =F7-$F$5 | H7: =Costs!D8 | I7: =SUM(Costs!D8:F8) | J7: =Costs!I8 | K7: =Costs!J8 | L7: =Costs!M8 | M7: =L7-$L$5 | N7: =IF(G7>0,M7/G7,"n/a")
A8: =B8&"|"&C8 | B8: 17F2M | C8: Alternative3 | D8: Alternative 3 | E8: 0 | F8: =SUMIFS(Benefits!$R$6:$R$98,Benefits!$A$6:$A$98,A8) | G8: =F8-$F$5 | H8: =Costs!D9 | I8: =SUM(Costs!D9:F9) | J8: =Costs!I9 | K8: =Costs!J9 | L8: =Costs!M9 | M8: =L8-$L$5 | N8: =IF(G8>0,M8/G8,"n/a")
A9: =B9&"|"&C9 | B9: 17D2E | C9: FWOP | D9: No Action | E9: 1 | F9: =SUMIFS(Benefits!$R$6:$R$98,Benefits!$A$6:$A$98,A9) | G9: =F9-$F$9 | H9: =Costs!D10 | I9: =SUM(Costs!D10:F10) | J9: =Costs!I10 | K9: =Costs!J10 | L9: =Costs!M10 | M9: =L9-$L$9 | N9: =IF(G9>0,M9/G9,"n/a")
A10: =B10&"|"&C10 | B10: 17D2E | C10: Alternative1 | D10: Alternative 1 | E10: 0 | F10: =SUMIFS(Benefits!$R$6:$R$98,Benefits!$A$6:$A$98,A10) | G10: =F10-$F$9 | H10: =Costs!D11 | I10: =SUM(Costs!D11:F11) | J10: =Costs!I11 | K10: =Costs!J11 | L10: =Costs!M11 | M10: =L10-$L$9 | N10: =IF(G10>0,M10/G10,"n/a")
A11: =B11&"|"&C11 | B11: 17D2E | C11: Alternative2 | D11: Alternative 2 | E11: 0 | F11: =SUMIFS(Benefits!$R$6:$R$98,Benefits!$A$6:$A$98,A11) | G11: =F11-$F$9 | H11: =Costs!D12 | I11: =SUM(Costs!D12:F12) | J11: =Costs!I12 | K11: =Costs!J12 | L11: =Costs!M12 | M11: =L11-$L$9 | N11: =IF(G11>0,M11/G11,"n/a")
A12: =B12&"|"&C12 | B12: 17D2E | C12: Alternative3 | D12: Alternative 3 | E12: 0 | F12: =SUMIFS(Benefits!$R$6:$R$98,Benefits!$A$6:$A$98,A12) | G12: =F12-$F$9 | H12: =Costs!D13 | I12: =SUM(Costs!D13:F13) | J12: =Costs!I13 | K12: =Costs!J13 | L12: =Costs!M13 | M12: =L12-$L$9 | N12: =IF(G12>0,M12/G12,"n/a")
A13: =B13&"|"&C13 | B13: 17B | C13: FWOP | D13: No Action | E13: 1 | F13: =SUMIFS(Benefits!$R$6:$R$98,Benefits!$A$6:$A$98,A13) | G13: =F13-$F$13 | H13: =Costs!D14 | I13: =SUM(Costs!D14:F14) | J13: =Costs!I14 | K13: =Costs!J14 | L13: =Costs!M14 | M13: =L13-$L$13 | N13: =IF(G13>0,M13/G13,"n/a")
A14: =B14&"|"&C14 | B14: 17B | C14: Alternative1 | D14: Alternative 1 | E14: 0 | F14: =SUMIFS(Benefits!$R$6:$R$98,Benefits!$A$6:$A$98,A14) | G14: =F14-$F$13 | H14: =Costs!D15 | I14: =SUM(Costs!D15:F15) | J14: =Costs!I15 | K14: =Costs!J15 | L14: =Costs!M15 | M14: =L14-$L$13 | N14: =IF(G14>0,M14/G14,"n/a")
A15: =B15&"|"&C15 | B15: 17B | C15: Alternative2 | D15: Alternative 2 | E15: 0 | F15: =SUMIFS(Benefits!$R$6:$R$98,Benefits!$A$6:$A$98,A15) | G15: =F15-$F$13 | H15: =Costs!D16 | I15: =SUM(Costs!D16:F16) | J15: =Costs!I16 | K15: =Costs!J16 | L15: =Costs!M16 | M15: =L15-$L$13 | N15: =IF(G15>0,M15/G15,"n/a")
A16: =B16&"|"&C16 | B16: 17B | C16: Alternative3 | D16: Alternative 3 | E16: 0 | F16: =SUMIFS(Benefits!$R$6:$R$98,Benefits!$A$6:$A$98,A16) | G16: =F16-$F$13 | H16: =Costs!D17 | I16: =SUM(Costs!D17:F17) | J16: =Costs!I17 | K16: =Costs!J17 | L16: =Costs!M17 | M16: =L16-$L$13 | N16: =IF(G16>0,M16/G16,"n/a")
A17: =B17&"|"&C17 | B17: 2A | C17: FWOP | D17: No Action | E17: 1 | F17: =SUMIFS(Benefits!$R$6:$R$98,Benefits!$A$6:$A$98,A17) | G17: =F17-$F$17 | H17: =Costs!D18 | I17: =SUM(Costs!D18:F18) | J17: =Costs!I18 | K17: =Costs!J18 | L17: =Costs!M18 | M17: =L17-$L$17 | N17: =IF(G17>0,M17/G17,"n/a")
A18: =B18&"|"&C18 | B18: 2A | C18: Alternative1 | D18: Alternative 1 | E18: 0 | F18: =SUMIFS(Benefits!$R$6:$R$98,Benefits!$A$6:$A$98,A18) | G18: =F18-$F$17 | H18: =Costs!D19 | I18: =SUM(Costs!D19:F19) | J18: =Costs!I19 | K18: =Costs!J19 | L18: =Costs!M19 | M18: =L18-$L$17 | N18: =IF(G18>0,M18/G18,"n/a")
A19: =B19&"|"&C19 | B19: 2A | C19: Alternative2 | D19: Alternative 2 | E19: 0 | F19: =SUMIFS(Benefits!$R$6:$R$98,Benefits!$A$6:$A$98,A19) | G19: =F19-$F$17 | H19: =Costs!D20 | I19: =SUM(Costs!D20:F20) | J19: =Costs!I20 | K19: =Costs!J20 | L19: =Costs!M20 | M19: =L19-$L$17 | N19: =IF(G19>0,M19/G19,"n/a")
A20: =B20&"|"&C20 | B20: 2A | C20: Alternative3 | D20: Alternative 3 | E20: 0 | F20: =SUMIFS(Benefits!$R$6:$R$98,Benefits!$A$6:$A$98,A20) | G20: =F20-$F$17 | H20: =Costs!D21 | I20: =SUM(Costs!D21:F21) | J20: =Costs!I21 | K20: =Costs!J21 | L20: =Costs!M21 | M20: =L20-$L$17 | N20: =IF(G20>0,M20/G20,"n/a")
A21: =B21&"|"&C21 | B21: 2B | C21: FWOP | D21: No Action | E21: 1 | F21: =SUMIFS(Benefits!$R$6:$R$98,Benefits!$A$6:$A$98,A21) | G21: =F21-$F$21 | H21: =Costs!D22 | I21: =SUM(Costs!D22:F22) | J21: =Costs!I22 | K21: =Costs!J22 | L21: =Costs!M22 | M21: =L21-$L$21 | N21: =IF(G21>0,M21/G21,"n/a")
A22: =B22&"|"&C22 | B22: 2B | C22: Alternative1 | D22: Alternative 1 | E22: 0 | F22: =SUMIFS(Benefits!$R$6:$R$98,Benefits!$A$6:$A$98,A22) | G22: =F22-$F$21 | H22: =Costs!D23 | I22: =SUM(Costs!D23:F23) | J22: =Costs!I23 | K22: =Costs!J23 | L22: =Costs!M23 | M22: =L22-$L$21 | N22: =IF(G22>0,M22/G22,"n/a")
A23: =B23&"|"&C23 | B23: 2B | C23: Alternative2 | D23: Alternative 2 | E23: 0 | F23: =SUMIFS(Benefits!$R$6:$R$98,Benefits!$A$6:$A$98,A23) | G23: =F23-$F$21 | H23: =Costs!D24 | I23: =SUM(Costs!D24:F24) | J23: =Costs!I24 | K23: =Costs!J24 | L23: =Costs!M24 | M23: =L23-$L$21 | N23: =IF(G23>0,M23/G23,"n/a")
A24: =B24&"|"&C24 | B24: 2B | C24: Alternative3 | D24: Alternative 3 | E24: 0 | F24: =SUMIFS(Benefits!$R$6:$R$98,Benefits!$A$6:$A$98,A24) | G24: =F24-$F$21 | H24: =Costs!D25 | I24: =SUM(Costs!D25:F25) | J24: =Costs!I25 | K24: =Costs!J25 | L24: =Costs!M25 | M24: =L24-$L$21 | N24: =IF(G24>0,M24/G24,"n/a")
A25: =B25&"|"&C25 | B25: 3E | C25: FWOP | D25: No Action | E25: 1 | F25: =SUMIFS(Benefits!$R$6:$R$98,Benefits!$A$6:$A$98,A25) | G25: =F25-$F$25 | H25: =Costs!D26 | I25: =SUM(Costs!D26:F26) | J25: =Costs!I26 | K25: =Costs!J26 | L25: =Costs!M26 | M25: =L25-$L$25 | N25: =IF(G25>0,M25/G25,"n/a")
A26: =B26&"|"&C26 | B26: 3E | C26: Alternative1 | D26: Alternative 1 | E26: 0 | F26: =SUMIFS(Benefits!$R$6:$R$98,Benefits!$A$6:$A$98,A26) | G26: =F26-$F$25 | H26: =Costs!D27 | I26: =SUM(Costs!D27:F27) | J26: =Costs!I27 | K26: =Costs!J27 | L26: =Costs!M27 | M26: =L26-$L$25 | N26: =IF(G26>0,M26/G26,"n/a")
A27: =B27&"|"&C27 | B27: 3E | C27: Alternative2 | D27: Alternative 2 | E27: 0 | F27: =SUMIFS(Benefits!$R$6:$R$98,Benefits!$A$6:$A$98,A27) | G27: =F27-$F$25 | H27: =Costs!D28 | I27: =SUM(Costs!D28:F28) | J27: =Costs!I28 | K27: =Costs!J28 | L27: =Costs!M28 | M27: =L27-$L$25 | N27: =IF(G27>0,M27/G27,"n/a")
A28: =B28&"|"&C28 | B28: 3E | C28: Alternative3 | D28: Alternative 3 | E28: 0 | F28: =SUMIFS(Benefits!$R$6:$R$98,Benefits!$A$6:$A$98,A28) | G28: =F28-$F$25 | H28: =Costs!D29 | I28: =SUM(Costs!D29:F29) | J28: =Costs!I29 | K28: =Costs!J29 | L28: =Costs!M29 | M28: =L28-$L$25 | N28: =IF(G28>0,M28/G28,"n/a")
A29: =B29&"|"&C29 | B29: 3F | C29: FWOP | D29: No Action | E29: 1 | F29: =SUMIFS(Benefits!$R$6:$R$98,Benefits!$A$6:$A$98,A29) | G29: =F29-$F$29 | H29: =Costs!D30 | I29: =SUM(Costs!D30:F30) | J29: =Costs!I30 | K29: =Costs!J30 | L29: =Costs!M30 | M29: =L29-$L$29 | N29: =IF(G29>0,M29/G29,"n/a")
A30: =B30&"|"&C30 | B30: 3F | C30: Alternative1 | D30: Alternative 1 | E30: 0 | F30: =SUMIFS(Benefits!$R$6:$R$98,Benefits!$A$6:$A$98,A30) | G30: =F30-$F$29 | H30: =Costs!D31 | I30: =SUM(Costs!D31:F31) | J30: =Costs!I31 | K30: =Costs!J31 | L30: =Costs!M31 | M30: =L30-$L$29 | N30: =IF(G30>0,M30/G30,"n/a")
A31: =B31&"|"&C31 | B31: 3F | C31: Alternative2 | D31: Alternative 2 | E31: 0 | F31: =SUMIFS(Benefits!$R$6:$R$98,Benefits!$A$6:$A$98,A31) | G31: =F31-$F$29 | H31: =Costs!D32 | I31: =SUM(Costs!D32:F32) | J31: =Costs!I32 | K31: =Costs!J32 | L31: =Costs!M32 | M31: =L31-$L$29 | N31: =IF(G31>0,M31/G31,"n/a")
A32: =B32&"|"&C32 | B32: 3F | C32: Alternative3 | D32: Alternative 3 | E32: 0 | F32: =SUMIFS(Benefits!$R$6:$R$98,Benefits!$A$6:$A$98,A32) | G32: =F32-$F$29 | H32: =Costs!D33 | I32: =SUM(Costs!D33:F33) | J32: =Costs!I33 | K32: =Costs!J33 | L32: =Costs!M33 | M32: =L32-$L$29 | N32: =IF(G32>0,M32/G32,"n/a")
A33: =B33&"|"&C33 | B33: 19A | C33: FWOP | D33: No Action | E33: 1 | F33: =SUMIFS(Benefits!$R$6:$R$98,Benefits!$A$6:$A$98,A33) | G33: =F33-$F$33 | H33: =Costs!D34 | I33: =SUM(Costs!D34:F34) | J33: =Costs!I34 | K33: =Costs!J34 | L33: =Costs!M34 | M33: =L33-$L$33 | N33: =IF(G33>0,M33/G33,"n/a")
A34: =B34&"|"&C34 | B34: 19A | C34: Alternative2 | D34: Alternative 2 | E34: 0 | F34: =SUMIFS(Benefits!$R$6:$R$98,Benefits!$A$6:$A$98,A34) | G34: =F34-$F$33 | H34: =Costs!D35 | I34: =SUM(Costs!D35:F35) | J34: =Costs!I35 | K34: =Costs!J35 | L34: =Costs!M35 | M34: =L34-$L$33 | N34: =IF(G34>0,M34/G34,"n/a")
A35: =B35&"|"&C35 | B35: 19A | C35: Alternative3 | D35: Alternative 3 | E35: 0 | F35: =SUMIFS(Benefits!$R$6:$R$98,Benefits!$A$6:$A$98,A35) | G35: =F35-$F$33 | H35: =Costs!D36 | I35: =SUM(Costs!D36:F36) | J35: =Costs!I36 | K35: =Costs!J36 | L35: =Costs!M36 | M35: =L35-$L$33 | N35: =IF(G35>0,M35/G35,"n/a")

Sheet Site CE-ICA
A1: Site-by-site CE/ICA
A2: Cost-effective: no alternative gives the same output for less, or more output for no more. Best buy: on the lower hull from No Action (IWR Planning Suite II rules).
A4: Key | B4: Site | C4: Alternative | D4: Name | E4: No Action | F4: Ordinal | G4: Lift (AAHU) | H4: Cost above No Action | I4: Lift (scaled) | J4: Cost (scaled) | K4: Dominated by | L4: Cost-effective | M4: Candidate | N4: Slope in (max) | O4: Slope out (min) | P4: Best buy | Q4: Best-buy step | R4: Previous lift (scaled) | S4: Previous cost (scaled) | T4: Incremental output | U4: Incremental cost | V4: Incremental cost per unit | W4: Unit cost | X4: Recommended
B5: 17F2M Golf course concrete channel
A6: =B6&"|"&C6 | B6: 17F2M | C6: FWOP | D6: No Action | E6: 1 | F6: 1 | G6: =Summary!G5 | H6: =Summary!M5 | I6: =ROUND(G6*10^in_out_dp,0) | J6: =ROUND(H6*10^in_cost_dp,0) | K6: =SUMPRODUCT(($I$6:$I$9=I6)*($J$6:$J$9<J6)+($I$6:$I$9>I6)*($J$6:$J$9<=J6)) | L6: =IF(OR(E6=1,K6=0),1,0) | M6: =IF(AND(L6=1,E6=0,I6>0),1,0) | N6: =IF(M6=1,MAX(J6/I6,SUMPRODUCT(MAX(((J6-$J$6:$J$9)*($M$6:$M$9*($I$6:$I$9<I6)))/((I6-$I$6:$I$9)*($M$6:$M$9*($I$6:$I$9<I6))+1-($M$6:$M$9*($I$6:$I$9<I6)))-(1-($M$6:$M$9*($I$6:$I$9<I6)))*1E+300))),0) | O6: =IF(M6=1,SUMPRODUCT(MIN(((($J$6:$J$9-J6)*($M$6:$M$9*($I$6:$I$9>I6)))/(($I$6:$I$9-I6)*($M$6:$M$9*($I$6:$I$9>I6))+1-($M$6:$M$9*($I$6:$I$9>I6)))+(1-($M$6:$M$9*($I$6:$I$9>I6)))*1E+300))),0) | P6: =IF(E6=1,1,IF(AND(M6=1,N6<=O6),1,0)) | Q6: =IF(P6=1,1+SUMPRODUCT($P$6:$P$9*(($I$6:$I$9<I6)+($I$6:$I$9=I6)*($F$6:$F$9<F6))),0) | R6: =IF(Q6<=1,0,SUMPRODUCT(($Q$6:$Q$9=Q6-1)*$I$6:$I$9)) | S6: =IF(Q6<=1,0,SUMPRODUCT(($Q$6:$Q$9=Q6-1)*$J$6:$J$9)) | T6: =IF(Q6=0,"",(I6-R6)/10^in_out_dp) | U6: =IF(Q6=0,"",(J6-S6)/10^in_cost_dp) | V6: =IF(Q6=0,"",IF(I6=R6,0,U6/T6)) | W6: =IF(I6>0,(J6/10^in_cost_dp)/(I6/10^in_out_dp),"n/a") | X6: =IF(Sites!$C$5=C6,1,0)
A7: =B7&"|"&C7 | B7: 17F2M | C7: Alternative1 | D7: Alternative 1 | E7: 0 | F7: 2 | G7: =Summary!G6 | H7: =Summary!M6 | I7: =ROUND(G7*10^in_out_dp,0) | J7: =ROUND(H7*10^in_cost_dp,0) | K7: =SUMPRODUCT(($I$6:$I$9=I7)*($J$6:$J$9<J7)+($I$6:$I$9>I7)*($J$6:$J$9<=J7)) | L7: =IF(OR(E7=1,K7=0),1,0) | M7: =IF(AND(L7=1,E7=0,I7>0),1,0) | N7: =IF(M7=1,MAX(J7/I7,SUMPRODUCT(MAX(((J7-$J$6:$J$9)*($M$6:$M$9*($I$6:$I$9<I7)))/((I7-$I$6:$I$9)*($M$6:$M$9*($I$6:$I$9<I7))+1-($M$6:$M$9*($I$6:$I$9<I7)))-(1-($M$6:$M$9*($I$6:$I$9<I7)))*1E+300))),0) | O7: =IF(M7=1,SUMPRODUCT(MIN(((($J$6:$J$9-J7)*($M$6:$M$9*($I$6:$I$9>I7)))/(($I$6:$I$9-I7)*($M$6:$M$9*($I$6:$I$9>I7))+1-($M$6:$M$9*($I$6:$I$9>I7)))+(1-($M$6:$M$9*($I$6:$I$9>I7)))*1E+300))),0) | P7: =IF(E7=1,1,IF(AND(M7=1,N7<=O7),1,0)) | Q7: =IF(P7=1,1+SUMPRODUCT($P$6:$P$9*(($I$6:$I$9<I7)+($I$6:$I$9=I7)*($F$6:$F$9<F7))),0) | R7: =IF(Q7<=1,0,SUMPRODUCT(($Q$6:$Q$9=Q7-1)*$I$6:$I$9)) | S7: =IF(Q7<=1,0,SUMPRODUCT(($Q$6:$Q$9=Q7-1)*$J$6:$J$9)) | T7: =IF(Q7=0,"",(I7-R7)/10^in_out_dp) | U7: =IF(Q7=0,"",(J7-S7)/10^in_cost_dp) | V7: =IF(Q7=0,"",IF(I7=R7,0,U7/T7)) | W7: =IF(I7>0,(J7/10^in_cost_dp)/(I7/10^in_out_dp),"n/a") | X7: =IF(Sites!$C$5=C7,1,0)
A8: =B8&"|"&C8 | B8: 17F2M | C8: Alternative2 | D8: Alternative 2 | E8: 0 | F8: 3 | G8: =Summary!G7 | H8: =Summary!M7 | I8: =ROUND(G8*10^in_out_dp,0) | J8: =ROUND(H8*10^in_cost_dp,0) | K8: =SUMPRODUCT(($I$6:$I$9=I8)*($J$6:$J$9<J8)+($I$6:$I$9>I8)*($J$6:$J$9<=J8)) | L8: =IF(OR(E8=1,K8=0),1,0) | M8: =IF(AND(L8=1,E8=0,I8>0),1,0) | N8: =IF(M8=1,MAX(J8/I8,SUMPRODUCT(MAX(((J8-$J$6:$J$9)*($M$6:$M$9*($I$6:$I$9<I8)))/((I8-$I$6:$I$9)*($M$6:$M$9*($I$6:$I$9<I8))+1-($M$6:$M$9*($I$6:$I$9<I8)))-(1-($M$6:$M$9*($I$6:$I$9<I8)))*1E+300))),0) | O8: =IF(M8=1,SUMPRODUCT(MIN(((($J$6:$J$9-J8)*($M$6:$M$9*($I$6:$I$9>I8)))/(($I$6:$I$9-I8)*($M$6:$M$9*($I$6:$I$9>I8))+1-($M$6:$M$9*($I$6:$I$9>I8)))+(1-($M$6:$M$9*($I$6:$I$9>I8)))*1E+300))),0) | P8: =IF(E8=1,1,IF(AND(M8=1,N8<=O8),1,0)) | Q8: =IF(P8=1,1+SUMPRODUCT($P$6:$P$9*(($I$6:$I$9<I8)+($I$6:$I$9=I8)*($F$6:$F$9<F8))),0) | R8: =IF(Q8<=1,0,SUMPRODUCT(($Q$6:$Q$9=Q8-1)*$I$6:$I$9)) | S8: =IF(Q8<=1,0,SUMPRODUCT(($Q$6:$Q$9=Q8-1)*$J$6:$J$9)) | T8: =IF(Q8=0,"",(I8-R8)/10^in_out_dp) | U8: =IF(Q8=0,"",(J8-S8)/10^in_cost_dp) | V8: =IF(Q8=0,"",IF(I8=R8,0,U8/T8)) | W8: =IF(I8>0,(J8/10^in_cost_dp)/(I8/10^in_out_dp),"n/a") | X8: =IF(Sites!$C$5=C8,1,0)
A9: =B9&"|"&C9 | B9: 17F2M | C9: Alternative3 | D9: Alternative 3 | E9: 0 | F9: 4 | G9: =Summary!G8 | H9: =Summary!M8 | I9: =ROUND(G9*10^in_out_dp,0) | J9: =ROUND(H9*10^in_cost_dp,0) | K9: =SUMPRODUCT(($I$6:$I$9=I9)*($J$6:$J$9<J9)+($I$6:$I$9>I9)*($J$6:$J$9<=J9)) | L9: =IF(OR(E9=1,K9=0),1,0) | M9: =IF(AND(L9=1,E9=0,I9>0),1,0) | N9: =IF(M9=1,MAX(J9/I9,SUMPRODUCT(MAX(((J9-$J$6:$J$9)*($M$6:$M$9*($I$6:$I$9<I9)))/((I9-$I$6:$I$9)*($M$6:$M$9*($I$6:$I$9<I9))+1-($M$6:$M$9*($I$6:$I$9<I9)))-(1-($M$6:$M$9*($I$6:$I$9<I9)))*1E+300))),0) | O9: =IF(M9=1,SUMPRODUCT(MIN(((($J$6:$J$9-J9)*($M$6:$M$9*($I$6:$I$9>I9)))/(($I$6:$I$9-I9)*($M$6:$M$9*($I$6:$I$9>I9))+1-($M$6:$M$9*($I$6:$I$9>I9)))+(1-($M$6:$M$9*($I$6:$I$9>I9)))*1E+300))),0) | P9: =IF(E9=1,1,IF(AND(M9=1,N9<=O9),1,0)) | Q9: =IF(P9=1,1+SUMPRODUCT($P$6:$P$9*(($I$6:$I$9<I9)+($I$6:$I$9=I9)*($F$6:$F$9<F9))),0) | R9: =IF(Q9<=1,0,SUMPRODUCT(($Q$6:$Q$9=Q9-1)*$I$6:$I$9)) | S9: =IF(Q9<=1,0,SUMPRODUCT(($Q$6:$Q$9=Q9-1)*$J$6:$J$9)) | T9: =IF(Q9=0,"",(I9-R9)/10^in_out_dp) | U9: =IF(Q9=0,"",(J9-S9)/10^in_cost_dp) | V9: =IF(Q9=0,"",IF(I9=R9,0,U9/T9)) | W9: =IF(I9>0,(J9/10^in_cost_dp)/(I9/10^in_out_dp),"n/a") | X9: =IF(Sites!$C$5=C9,1,0)
B11: 17D2E Concrete channel to Beecher Road
A12: =B12&"|"&C12 | B12: 17D2E | C12: FWOP | D12: No Action | E12: 1 | F12: 1 | G12: =Summary!G9 | H12: =Summary!M9 | I12: =ROUND(G12*10^in_out_dp,0) | J12: =ROUND(H12*10^in_cost_dp,0) | K12: =SUMPRODUCT(($I$12:$I$15=I12)*($J$12:$J$15<J12)+($I$12:$I$15>I12)*($J$12:$J$15<=J12)) | L12: =IF(OR(E12=1,K12=0),1,0) | M12: =IF(AND(L12=1,E12=0,I12>0),1,0) | N12: =IF(M12=1,MAX(J12/I12,SUMPRODUCT(MAX(((J12-$J$12:$J$15)*($M$12:$M$15*($I$12:$I$15<I12)))/((I12-$I$12:$I$15)*($M$12:$M$15*($I$12:$I$15<I12))+1-($M$12:$M$15*($I$12:$I$15<I12)))-(1-($M$12:$M$15*($I$12:$I$15<I12)))*1E+300))),0) | O12: =IF(M12=1,SUMPRODUCT(MIN(((($J$12:$J$15-J12)*($M$12:$M$15*($I$12:$I$15>I12)))/(($I$12:$I$15-I12)*($M$12:$M$15*($I$12:$I$15>I12))+1-($M$12:$M$15*($I$12:$I$15>I12)))+(1-($M$12:$M$15*($I$12:$I$15>I12)))*1E+300))),0) | P12: =IF(E12=1,1,IF(AND(M12=1,N12<=O12),1,0)) | Q12: =IF(P12=1,1+SUMPRODUCT($P$12:$P$15*(($I$12:$I$15<I12)+($I$12:$I$15=I12)*($F$12:$F$15<F12))),0) | R12: =IF(Q12<=1,0,SUMPRODUCT(($Q$12:$Q$15=Q12-1)*$I$12:$I$15)) | S12: =IF(Q12<=1,0,SUMPRODUCT(($Q$12:$Q$15=Q12-1)*$J$12:$J$15)) | T12: =IF(Q12=0,"",(I12-R12)/10^in_out_dp) | U12: =IF(Q12=0,"",(J12-S12)/10^in_cost_dp) | V12: =IF(Q12=0,"",IF(I12=R12,0,U12/T12)) | W12: =IF(I12>0,(J12/10^in_cost_dp)/(I12/10^in_out_dp),"n/a") | X12: =IF(Sites!$C$6=C12,1,0)
A13: =B13&"|"&C13 | B13: 17D2E | C13: Alternative1 | D13: Alternative 1 | E13: 0 | F13: 2 | G13: =Summary!G10 | H13: =Summary!M10 | I13: =ROUND(G13*10^in_out_dp,0) | J13: =ROUND(H13*10^in_cost_dp,0) | K13: =SUMPRODUCT(($I$12:$I$15=I13)*($J$12:$J$15<J13)+($I$12:$I$15>I13)*($J$12:$J$15<=J13)) | L13: =IF(OR(E13=1,K13=0),1,0) | M13: =IF(AND(L13=1,E13=0,I13>0),1,0) | N13: =IF(M13=1,MAX(J13/I13,SUMPRODUCT(MAX(((J13-$J$12:$J$15)*($M$12:$M$15*($I$12:$I$15<I13)))/((I13-$I$12:$I$15)*($M$12:$M$15*($I$12:$I$15<I13))+1-($M$12:$M$15*($I$12:$I$15<I13)))-(1-($M$12:$M$15*($I$12:$I$15<I13)))*1E+300))),0) | O13: =IF(M13=1,SUMPRODUCT(MIN(((($J$12:$J$15-J13)*($M$12:$M$15*($I$12:$I$15>I13)))/(($I$12:$I$15-I13)*($M$12:$M$15*($I$12:$I$15>I13))+1-($M$12:$M$15*($I$12:$I$15>I13)))+(1-($M$12:$M$15*($I$12:$I$15>I13)))*1E+300))),0) | P13: =IF(E13=1,1,IF(AND(M13=1,N13<=O13),1,0)) | Q13: =IF(P13=1,1+SUMPRODUCT($P$12:$P$15*(($I$12:$I$15<I13)+($I$12:$I$15=I13)*($F$12:$F$15<F13))),0) | R13: =IF(Q13<=1,0,SUMPRODUCT(($Q$12:$Q$15=Q13-1)*$I$12:$I$15)) | S13: =IF(Q13<=1,0,SUMPRODUCT(($Q$12:$Q$15=Q13-1)*$J$12:$J$15)) | T13: =IF(Q13=0,"",(I13-R13)/10^in_out_dp) | U13: =IF(Q13=0,"",(J13-S13)/10^in_cost_dp) | V13: =IF(Q13=0,"",IF(I13=R13,0,U13/T13)) | W13: =IF(I13>0,(J13/10^in_cost_dp)/(I13/10^in_out_dp),"n/a") | X13: =IF(Sites!$C$6=C13,1,0)
