Workbook
Name in_rate: Parameters!$B$4
Name in_poa: Parameters!$B$5
Name in_ppy: Parameters!$B$6
Name in_idc_method: Parameters!$B$7
Name in_timing: Parameters!$B$8
Name in_cost_dp: Parameters!$B$9
Name in_out_dp: Parameters!$B$10
Name calc_crf: Parameters!$B$11
Name out_status: 'Read me'!$B$10
Name out_changed: 'Read me'!$B$11
Name out_mismatch: 'Read me'!$B$12

Sheet Read me
A1: STAF demonstration: CE/ICA calculator
A2: Cost-effectiveness and incremental cost analysis, as live formulas.
A4: Study | B4: STAF demonstration
A5: Generated by | B5: CEICA 0.1.0 (engine 1)
A6: Project digest | B6: 5d6ded045e76
A7: Discount rate | B7: 3 percent
A8: Period of analysis | B8: 50 years
A10: Status | B10: =IF((SUMPRODUCT(1*(Parameters!B4:B10<>'snap Parameters'!B4:B10))+SUMPRODUCT(1*(Parameters!B14:G14<>'snap Parameters'!B14:G14))+SUMPRODUCT(1*('STAF scores'!F10:Y12<>'snap STAF scores'!F10:Y12))+SUMPRODUCT(1*('STAF scores'!E15:Y74<>'snap STAF scores'!E15:Y74))+SUMPRODUCT(1*(Costs!D6:G15<>'snap Costs'!D6:G15))+SUMPRODUCT(1*(Costs!L6:L15<>'snap Costs'!L6:L15))+SUMPRODUCT(1*(OMRRR!F5:M19<>'snap OMRRR'!F5:M19))+SUMPRODUCT(1*(Sites!C5:C7<>'snap Sites'!C5:C7))+SUMPRODUCT(1*('Watershed plans'!AA12:AA19<>'snap Watershed plans'!AA12:AA19))+SUMPRODUCT(1*('Watershed summary'!K50:L89<>'snap Watershed summary'!K50:L89))+SUMPRODUCT(1*('Watershed summary'!B93:B93<>'snap Watershed summary'!B93:B93)))=0,IF((SUMPRODUCT(1*(ABS(Summary!G5:G14-'snap Summary'!G5:G14)>1e-06))+SUMPRODUCT(1*(ABS(Summary!L5:L14-'snap Summary'!L5:L14)>0.0001))+SUMPRODUCT(1*('Site CE-ICA'!L6:L9<>'snap Site CE-ICA'!L6:L9))+SUMPRODUCT(1*('Site CE-ICA'!P6:P9<>'snap Site CE-ICA'!P6:P9))+SUMPRODUCT(1*('Site CE-ICA'!L12:L14<>'snap Site CE-ICA'!L12:L14))+SUMPRODUCT(1*('Site CE-ICA'!P12:P14<>'snap Site CE-ICA'!P12:P14))+SUMPRODUCT(1*('Site CE-ICA'!L17:L19<>'snap Site CE-ICA'!L17:L19))+SUMPRODUCT(1*('Site CE-ICA'!P17:P19<>'snap Site CE-ICA'!P17:P19))+SUMPRODUCT(1*('Watershed plans'!O12:O19<>'snap Watershed plans'!O12:O19))+SUMPRODUCT(1*('Watershed plans'!S12:S19<>'snap Watershed plans'!S12:S19)))=0,"Unchanged: matches the CEICA export","ERROR: results differ from the export although no input changed"),"Edited: "&(SUMPRODUCT(1*(Parameters!B4:B10<>'snap Parameters'!B4:B10))+SUMPRODUCT(1*(Parameters!B14:G14<>'snap Parameters'!B14:G14))+SUMPRODUCT(1*('STAF scores'!F10:Y12<>'snap STAF scores'!F10:Y12))+SUMPRODUCT(1*('STAF scores'!E15:Y74<>'snap STAF scores'!E15:Y74))+SUMPRODUCT(1*(Costs!D6:G15<>'snap Costs'!D6:G15))+SUMPRODUCT(1*(Costs!L6:L15<>'snap Costs'!L6:L15))+SUMPRODUCT(1*(OMRRR!F5:M19<>'snap OMRRR'!F5:M19))+SUMPRODUCT(1*(Sites!C5:C7<>'snap Sites'!C5:C7))+SUMPRODUCT(1*('Watershed plans'!AA12:AA19<>'snap Watershed plans'!AA12:AA19))+SUMPRODUCT(1*('Watershed summary'!K50:L89<>'snap Watershed summary'!K50:L89))+SUMPRODUCT(1*('Watershed summary'!B93:B93<>'snap Watershed summary'!B93:B93)))&" input cells changed since the export")
A11: Inputs changed | B11: =(SUMPRODUCT(1*(Parameters!B4:B10<>'snap Parameters'!B4:B10))+SUMPRODUCT(1*(Parameters!B14:G14<>'snap Parameters'!B14:G14))+SUMPRODUCT(1*('STAF scores'!F10:Y12<>'snap STAF scores'!F10:Y12))+SUMPRODUCT(1*('STAF scores'!E15:Y74<>'snap STAF scores'!E15:Y74))+SUMPRODUCT(1*(Costs!D6:G15<>'snap Costs'!D6:G15))+SUMPRODUCT(1*(Costs!L6:L15<>'snap Costs'!L6:L15))+SUMPRODUCT(1*(OMRRR!F5:M19<>'snap OMRRR'!F5:M19))+SUMPRODUCT(1*(Sites!C5:C7<>'snap Sites'!C5:C7))+SUMPRODUCT(1*('Watershed plans'!AA12:AA19<>'snap Watershed plans'!AA12:AA19))+SUMPRODUCT(1*('Watershed summary'!K50:L89<>'snap Watershed summary'!K50:L89))+SUMPRODUCT(1*('Watershed summary'!B93:B93<>'snap Watershed summary'!B93:B93)))
A12: Results that differ from the export | B12: =(SUMPRODUCT(1*(ABS(Summary!G5:G14-'snap Summary'!G5:G14)>1e-06))+SUMPRODUCT(1*(ABS(Summary!L5:L14-'snap Summary'!L5:L14)>0.0001))+SUMPRODUCT(1*('Site CE-ICA'!L6:L9<>'snap Site CE-ICA'!L6:L9))+SUMPRODUCT(1*('Site CE-ICA'!P6:P9<>'snap Site CE-ICA'!P6:P9))+SUMPRODUCT(1*('Site CE-ICA'!L12:L14<>'snap Site CE-ICA'!L12:L14))+SUMPRODUCT(1*('Site CE-ICA'!P12:P14<>'snap Site CE-ICA'!P12:P14))+SUMPRODUCT(1*('Site CE-ICA'!L17:L19<>'snap Site CE-ICA'!L17:L19))+SUMPRODUCT(1*('Site CE-ICA'!P17:P19<>'snap Site CE-ICA'!P17:P19))+SUMPRODUCT(1*('Watershed plans'!O12:O19<>'snap Watershed plans'!O12:O19))+SUMPRODUCT(1*('Watershed plans'!S12:S19<>'snap Watershed plans'!S12:S19)))
A14: How to use
A15: - Orange cells are inputs; grey cells are formulas. Sheets are protected (password 'ceica') only to prevent accidental edits.
A16: - Change any orange cell: annualization, site CE/ICA, the watershed plans and the summary update. Changed inputs turn yellow.
A17: - To add sites, alternatives or years, make the change in CEICA and export again.
A18: - Import this workbook in CEICA to bring your changes back into the project.
A20: Legend
A21: Input
A22: Formula
A23: Changed since export

Sheet Parameters
A1: Parameters
A2: Economics and conventions. Orange cells are inputs.
A3: Parameter | B3: Value
A4: Discount rate | B4: 0.03
A5: Period of analysis (years) | B5: 50
A6: Interest during construction: periods per year | B6: 12
A7: Interest during construction: spending in each period (END, MIDDLE or START) | B7: END
A8: OMRRR discounting (END_OF_YEAR or MID_YEAR) | B8: END_OF_YEAR
A9: Cost decimals kept for CE/ICA | B9: 2
A10: Output decimals kept for CE/ICA | B10: 3
A11: Capital recovery factor | B11: =IF(in_rate=0,1/in_poa,in_rate*(1+in_rate)^in_poa/((1+in_rate)^in_poa-1))
A13: Target years | B13: Year 1 | C13: Year 2 | D13: Year 3 | E13: Year 4 | F13: Year 5 | G13: Year 6
A14: Years (first to last) | B14: 0 | C14: 1 | D14: 5 | E14: 10 | F14: 25 | G14: 50

Sheet STAF scores
A1: STAF scores: function scores (0 to 15) at each target year
A2: Outcome mapping STAF documentation, EASI and DEEP (A): weight 1 for a direct effect, 0.1 for an indirect one. A function marked 0 under Assessed is left out of both sums at that site.
B4: Weights | F4: Catchment hydrology | G4: Surface water storage | H4: Reach inflow | I4: Streamflow regime | J4: Low flow and baseflow dynamics | K4: High flow dynamics | L4: Floodplain connectivity | M4: Hyporheic connectivity | N4: Channel evolution | O4: Channel and floodplain dynamics | P4: Sediment continuity | Q4: Bed composition and large wood | R4: Light & thermal regime | S4: Carbon processing | T4: Nutrient cycling | U4: Water & soil quality | V4: Habitat provision | W4: Population support | X4: Community dynamics | Y4: Watershed connectivity
B5: Physical | F5: 1 | G5: 1 | H5: 1 | I5: 1 | J5: 1 | K5: 1 | L5: 1 | M5: 1 | N5: 1 | O5: 1 | P5: 1 | Q5: 1 | R5: 0 | S5: 0 | T5: 0.1 | U5: 0.1 | V5: 0 | W5: 0.1 | X5: 0.1 | Y5: 0.1
B6: Chemical | F6: 0.1 | G6: 0.1 | H6: 0.1 | I6: 0.1 | J6: 0.1 | K6: 0.1 | L6: 0.1 | M6: 0.1 | N6: 0.1 | O6: 0.1 | P6: 0.1 | Q6: 0.1 | R6: 1 | S6: 1 | T6: 1 | U6: 1 | V6: 0 | W6: 0.1 | X6: 0.1 | Y6: 0
B7: Biological | F7: 0.1 | G7: 0.1 | H7: 0.1 | I7: 0.1 | J7: 0.1 | K7: 0.1 | L7: 0.1 | M7: 0.1 | N7: 0.1 | O7: 0.1 | P7: 0.1 | Q7: 0.1 | R7: 0.1 | S7: 0.1 | T7: 0.1 | U7: 0.1 | V7: 1 | W7: 1 | X7: 1 | Y7: 1
B9: Assessed (1) or not (0) | F9: Catchment hydrology | G9: Surface water storage | H9: Reach inflow | I9: Streamflow regime | J9: Low flow and baseflow dynamics | K9: High flow dynamics | L9: Floodplain connectivity | M9: Hyporheic connectivity | N9: Channel evolution | O9: Channel and floodplain dynamics | P9: Sediment continuity | Q9: Bed composition and large wood | R9: Light & thermal regime | S9: Carbon processing | T9: Nutrient cycling | U9: Water & soil quality | V9: Habitat provision | W9: Population support | X9: Community dynamics | Y9: Watershed connectivity
B10: R1 | F10: 1 | G10: 1 | H10: 1 | I10: 1 | J10: 1 | K10: 1 | L10: 1 | M10: 1 | N10: 1 | O10: 1 | P10: 1 | Q10: 1 | R10: 1 | S10: 1 | T10: 1 | U10: 1 | V10: 1 | W10: 1 | X10: 1 | Y10: 1
B11: R2 | F11: 1 | G11: 1 | H11: 1 | I11: 1 | J11: 1 | K11: 1 | L11: 1 | M11: 1 | N11: 1 | O11: 1 | P11: 1 | Q11: 1 | R11: 1 | S11: 1 | T11: 1 | U11: 1 | V11: 1 | W11: 1 | X11: 1 | Y11: 1
B12: R3 | F12: 1 | G12: 1 | H12: 1 | I12: 1 | J12: 1 | K12: 1 | L12: 1 | M12: 1 | N12: 1 | O12: 1 | P12: 1 | Q12: 1 | R12: 1 | S12: 1 | T12: 1 | U12: 1 | V12: 1 | W12: 1 | X12: 1 | Y12: 0
B14: Site | C14: Alternative | D14: Year | E14: Quantity (ft) | F14: Catchment hydrology | G14: Surface water storage | H14: Reach inflow | I14: Streamflow regime | J14: Low flow and baseflow dynamics | K14: High flow dynamics | L14: Floodplain connectivity | M14: Hyporheic connectivity | N14: Channel evolution | O14: Channel and floodplain dynamics | P14: Sediment continuity | Q14: Bed composition and large wood | R14: Light & thermal regime | S14: Carbon processing | T14: Nutrient cycling | U14: Water & soil quality | V14: Habitat provision | W14: Population support | X14: Community dynamics | Y14: Watershed connectivity
B15: R1 | C15: FWOP | D15: =Parameters!$B$14 | E15: 1000 | F15: 8 | G15: 15 | H15: 7 | I15: 12 | J15: 4 | K15: 11 | L15: 9 | M15: 13 | N15: 5 | O15: 10 | P15: 6 | Q15: 5 | R15: 12 | S15: 13 | T15: 13 | U15: 10 | V15: 2 | W15: 3 | X15: 4 | Y15: 1
B16: R1 | C16: FWOP | D16: =Parameters!$C$14 | E16: 1000 | F16: 8 | G16: 15 | H16: 7 | I16: 12 | J16: 4 | K16: 11 | L16: 9 | M16: 13 | N16: 5 | O16: 10 | P16: 6 | Q16: 5 | R16: 12 | S16: 13 | T16: 13 | U16: 10 | V16: 2 | W16: 3 | X16: 4 | Y16: 1
B17: R1 | C17: FWOP | D17: =Parameters!$D$14 | E17: 1000 | F17: 8 | G17: 15 | H17: 7 | I17: 12 | J17: 4 | K17: 11 | L17: 9 | M17: 13 | N17: 4.9 | O17: 10 | P17: 6 | Q17: 4.9 | R17: 12 | S17: 13 | T17: 13 | U17: 10 | V17: 2 | W17: 2.9 | X17: 3.9 | Y17: 1
B18: R1 | C18: FWOP | D18: =Parameters!$E$14 | E18: 1000 | F18: 8 | G18: 15 | H18: 7 | I18: 12 | J18: 4 | K18: 11 | L18: 9 | M18: 13 | N18: 4.8 | O18: 10 | P18: 6 | Q18: 4.8 | R18: 12 | S18: 13 | T18: 13 | U18: 10 | V18: 2 | W18: 2.8 | X18: 3.8 | Y18: 1
B19: R1 | C19: FWOP | D19: =Parameters!$F$14 | E19: 1000 | F19: 8 | G19: 15 | H19: 7 | I19: 12 | J19: 4 | K19: 11 | L19: 9 | M19: 13 | N19: 4.5 | O19: 10 | P19: 6 | Q19: 4.5 | R19: 12 | S19: 13 | T19: 13 | U19: 10 | V19: 2 | W19: 2.5 | X19: 3.5 | Y19: 1
B20: R1 | C20: FWOP | D20: =Parameters!$G$14 | E20: 1000 | F20: 8 | G20: 15 | H20: 7 | I20: 12 | J20: 4 | K20: 11 | L20: 9 | M20: 13 | N20: 4 | O20: 10 | P20: 6 | Q20: 4 | R20: 12 | S20: 13 | T20: 13 | U20: 10 | V20: 2 | W20: 2 | X20: 3 | Y20: 1
B21: R1 | C21: A1 | D21: =Parameters!$B$14 | E21: 1000 | F21: 8 | G21: 15 | H21: 7 | I21: 12 | J21: 4 | K21: 11 | L21: 9 | M21: 13 | N21: 5 | O21: 10 | P21: 6 | Q21: 5 | R21: 12 | S21: 13 | T21: 13 | U21: 10 | V21: 2 | W21: 3 | X21: 4 | Y21: 1
B22: R1 | C22: A1 | D22: =Parameters!$C$14 | E22: 1000 | F22: 8 | G22: 15 | H22: 7 | I22: 12 | J22: 4 | K22: 11 | L22: 9 | M22: 13 | N22: 5 | O22: 10 | P22: 6 | Q22: 5 | R22: 12.2 | S22: 13.1 | T22: 13.1 | U22: 10.2 | V22: 2 | W22: 3 | X22: 4 | Y22: 1
B23: R1 | C23: A1 | D23: =Parameters!$D$14 | E23: 1000 | F23: 8 | G23: 15 | H23: 7 | I23: 12 | J23: 4 | K23: 11 | L23: 9 | M23: 13 | N23: 4.9 | O23: 10 | P23: 6 | Q23: 4.9 | R23: 13 | S23: 13.5 | T23: 13.5 | U23: 11 | V23: 2.8 | W23: 3.4 | X23: 4.4 | Y23: 1
B24: R1 | C24: A1 | D24: =Parameters!$E$14 | E24: 1000 | F24: 8 | G24: 15 | H24: 7 | I24: 12 | J24: 4 | K24: 11 | L24: 9 | M24: 13 | N24: 4.8 | O24: 10 | P24: 6 | Q24: 4.8 | R24: 13.6 | S24: 13.8 | T24: 13.8 | U24: 11.6 | V24: 3.4 | W24: 3.7 | X24: 4.7 | Y24: 1
B25: R1 | C25: A1 | D25: =Parameters!$F$14 | E25: 1000 | F25: 8 | G25: 15 | H25: 7 | I25: 12 | J25: 4 | K25: 11 | L25: 9 | M25: 13 | N25: 4.5 | O25: 10 | P25: 6 | Q25: 4.5 | R25: 14 | S25: 14 | T25: 14 | U25: 12 | V25: 4 | W25: 4 | X25: 5 | Y25: 1
B26: R1 | C26: A1 | D26: =Parameters!$G$14 | E26: 1000 | F26: 8 | G26: 15 | H26: 7 | I26: 12 | J26: 4 | K26: 11 | L26: 9 | M26: 13 | N26: 4 | O26: 10 | P26: 6 | Q26: 4 | R26: 14 | S26: 14 | T26: 14 | U26: 12 | V26: 4 | W26: 4 | X26: 5 | Y26: 1
B27: R1 | C27: A2 | D27: =Parameters!$B$14 | E27: 1000 | F27: 8 | G27: 15 | H27: 7 | I27: 12 | J27: 4 | K27: 11 | L27: 9 | M27: 13 | N27: 5 | O27: 10 | P27: 6 | Q27: 5 | R27: 12 | S27: 13 | T27: 13 | U27: 10 | V27: 2 | W27: 3 | X27: 4 | Y27: 1
B28: R1 | C28: A2 | D28: =Parameters!$C$14 | E28: 1000 | F28: 8 | G28: 15 | H28: 7 | I28: 12 | J28: 4 | K28: 12.6 | L28: 12.2 | M28: 13.8 | N28: 5 | O28: 11.6 | P28: 6 | Q28: 5 | R28: 12.2 | S28: 13.1 | T28: 13.1 | U28: 10.2 | V28: 2 | W28: 3 | X28: 4 | Y28: 1
B29: R1 | C29: A2 | D29: =Parameters!$D$14 | E29: 1000 | F29: 8 | G29: 15 | H29: 7 | I29: 12 | J29: 4 | K29: 13 | L29: 13 | M29: 14 | N29: 5 | O29: 12 | P29: 6 | Q29: 5 | R29: 13 | S29: 13.5 | T29: 13.5 | U29: 11 | V29: 4 | W29: 4.2 | X29: 5.2 | Y29: 1
B30: R1 | C30: A2 | D30: =Parameters!$E$14 | E30: 1000 | F30: 8 | G30: 15 | H30: 7 | I30: 12 | J30: 4 | K30: 13 | L30: 13 | M30: 14 | N30: 5 | O30: 12 | P30: 6 | Q30: 5 | R30: 13.6 | S30: 13.8 | T30: 13.8 | U30: 11.6 | V30: 5.5 | W30: 5.1 | X30: 6.1 | Y30: 1
B31: R1 | C31: A2 | D31: =Parameters!$F$14 | E31: 1000 | F31: 8 | G31: 15 | H31: 7 | I31: 12 | J31: 4 | K31: 13 | L31: 13 | M31: 14 | N31: 5 | O31: 12 | P31: 6 | Q31: 5 | R31: 14 | S31: 14 | T31: 14 | U31: 12 | V31: 7 | W31: 6 | X31: 7 | Y31: 1
B32: R1 | C32: A2 | D32: =Parameters!$G$14 | E32: 1000 | F32: 8 | G32: 15 | H32: 7 | I32: 12 | J32: 4 | K32: 13 | L32: 13 | M32: 14 | N32: 5 | O32: 12 | P32: 6 | Q32: 5 | R32: 14 | S32: 14 | T32: 14 | U32: 12 | V32: 7 | W32: 6 | X32: 7 | Y32: 1
B33: R1 | C33: A3 | D33: =Parameters!$B$14 | E33: 1000 | F33: 8 | G33: 15 | H33: 7 | I33: 12 | J33: 4 | K33: 11 | L33: 9 | M33: 13 | N33: 5 | O33: 10 | P33: 6 | Q33: 5 | R33: 12 | S33: 13 | T33: 13 | U33: 10 | V33: 2 | W33: 3 | X33: 4 | Y33: 1
B34: R1 | C34: A3 | D34: =Parameters!$C$14 | E34: 1000 | F34: 8 | G34: 15 | H34: 7 | I34: 12 | J34: 6.4 | K34: 12.6 | L34: 12.2 | M34: 13.8 | N34: 5 | O34: 11.6 | P34: 7.6 | Q34: 9 | R34: 12.2 | S34: 13.1 | T34: 13.1 | U34: 10.2 | V34: 2 | W34: 3 | X34: 4 | Y34: 1
B35: R1 | C35: A3 | D35: =Parameters!$D$14 | E35: 1000 | F35: 8 | G35: 15 | H35: 7 | I35: 12 | J35: 7 | K35: 13 | L35: 13 | M35: 14 | N35: 5 | O35: 12 | P35: 8 | Q35: 10 | R35: 13 | S35: 13.5 | T35: 13.5 | U35: 11 | V35: 5.2 | W35: 5 | X35: 5.6 | Y35: 1
B36: R1 | C36: A3 | D36: =Parameters!$E$14 | E36: 1000 | F36: 8 | G36: 15 | H36: 7 | I36: 12 | J36: 7 | K36: 13 | L36: 13 | M36: 14 | N36: 5 | O36: 12 | P36: 8 | Q36: 10 | R36: 13.6 | S36: 13.8 | T36: 13.8 | U36: 11.6 | V36: 7.6 | W36: 6.5 | X36: 6.8 | Y36: 1
B37: R1 | C37: A3 | D37: =Parameters!$F$14 | E37: 1000 | F37: 8 | G37: 15 | H37: 7 | I37: 12 | J37: 7 | K37: 13 | L37: 13 | M37: 14 | N37: 5 | O37: 12 | P37: 8 | Q37: 10 | R37: 14 | S37: 14 | T37: 14 | U37: 12 | V37: 10 | W37: 8 | X37: 8 | Y37: 1
B38: R1 | C38: A3 | D38: =Parameters!$G$14 | E38: 1000 | F38: 8 | G38: 15 | H38: 7 | I38: 12 | J38: 7 | K38: 13 | L38: 13 | M38: 14 | N38: 5 | O38: 12 | P38: 8 | Q38: 10 | R38: 14 | S38: 14 | T38: 14 | U38: 12 | V38: 10 | W38: 8 | X38: 8 | Y38: 1
B39: R2 | C39: FWOP | D39: =Parameters!$B$14 | E39: 2400 | F39: 3 | G39: 4 | H39: 3 | I39: 4 | J39: 3 | K39: 3 | L39: 2 | M39: 4 | N39: 3 | O39: 3 | P39: 4 | Q39: 3 | R39: 5 | S39: 5 | T39: 6 | U39: 4 | V39: 2 | W39: 2 | X39: 2 | Y39: 3
B40: R2 | C40: FWOP | D40: =Parameters!$C$14 | E40: 2400 | F40: 3 | G40: 4 | H40: 3 | I40: 4 | J40: 3 | K40: 3 | L40: 2 | M40: 4 | N40: 3 | O40: 3 | P40: 4 | Q40: 3 | R40: 5 | S40: 5 | T40: 6 | U40: 4 | V40: 2 | W40: 2 | X40: 2 | Y40: 3
B41: R2 | C41: FWOP | D41: =Parameters!$D$14 | E41: 2400 | F41: 3 | G41: 4 | H41: 3 | I41: 4 | J41: 3 | K41: 3 | L41: 2 | M41: 4 | N41: 2.9 | O41: 2.9 | P41: 4 | Q41: 3 | R41: 5 | S41: 5 | T41: 6 | U41: 3.9 | V41: 2 | W41: 2 | X41: 2 | Y41: 3
B42: R2 | C42: FWOP | D42: =Parameters!$E$14 | E42: 2400 | F42: 3 | G42: 4 | H42: 3 | I42: 4 | J42: 3 | K42: 3 | L42: 2 | M42: 4 | N42: 2.8 | O42: 2.8 | P42: 4 | Q42: 3 | R42: 5 | S42: 5 | T42: 6 | U42: 3.8 | V42: 2 | W42: 2 | X42: 2 | Y42: 3
B43: R2 | C43: FWOP | D43: =Parameters!$F$14 | E43: 2400 | F43: 3 | G43: 4 | H43: 3 | I43: 4 | J43: 3 | K43: 3 | L43: 2 | M43: 4 | N43: 2.5 | O43: 2.5 | P43: 4 | Q43: 3 | R43: 5 | S43: 5 | T43: 6 | U43: 3.5 | V43: 2 | W43: 2 | X43: 2 | Y43: 3
...

Sheet STAF roll-up
A1: STAF roll-up: sub-indices, Ecosystem Condition Index and condition units
A2: Each row matches the same row of STAF scores. Condition units = ECI x quantity; the Benefits sheet averages them over the period.
B4: Site | C4: Alternative | D4: Year | E4: Physical | F4: Chemical | G4: Biological | H4: Blank scores | I4: ECI | J4: Condition | K4: Quantity (ft) | L4: Condition units (CU)
B5: ='STAF scores'!B15 | C5: ='STAF scores'!C15 | D5: ='STAF scores'!D15 | E5: =IF(SUMPRODUCT('STAF scores'!$F$5:$Y$5,'STAF scores'!$F$10:$Y$10)>0,SUMPRODUCT('STAF scores'!F15:Y15,'STAF scores'!$F$5:$Y$5,'STAF scores'!$F$10:$Y$10)/(15*SUMPRODUCT('STAF scores'!$F$5:$Y$5,'STAF scores'!$F$10:$Y$10)),NA()) | F5: =IF(SUMPRODUCT('STAF scores'!$F$6:$Y$6,'STAF scores'!$F$10:$Y$10)>0,SUMPRODUCT('STAF scores'!F15:Y15,'STAF scores'!$F$6:$Y$6,'STAF scores'!$F$10:$Y$10)/(15*SUMPRODUCT('STAF scores'!$F$6:$Y$6,'STAF scores'!$F$10:$Y$10)),NA()) | G5: =IF(SUMPRODUCT('STAF scores'!$F$7:$Y$7,'STAF scores'!$F$10:$Y$10)>0,SUMPRODUCT('STAF scores'!F15:Y15,'STAF scores'!$F$7:$Y$7,'STAF scores'!$F$10:$Y$10)/(15*SUMPRODUCT('STAF scores'!$F$7:$Y$7,'STAF scores'!$F$10:$Y$10)),NA()) | H5: =SUMPRODUCT('STAF scores'!$F$10:$Y$10*(1-ISNUMBER('STAF scores'!F15:Y15))) | I5: =IF(H5>0,NA(),(E5+F5+G5)/3) | J5: =IF(ISNUMBER(I5),IF(ROUND(I5,2)<=0.39,"Non-Functioning",IF(ROUND(I5,2)<=0.69,"Functioning-at-Risk","Functioning")),"") | K5: =IF(ISNUMBER('STAF scores'!E15),'STAF scores'!E15,NA()) | L5: =I5*K5
B6: ='STAF scores'!B16 | C6: ='STAF scores'!C16 | D6: ='STAF scores'!D16 | E6: =IF(SUMPRODUCT('STAF scores'!$F$5:$Y$5,'STAF scores'!$F$10:$Y$10)>0,SUMPRODUCT('STAF scores'!F16:Y16,'STAF scores'!$F$5:$Y$5,'STAF scores'!$F$10:$Y$10)/(15*SUMPRODUCT('STAF scores'!$F$5:$Y$5,'STAF scores'!$F$10:$Y$10)),NA()) | F6: =IF(SUMPRODUCT('STAF scores'!$F$6:$Y$6,'STAF scores'!$F$10:$Y$10)>0,SUMPRODUCT('STAF scores'!F16:Y16,'STAF scores'!$F$6:$Y$6,'STAF scores'!$F$10:$Y$10)/(15*SUMPRODUCT('STAF scores'!$F$6:$Y$6,'STAF scores'!$F$10:$Y$10)),NA()) | G6: =IF(SUMPRODUCT('STAF scores'!$F$7:$Y$7,'STAF scores'!$F$10:$Y$10)>0,SUMPRODUCT('STAF scores'!F16:Y16,'STAF scores'!$F$7:$Y$7,'STAF scores'!$F$10:$Y$10)/(15*SUMPRODUCT('STAF scores'!$F$7:$Y$7,'STAF scores'!$F$10:$Y$10)),NA()) | H6: =SUMPRODUCT('STAF scores'!$F$10:$Y$10*(1-ISNUMBER('STAF scores'!F16:Y16))) | I6: =IF(H6>0,NA(),(E6+F6+G6)/3) | J6: =IF(ISNUMBER(I6),IF(ROUND(I6,2)<=0.39,"Non-Functioning",IF(ROUND(I6,2)<=0.69,"Functioning-at-Risk","Functioning")),"") | K6: =IF(ISNUMBER('STAF scores'!E16),'STAF scores'!E16,NA()) | L6: =I6*K6
B7: ='STAF scores'!B17 | C7: ='STAF scores'!C17 | D7: ='STAF scores'!D17 | E7: =IF(SUMPRODUCT('STAF scores'!$F$5:$Y$5,'STAF scores'!$F$10:$Y$10)>0,SUMPRODUCT('STAF scores'!F17:Y17,'STAF scores'!$F$5:$Y$5,'STAF scores'!$F$10:$Y$10)/(15*SUMPRODUCT('STAF scores'!$F$5:$Y$5,'STAF scores'!$F$10:$Y$10)),NA()) | F7: =IF(SUMPRODUCT('STAF scores'!$F$6:$Y$6,'STAF scores'!$F$10:$Y$10)>0,SUMPRODUCT('STAF scores'!F17:Y17,'STAF scores'!$F$6:$Y$6,'STAF scores'!$F$10:$Y$10)/(15*SUMPRODUCT('STAF scores'!$F$6:$Y$6,'STAF scores'!$F$10:$Y$10)),NA()) | G7: =IF(SUMPRODUCT('STAF scores'!$F$7:$Y$7,'STAF scores'!$F$10:$Y$10)>0,SUMPRODUCT('STAF scores'!F17:Y17,'STAF scores'!$F$7:$Y$7,'STAF scores'!$F$10:$Y$10)/(15*SUMPRODUCT('STAF scores'!$F$7:$Y$7,'STAF scores'!$F$10:$Y$10)),NA()) | H7: =SUMPRODUCT('STAF scores'!$F$10:$Y$10*(1-ISNUMBER('STAF scores'!F17:Y17))) | I7: =IF(H7>0,NA(),(E7+F7+G7)/3) | J7: =IF(ISNUMBER(I7),IF(ROUND(I7,2)<=0.39,"Non-Functioning",IF(ROUND(I7,2)<=0.69,"Functioning-at-Risk","Functioning")),"") | K7: =IF(ISNUMBER('STAF scores'!E17),'STAF scores'!E17,NA()) | L7: =I7*K7
B8: ='STAF scores'!B18 | C8: ='STAF scores'!C18 | D8: ='STAF scores'!D18 | E8: =IF(SUMPRODUCT('STAF scores'!$F$5:$Y$5,'STAF scores'!$F$10:$Y$10)>0,SUMPRODUCT('STAF scores'!F18:Y18,'STAF scores'!$F$5:$Y$5,'STAF scores'!$F$10:$Y$10)/(15*SUMPRODUCT('STAF scores'!$F$5:$Y$5,'STAF scores'!$F$10:$Y$10)),NA()) | F8: =IF(SUMPRODUCT('STAF scores'!$F$6:$Y$6,'STAF scores'!$F$10:$Y$10)>0,SUMPRODUCT('STAF scores'!F18:Y18,'STAF scores'!$F$6:$Y$6,'STAF scores'!$F$10:$Y$10)/(15*SUMPRODUCT('STAF scores'!$F$6:$Y$6,'STAF scores'!$F$10:$Y$10)),NA()) | G8: =IF(SUMPRODUCT('STAF scores'!$F$7:$Y$7,'STAF scores'!$F$10:$Y$10)>0,SUMPRODUCT('STAF scores'!F18:Y18,'STAF scores'!$F$7:$Y$7,'STAF scores'!$F$10:$Y$10)/(15*SUMPRODUCT('STAF scores'!$F$7:$Y$7,'STAF scores'!$F$10:$Y$10)),NA()) | H8: =SUMPRODUCT('STAF scores'!$F$10:$Y$10*(1-ISNUMBER('STAF scores'!F18:Y18))) | I8: =IF(H8>0,NA(),(E8+F8+G8)/3) | J8: =IF(ISNUMBER(I8),IF(ROUND(I8,2)<=0.39,"Non-Functioning",IF(ROUND(I8,2)<=0.69,"Functioning-at-Risk","Functioning")),"") | K8: =IF(ISNUMBER('STAF scores'!E18),'STAF scores'!E18,NA()) | L8: =I8*K8
B9: ='STAF scores'!B19 | C9: ='STAF scores'!C19 | D9: ='STAF scores'!D19 | E9: =IF(SUMPRODUCT('STAF scores'!$F$5:$Y$5,'STAF scores'!$F$10:$Y$10)>0,SUMPRODUCT('STAF scores'!F19:Y19,'STAF scores'!$F$5:$Y$5,'STAF scores'!$F$10:$Y$10)/(15*SUMPRODUCT('STAF scores'!$F$5:$Y$5,'STAF scores'!$F$10:$Y$10)),NA()) | F9: =IF(SUMPRODUCT('STAF scores'!$F$6:$Y$6,'STAF scores'!$F$10:$Y$10)>0,SUMPRODUCT('STAF scores'!F19:Y19,'STAF scores'!$F$6:$Y$6,'STAF scores'!$F$10:$Y$10)/(15*SUMPRODUCT('STAF scores'!$F$6:$Y$6,'STAF scores'!$F$10:$Y$10)),NA()) | G9: =IF(SUMPRODUCT('STAF scores'!$F$7:$Y$7,'STAF scores'!$F$10:$Y$10)>0,SUMPRODUCT('STAF scores'!F19:Y19,'STAF scores'!$F$7:$Y$7,'STAF scores'!$F$10:$Y$10)/(15*SUMPRODUCT('STAF scores'!$F$7:$Y$7,'STAF scores'!$F$10:$Y$10)),NA()) | H9: =SUMPRODUCT('STAF scores'!$F$10:$Y$10*(1-ISNUMBER('STAF scores'!F19:Y19))) | I9: =IF(H9>0,NA(),(E9+F9+G9)/3) | J9: =IF(ISNUMBER(I9),IF(ROUND(I9,2)<=0.39,"Non-Functioning",IF(ROUND(I9,2)<=0.69,"Functioning-at-Risk","Functioning")),"") | K9: =IF(ISNUMBER('STAF scores'!E19),'STAF scores'!E19,NA()) | L9: =I9*K9
B10: ='STAF scores'!B20 | C10: ='STAF scores'!C20 | D10: ='STAF scores'!D20 | E10: =IF(SUMPRODUCT('STAF scores'!$F$5:$Y$5,'STAF scores'!$F$10:$Y$10)>0,SUMPRODUCT('STAF scores'!F20:Y20,'STAF scores'!$F$5:$Y$5,'STAF scores'!$F$10:$Y$10)/(15*SUMPRODUCT('STAF scores'!$F$5:$Y$5,'STAF scores'!$F$10:$Y$10)),NA()) | F10: =IF(SUMPRODUCT('STAF scores'!$F$6:$Y$6,'STAF scores'!$F$10:$Y$10)>0,SUMPRODUCT('STAF scores'!F20:Y20,'STAF scores'!$F$6:$Y$6,'STAF scores'!$F$10:$Y$10)/(15*SUMPRODUCT('STAF scores'!$F$6:$Y$6,'STAF scores'!$F$10:$Y$10)),NA()) | G10: =IF(SUMPRODUCT('STAF scores'!$F$7:$Y$7,'STAF scores'!$F$10:$Y$10)>0,SUMPRODUCT('STAF scores'!F20:Y20,'STAF scores'!$F$7:$Y$7,'STAF scores'!$F$10:$Y$10)/(15*SUMPRODUCT('STAF scores'!$F$7:$Y$7,'STAF scores'!$F$10:$Y$10)),NA()) | H10: =SUMPRODUCT('STAF scores'!$F$10:$Y$10*(1-ISNUMBER('STAF scores'!F20:Y20))) | I10: =IF(H10>0,NA(),(E10+F10+G10)/3) | J10: =IF(ISNUMBER(I10),IF(ROUND(I10,2)<=0.39,"Non-Functioning",IF(ROUND(I10,2)<=0.69,"Functioning-at-Risk","Functioning")),"") | K10: =IF(ISNUMBER('STAF scores'!E20),'STAF scores'!E20,NA()) | L10: =I10*K10
B11: ='STAF scores'!B21 | C11: ='STAF scores'!C21 | D11: ='STAF scores'!D21 | E11: =IF(SUMPRODUCT('STAF scores'!$F$5:$Y$5,'STAF scores'!$F$10:$Y$10)>0,SUMPRODUCT('STAF scores'!F21:Y21,'STAF scores'!$F$5:$Y$5,'STAF scores'!$F$10:$Y$10)/(15*SUMPRODUCT('STAF scores'!$F$5:$Y$5,'STAF scores'!$F$10:$Y$10)),NA()) | F11: =IF(SUMPRODUCT('STAF scores'!$F$6:$Y$6,'STAF scores'!$F$10:$Y$10)>0,SUMPRODUCT('STAF scores'!F21:Y21,'STAF scores'!$F$6:$Y$6,'STAF scores'!$F$10:$Y$10)/(15*SUMPRODUCT('STAF scores'!$F$6:$Y$6,'STAF scores'!$F$10:$Y$10)),NA()) | G11: =IF(SUMPRODUCT('STAF scores'!$F$7:$Y$7,'STAF scores'!$F$10:$Y$10)>0,SUMPRODUCT('STAF scores'!F21:Y21,'STAF scores'!$F$7:$Y$7,'STAF scores'!$F$10:$Y$10)/(15*SUMPRODUCT('STAF scores'!$F$7:$Y$7,'STAF scores'!$F$10:$Y$10)),NA()) | H11: =SUMPRODUCT('STAF scores'!$F$10:$Y$10*(1-ISNUMBER('STAF scores'!F21:Y21))) | I11: =IF(H11>0,NA(),(E11+F11+G11)/3) | J11: =IF(ISNUMBER(I11),IF(ROUND(I11,2)<=0.39,"Non-Functioning",IF(ROUND(I11,2)<=0.69,"Functioning-at-Risk","Functioning")),"") | K11: =IF(ISNUMBER('STAF scores'!E21),'STAF scores'!E21,NA()) | L11: =I11*K11
B12: ='STAF scores'!B22 | C12: ='STAF scores'!C22 | D12: ='STAF scores'!D22 | E12: =IF(SUMPRODUCT('STAF scores'!$F$5:$Y$5,'STAF scores'!$F$10:$Y$10)>0,SUMPRODUCT('STAF scores'!F22:Y22,'STAF scores'!$F$5:$Y$5,'STAF scores'!$F$10:$Y$10)/(15*SUMPRODUCT('STAF scores'!$F$5:$Y$5,'STAF scores'!$F$10:$Y$10)),NA()) | F12: =IF(SUMPRODUCT('STAF scores'!$F$6:$Y$6,'STAF scores'!$F$10:$Y$10)>0,SUMPRODUCT('STAF scores'!F22:Y22,'STAF scores'!$F$6:$Y$6,'STAF scores'!$F$10:$Y$10)/(15*SUMPRODUCT('STAF scores'!$F$6:$Y$6,'STAF scores'!$F$10:$Y$10)),NA()) | G12: =IF(SUMPRODUCT('STAF scores'!$F$7:$Y$7,'STAF scores'!$F$10:$Y$10)>0,SUMPRODUCT('STAF scores'!F22:Y22,'STAF scores'!$F$7:$Y$7,'STAF scores'!$F$10:$Y$10)/(15*SUMPRODUCT('STAF scores'!$F$7:$Y$7,'STAF scores'!$F$10:$Y$10)),NA()) | H12: =SUMPRODUCT('STAF scores'!$F$10:$Y$10*(1-ISNUMBER('STAF scores'!F22:Y22))) | I12: =IF(H12>0,NA(),(E12+F12+G12)/3) | J12: =IF(ISNUMBER(I12),IF(ROUND(I12,2)<=0.39,"Non-Functioning",IF(ROUND(I12,2)<=0.69,"Functioning-at-Risk","Functioning")),"") | K12: =IF(ISNUMBER('STAF scores'!E22),'STAF scores'!E22,NA()) | L12: =I12*K12
B13: ='STAF scores'!B23 | C13: ='STAF scores'!C23 | D13: ='STAF scores'!D23 | E13: =IF(SUMPRODUCT('STAF scores'!$F$5:$Y$5,'STAF scores'!$F$10:$Y$10)>0,SUMPRODUCT('STAF scores'!F23:Y23,'STAF scores'!$F$5:$Y$5,'STAF scores'!$F$10:$Y$10)/(15*SUMPRODUCT('STAF scores'!$F$5:$Y$5,'STAF scores'!$F$10:$Y$10)),NA()) | F13: =IF(SUMPRODUCT('STAF scores'!$F$6:$Y$6,'STAF scores'!$F$10:$Y$10)>0,SUMPRODUCT('STAF scores'!F23:Y23,'STAF scores'!$F$6:$Y$6,'STAF scores'!$F$10:$Y$10)/(15*SUMPRODUCT('STAF scores'!$F$6:$Y$6,'STAF scores'!$F$10:$Y$10)),NA()) | G13: =IF(SUMPRODUCT('STAF scores'!$F$7:$Y$7,'STAF scores'!$F$10:$Y$10)>0,SUMPRODUCT('STAF scores'!F23:Y23,'STAF scores'!$F$7:$Y$7,'STAF scores'!$F$10:$Y$10)/(15*SUMPRODUCT('STAF scores'!$F$7:$Y$7,'STAF scores'!$F$10:$Y$10)),NA()) | H13: =SUMPRODUCT('STAF scores'!$F$10:$Y$10*(1-ISNUMBER('STAF scores'!F23:Y23))) | I13: =IF(H13>0,NA(),(E13+F13+G13)/3) | J13: =IF(ISNUMBER(I13),IF(ROUND(I13,2)<=0.39,"Non-Functioning",IF(ROUND(I13,2)<=0.69,"Functioning-at-Risk","Functioning")),"") | K13: =IF(ISNUMBER('STAF scores'!E23),'STAF scores'!E23,NA()) | L13: =I13*K13
B14: ='STAF scores'!B24 | C14: ='STAF scores'!C24 | D14: ='STAF scores'!D24 | E14: =IF(SUMPRODUCT('STAF scores'!$F$5:$Y$5,'STAF scores'!$F$10:$Y$10)>0,SUMPRODUCT('STAF scores'!F24:Y24,'STAF scores'!$F$5:$Y$5,'STAF scores'!$F$10:$Y$10)/(15*SUMPRODUCT('STAF scores'!$F$5:$Y$5,'STAF scores'!$F$10:$Y$10)),NA()) | F14: =IF(SUMPRODUCT('STAF scores'!$F$6:$Y$6,'STAF scores'!$F$10:$Y$10)>0,SUMPRODUCT('STAF scores'!F24:Y24,'STAF scores'!$F$6:$Y$6,'STAF scores'!$F$10:$Y$10)/(15*SUMPRODUCT('STAF scores'!$F$6:$Y$6,'STAF scores'!$F$10:$Y$10)),NA()) | G14: =IF(SUMPRODUCT('STAF scores'!$F$7:$Y$7,'STAF scores'!$F$10:$Y$10)>0,SUMPRODUCT('STAF scores'!F24:Y24,'STAF scores'!$F$7:$Y$7,'STAF scores'!$F$10:$Y$10)/(15*SUMPRODUCT('STAF scores'!$F$7:$Y$7,'STAF scores'!$F$10:$Y$10)),NA()) | H14: =SUMPRODUCT('STAF scores'!$F$10:$Y$10*(1-ISNUMBER('STAF scores'!F24:Y24))) | I14: =IF(H14>0,NA(),(E14+F14+G14)/3) | J14: =IF(ISNUMBER(I14),IF(ROUND(I14,2)<=0.39,"Non-Functioning",IF(ROUND(I14,2)<=0.69,"Functioning-at-Risk","Functioning")),"") | K14: =IF(ISNUMBER('STAF scores'!E24),'STAF scores'!E24,NA()) | L14: =I14*K14
B15: ='STAF scores'!B25 | C15: ='STAF scores'!C25 | D15: ='STAF scores'!D25 | E15: =IF(SUMPRODUCT('STAF scores'!$F$5:$Y$5,'STAF scores'!$F$10:$Y$10)>0,SUMPRODUCT('STAF scores'!F25:Y25,'STAF scores'!$F$5:$Y$5,'STAF scores'!$F$10:$Y$10)/(15*SUMPRODUCT('STAF scores'!$F$5:$Y$5,'STAF scores'!$F$10:$Y$10)),NA()) | F15: =IF(SUMPRODUCT('STAF scores'!$F$6:$Y$6,'STAF scores'!$F$10:$Y$10)>0,SUMPRODUCT('STAF scores'!F25:Y25,'STAF scores'!$F$6:$Y$6,'STAF scores'!$F$10:$Y$10)/(15*SUMPRODUCT('STAF scores'!$F$6:$Y$6,'STAF scores'!$F$10:$Y$10)),NA()) | G15: =IF(SUMPRODUCT('STAF scores'!$F$7:$Y$7,'STAF scores'!$F$10:$Y$10)>0,SUMPRODUCT('STAF scores'!F25:Y25,'STAF scores'!$F$7:$Y$7,'STAF scores'!$F$10:$Y$10)/(15*SUMPRODUCT('STAF scores'!$F$7:$Y$7,'STAF scores'!$F$10:$Y$10)),NA()) | H15: =SUMPRODUCT('STAF scores'!$F$10:$Y$10*(1-ISNUMBER('STAF scores'!F25:Y25))) | I15: =IF(H15>0,NA(),(E15+F15+G15)/3) | J15: =IF(ISNUMBER(I15),IF(ROUND(I15,2)<=0.39,"Non-Functioning",IF(ROUND(I15,2)<=0.69,"Functioning-at-Risk","Functioning")),"") | K15: =IF(ISNUMBER('STAF scores'!E25),'STAF scores'!E25,NA()) | L15: =I15*K15
B16: ='STAF scores'!B26 | C16: ='STAF scores'!C26 | D16: ='STAF scores'!D26 | E16: =IF(SUMPRODUCT('STAF scores'!$F$5:$Y$5,'STAF scores'!$F$10:$Y$10)>0,SUMPRODUCT('STAF scores'!F26:Y26,'STAF scores'!$F$5:$Y$5,'STAF scores'!$F$10:$Y$10)/(15*SUMPRODUCT('STAF scores'!$F$5:$Y$5,'STAF scores'!$F$10:$Y$10)),NA()) | F16: =IF(SUMPRODUCT('STAF scores'!$F$6:$Y$6,'STAF scores'!$F$10:$Y$10)>0,SUMPRODUCT('STAF scores'!F26:Y26,'STAF scores'!$F$6:$Y$6,'STAF scores'!$F$10:$Y$10)/(15*SUMPRODUCT('STAF scores'!$F$6:$Y$6,'STAF scores'!$F$10:$Y$10)),NA()) | G16: =IF(SUMPRODUCT('STAF scores'!$F$7:$Y$7,'STAF scores'!$F$10:$Y$10)>0,SUMPRODUCT('STAF scores'!F26:Y26,'STAF scores'!$F$7:$Y$7,'STAF scores'!$F$10:$Y$10)/(15*SUMPRODUCT('STAF scores'!$F$7:$Y$7,'STAF scores'!$F$10:$Y$10)),NA()) | H16: =SUMPRODUCT('STAF scores'!$F$10:$Y$10*(1-ISNUMBER('STAF scores'!F26:Y26))) | I16: =IF(H16>0,NA(),(E16+F16+G16)/3) | J16: =IF(ISNUMBER(I16),IF(ROUND(I16,2)<=0.39,"Non-Functioning",IF(ROUND(I16,2)<=0.69,"Functioning-at-Risk","Functioning")),"") | K16: =IF(ISNUMBER('STAF scores'!E26),'STAF scores'!E26,NA()) | L16: =I16*K16
... B28: ='STAF scores'!B38 | C28: ='STAF scores'!C38 | D28: ='STAF scores'!D38 | E28: =IF(SUMPRODUCT('STAF scores'!$F$5:$Y$5,'STAF scores'!$F$10:$Y$10)>0,SUMPRODUCT('STAF scores'!F38:Y38,'STAF scores'!$F$5:$Y$5,'STAF scores'!$F$10:$Y$10)/(15*SUMPRODUCT('STAF scores'!$F$5:$Y$5,'STAF scores'!$F$10:$Y$10)),NA()) | F28: =IF(SUMPRODUCT('STAF scores'!$F$6:$Y$6,'STAF scores'!$F$10:$Y$10)>0,SUMPRODUCT('STAF scores'!F38:Y38,'STAF scores'!$F$6:$Y$6,'STAF scores'!$F$10:$Y$10)/(15*SUMPRODUCT('STAF scores'!$F$6:$Y$6,'STAF scores'!$F$10:$Y$10)),NA()) | G28: =IF(SUMPRODUCT('STAF scores'!$F$7:$Y$7,'STAF scores'!$F$10:$Y$10)>0,SUMPRODUCT('STAF scores'!F38:Y38,'STAF scores'!$F$7:$Y$7,'STAF scores'!$F$10:$Y$10)/(15*SUMPRODUCT('STAF scores'!$F$7:$Y$7,'STAF scores'!$F$10:$Y$10)),NA()) | H28: =SUMPRODUCT('STAF scores'!$F$10:$Y$10*(1-ISNUMBER('STAF scores'!F38:Y38))) | I28: =IF(H28>0,NA(),(E28+F28+G28)/3) | J28: =IF(ISNUMBER(I28),IF(ROUND(I28,2)<=0.39,"Non-Functioning",IF(ROUND(I28,2)<=0.69,"Functioning-at-Risk","Functioning")),"") | K28: =IF(ISNUMBER('STAF scores'!E38),'STAF scores'!E38,NA()) | L28: =I28*K28
B29: ='STAF scores'!B39 | C29: ='STAF scores'!C39 | D29: ='STAF scores'!D39 | E29: =IF(SUMPRODUCT('STAF scores'!$F$5:$Y$5,'STAF scores'!$F$11:$Y$11)>0,SUMPRODUCT('STAF scores'!F39:Y39,'STAF scores'!$F$5:$Y$5,'STAF scores'!$F$11:$Y$11)/(15*SUMPRODUCT('STAF scores'!$F$5:$Y$5,'STAF scores'!$F$11:$Y$11)),NA()) | F29: =IF(SUMPRODUCT('STAF scores'!$F$6:$Y$6,'STAF scores'!$F$11:$Y$11)>0,SUMPRODUCT('STAF scores'!F39:Y39,'STAF scores'!$F$6:$Y$6,'STAF scores'!$F$11:$Y$11)/(15*SUMPRODUCT('STAF scores'!$F$6:$Y$6,'STAF scores'!$F$11:$Y$11)),NA()) | G29: =IF(SUMPRODUCT('STAF scores'!$F$7:$Y$7,'STAF scores'!$F$11:$Y$11)>0,SUMPRODUCT('STAF scores'!F39:Y39,'STAF scores'!$F$7:$Y$7,'STAF scores'!$F$11:$Y$11)/(15*SUMPRODUCT('STAF scores'!$F$7:$Y$7,'STAF scores'!$F$11:$Y$11)),NA()) | H29: =SUMPRODUCT('STAF scores'!$F$11:$Y$11*(1-ISNUMBER('STAF scores'!F39:Y39))) | I29: =IF(H29>0,NA(),(E29+F29+G29)/3) | J29: =IF(ISNUMBER(I29),IF(ROUND(I29,2)<=0.39,"Non-Functioning",IF(ROUND(I29,2)<=0.69,"Functioning-at-Risk","Functioning")),"") | K29: =IF(ISNUMBER('STAF scores'!E39),'STAF scores'!E39,NA()) | L29: =I29*K29
B30: ='STAF scores'!B40 | C30: ='STAF scores'!C40 | D30: ='STAF scores'!D40 | E30: =IF(SUMPRODUCT('STAF scores'!$F$5:$Y$5,'STAF scores'!$F$11:$Y$11)>0,SUMPRODUCT('STAF scores'!F40:Y40,'STAF scores'!$F$5:$Y$5,'STAF scores'!$F$11:$Y$11)/(15*SUMPRODUCT('STAF scores'!$F$5:$Y$5,'STAF scores'!$F$11:$Y$11)),NA()) | F30: =IF(SUMPRODUCT('STAF scores'!$F$6:$Y$6,'STAF scores'!$F$11:$Y$11)>0,SUMPRODUCT('STAF scores'!F40:Y40,'STAF scores'!$F$6:$Y$6,'STAF scores'!$F$11:$Y$11)/(15*SUMPRODUCT('STAF scores'!$F$6:$Y$6,'STAF scores'!$F$11:$Y$11)),NA()) | G30: =IF(SUMPRODUCT('STAF scores'!$F$7:$Y$7,'STAF scores'!$F$11:$Y$11)>0,SUMPRODUCT('STAF scores'!F40:Y40,'STAF scores'!$F$7:$Y$7,'STAF scores'!$F$11:$Y$11)/(15*SUMPRODUCT('STAF scores'!$F$7:$Y$7,'STAF scores'!$F$11:$Y$11)),NA()) | H30: =SUMPRODUCT('STAF scores'!$F$11:$Y$11*(1-ISNUMBER('STAF scores'!F40:Y40))) | I30: =IF(H30>0,NA(),(E30+F30+G30)/3) | J30: =IF(ISNUMBER(I30),IF(ROUND(I30,2)<=0.39,"Non-Functioning",IF(ROUND(I30,2)<=0.69,"Functioning-at-Risk","Functioning")),"") | K30: =IF(ISNUMBER('STAF scores'!E40),'STAF scores'!E40,NA()) | L30: =I30*K30
B31: ='STAF scores'!B41 | C31: ='STAF scores'!C41 | D31: ='STAF scores'!D41 | E31: =IF(SUMPRODUCT('STAF scores'!$F$5:$Y$5,'STAF scores'!$F$11:$Y$11)>0,SUMPRODUCT('STAF scores'!F41:Y41,'STAF scores'!$F$5:$Y$5,'STAF scores'!$F$11:$Y$11)/(15*SUMPRODUCT('STAF scores'!$F$5:$Y$5,'STAF scores'!$F$11:$Y$11)),NA()) | F31: =IF(SUMPRODUCT('STAF scores'!$F$6:$Y$6,'STAF scores'!$F$11:$Y$11)>0,SUMPRODUCT('STAF scores'!F41:Y41,'STAF scores'!$F$6:$Y$6,'STAF scores'!$F$11:$Y$11)/(15*SUMPRODUCT('STAF scores'!$F$6:$Y$6,'STAF scores'!$F$11:$Y$11)),NA()) | G31: =IF(SUMPRODUCT('STAF scores'!$F$7:$Y$7,'STAF scores'!$F$11:$Y$11)>0,SUMPRODUCT('STAF scores'!F41:Y41,'STAF scores'!$F$7:$Y$7,'STAF scores'!$F$11:$Y$11)/(15*SUMPRODUCT('STAF scores'!$F$7:$Y$7,'STAF scores'!$F$11:$Y$11)),NA()) | H31: =SUMPRODUCT('STAF scores'!$F$11:$Y$11*(1-ISNUMBER('STAF scores'!F41:Y41))) | I31: =IF(H31>0,NA(),(E31+F31+G31)/3) | J31: =IF(ISNUMBER(I31),IF(ROUND(I31,2)<=0.39,"Non-Functioning",IF(ROUND(I31,2)<=0.69,"Functioning-at-Risk","Functioning")),"") | K31: =IF(ISNUMBER('STAF scores'!E41),'STAF scores'!E41,NA()) | L31: =I31*K31
B32: ='STAF scores'!B42 | C32: ='STAF scores'!C42 | D32: ='STAF scores'!D42 | E32: =IF(SUMPRODUCT('STAF scores'!$F$5:$Y$5,'STAF scores'!$F$11:$Y$11)>0,SUMPRODUCT('STAF scores'!F42:Y42,'STAF scores'!$F$5:$Y$5,'STAF scores'!$F$11:$Y$11)/(15*SUMPRODUCT('STAF scores'!$F$5:$Y$5,'STAF scores'!$F$11:$Y$11)),NA()) | F32: =IF(SUMPRODUCT('STAF scores'!$F$6:$Y$6,'STAF scores'!$F$11:$Y$11)>0,SUMPRODUCT('STAF scores'!F42:Y42,'STAF scores'!$F$6:$Y$6,'STAF scores'!$F$11:$Y$11)/(15*SUMPRODUCT('STAF scores'!$F$6:$Y$6,'STAF scores'!$F$11:$Y$11)),NA()) | G32: =IF(SUMPRODUCT('STAF scores'!$F$7:$Y$7,'STAF scores'!$F$11:$Y$11)>0,SUMPRODUCT('STAF scores'!F42:Y42,'STAF scores'!$F$7:$Y$7,'STAF scores'!$F$11:$Y$11)/(15*SUMPRODUCT('STAF scores'!$F$7:$Y$7,'STAF scores'!$F$11:$Y$11)),NA()) | H32: =SUMPRODUCT('STAF scores'!$F$11:$Y$11*(1-ISNUMBER('STAF scores'!F42:Y42))) | I32: =IF(H32>0,NA(),(E32+F32+G32)/3) | J32: =IF(ISNUMBER(I32),IF(ROUND(I32,2)<=0.39,"Non-Functioning",IF(ROUND(I32,2)<=0.69,"Functioning-at-Risk","Functioning")),"") | K32: =IF(ISNUMBER('STAF scores'!E42),'STAF scores'!E42,NA()) | L32: =I32*K32
B33: ='STAF scores'!B43 | C33: ='STAF scores'!C43 | D33: ='STAF scores'!D43 | E33: =IF(SUMPRODUCT('STAF scores'!$F$5:$Y$5,'STAF scores'!$F$11:$Y$11)>0,SUMPRODUCT('STAF scores'!F43:Y43,'STAF scores'!$F$5:$Y$5,'STAF scores'!$F$11:$Y$11)/(15*SUMPRODUCT('STAF scores'!$F$5:$Y$5,'STAF scores'!$F$11:$Y$11)),NA()) | F33: =IF(SUMPRODUCT('STAF scores'!$F$6:$Y$6,'STAF scores'!$F$11:$Y$11)>0,SUMPRODUCT('STAF scores'!F43:Y43,'STAF scores'!$F$6:$Y$6,'STAF scores'!$F$11:$Y$11)/(15*SUMPRODUCT('STAF scores'!$F$6:$Y$6,'STAF scores'!$F$11:$Y$11)),NA()) | G33: =IF(SUMPRODUCT('STAF scores'!$F$7:$Y$7,'STAF scores'!$F$11:$Y$11)>0,SUMPRODUCT('STAF scores'!F43:Y43,'STAF scores'!$F$7:$Y$7,'STAF scores'!$F$11:$Y$11)/(15*SUMPRODUCT('STAF scores'!$F$7:$Y$7,'STAF scores'!$F$11:$Y$11)),NA()) | H33: =SUMPRODUCT('STAF scores'!$F$11:$Y$11*(1-ISNUMBER('STAF scores'!F43:Y43))) | I33: =IF(H33>0,NA(),(E33+F33+G33)/3) | J33: =IF(ISNUMBER(I33),IF(ROUND(I33,2)<=0.39,"Non-Functioning",IF(ROUND(I33,2)<=0.69,"Functioning-at-Risk","Functioning")),"") | K33: =IF(ISNUMBER('STAF scores'!E43),'STAF scores'!E43,NA()) | L33: =I33*K33
B34: ='STAF scores'!B44 | C34: ='STAF scores'!C44 | D34: ='STAF scores'!D44 | E34: =IF(SUMPRODUCT('STAF scores'!$F$5:$Y$5,'STAF scores'!$F$11:$Y$11)>0,SUMPRODUCT('STAF scores'!F44:Y44,'STAF scores'!$F$5:$Y$5,'STAF scores'!$F$11:$Y$11)/(15*SUMPRODUCT('STAF scores'!$F$5:$Y$5,'STAF scores'!$F$11:$Y$11)),NA()) | F34: =IF(SUMPRODUCT('STAF scores'!$F$6:$Y$6,'STAF scores'!$F$11:$Y$11)>0,SUMPRODUCT('STAF scores'!F44:Y44,'STAF scores'!$F$6:$Y$6,'STAF scores'!$F$11:$Y$11)/(15*SUMPRODUCT('STAF scores'!$F$6:$Y$6,'STAF scores'!$F$11:$Y$11)),NA()) | G34: =IF(SUMPRODUCT('STAF scores'!$F$7:$Y$7,'STAF scores'!$F$11:$Y$11)>0,SUMPRODUCT('STAF scores'!F44:Y44,'STAF scores'!$F$7:$Y$7,'STAF scores'!$F$11:$Y$11)/(15*SUMPRODUCT('STAF scores'!$F$7:$Y$7,'STAF scores'!$F$11:$Y$11)),NA()) | H34: =SUMPRODUCT('STAF scores'!$F$11:$Y$11*(1-ISNUMBER('STAF scores'!F44:Y44))) | I34: =IF(H34>0,NA(),(E34+F34+G34)/3) | J34: =IF(ISNUMBER(I34),IF(ROUND(I34,2)<=0.39,"Non-Functioning",IF(ROUND(I34,2)<=0.69,"Functioning-at-Risk","Functioning")),"") | K34: =IF(ISNUMBER('STAF scores'!E44),'STAF scores'!E44,NA()) | L34: =I34*K34
B35: ='STAF scores'!B45 | C35: ='STAF scores'!C45 | D35: ='STAF scores'!D45 | E35: =IF(SUMPRODUCT('STAF scores'!$F$5:$Y$5,'STAF scores'!$F$11:$Y$11)>0,SUMPRODUCT('STAF scores'!F45:Y45,'STAF scores'!$F$5:$Y$5,'STAF scores'!$F$11:$Y$11)/(15*SUMPRODUCT('STAF scores'!$F$5:$Y$5,'STAF scores'!$F$11:$Y$11)),NA()) | F35: =IF(SUMPRODUCT('STAF scores'!$F$6:$Y$6,'STAF scores'!$F$11:$Y$11)>0,SUMPRODUCT('STAF scores'!F45:Y45,'STAF scores'!$F$6:$Y$6,'STAF scores'!$F$11:$Y$11)/(15*SUMPRODUCT('STAF scores'!$F$6:$Y$6,'STAF scores'!$F$11:$Y$11)),NA()) | G35: =IF(SUMPRODUCT('STAF scores'!$F$7:$Y$7,'STAF scores'!$F$11:$Y$11)>0,SUMPRODUCT('STAF scores'!F45:Y45,'STAF scores'!$F$7:$Y$7,'STAF scores'!$F$11:$Y$11)/(15*SUMPRODUCT('STAF scores'!$F$7:$Y$7,'STAF scores'!$F$11:$Y$11)),NA()) | H35: =SUMPRODUCT('STAF scores'!$F$11:$Y$11*(1-ISNUMBER('STAF scores'!F45:Y45))) | I35: =IF(H35>0,NA(),(E35+F35+G35)/3) | J35: =IF(ISNUMBER(I35),IF(ROUND(I35,2)<=0.39,"Non-Functioning",IF(ROUND(I35,2)<=0.69,"Functioning-at-Risk","Functioning")),"") | K35: =IF(ISNUMBER('STAF scores'!E45),'STAF scores'!E45,NA()) | L35: =I35*K35
B36: ='STAF scores'!B46 | C36: ='STAF scores'!C46 | D36: ='STAF scores'!D46 | E36: =IF(SUMPRODUCT('STAF scores'!$F$5:$Y$5,'STAF scores'!$F$11:$Y$11)>0,SUMPRODUCT('STAF scores'!F46:Y46,'STAF scores'!$F$5:$Y$5,'STAF scores'!$F$11:$Y$11)/(15*SUMPRODUCT('STAF scores'!$F$5:$Y$5,'STAF scores'!$F$11:$Y$11)),NA()) | F36: =IF(SUMPRODUCT('STAF scores'!$F$6:$Y$6,'STAF scores'!$F$11:$Y$11)>0,SUMPRODUCT('STAF scores'!F46:Y46,'STAF scores'!$F$6:$Y$6,'STAF scores'!$F$11:$Y$11)/(15*SUMPRODUCT('STAF scores'!$F$6:$Y$6,'STAF scores'!$F$11:$Y$11)),NA()) | G36: =IF(SUMPRODUCT('STAF scores'!$F$7:$Y$7,'STAF scores'!$F$11:$Y$11)>0,SUMPRODUCT('STAF scores'!F46:Y46,'STAF scores'!$F$7:$Y$7,'STAF scores'!$F$11:$Y$11)/(15*SUMPRODUCT('STAF scores'!$F$7:$Y$7,'STAF scores'!$F$11:$Y$11)),NA()) | H36: =SUMPRODUCT('STAF scores'!$F$11:$Y$11*(1-ISNUMBER('STAF scores'!F46:Y46))) | I36: =IF(H36>0,NA(),(E36+F36+G36)/3) | J36: =IF(ISNUMBER(I36),IF(ROUND(I36,2)<=0.39,"Non-Functioning",IF(ROUND(I36,2)<=0.69,"Functioning-at-Risk","Functioning")),"") | K36: =IF(ISNUMBER('STAF scores'!E46),'STAF scores'!E46,NA()) | L36: =I36*K36
B37: ='STAF scores'!B47 | C37: ='STAF scores'!C47 | D37: ='STAF scores'!D47 | E37: =IF(SUMPRODUCT('STAF scores'!$F$5:$Y$5,'STAF scores'!$F$11:$Y$11)>0,SUMPRODUCT('STAF scores'!F47:Y47,'STAF scores'!$F$5:$Y$5,'STAF scores'!$F$11:$Y$11)/(15*SUMPRODUCT('STAF scores'!$F$5:$Y$5,'STAF scores'!$F$11:$Y$11)),NA()) | F37: =IF(SUMPRODUCT('STAF scores'!$F$6:$Y$6,'STAF scores'!$F$11:$Y$11)>0,SUMPRODUCT('STAF scores'!F47:Y47,'STAF scores'!$F$6:$Y$6,'STAF scores'!$F$11:$Y$11)/(15*SUMPRODUCT('STAF scores'!$F$6:$Y$6,'STAF scores'!$F$11:$Y$11)),NA()) | G37: =IF(SUMPRODUCT('STAF scores'!$F$7:$Y$7,'STAF scores'!$F$11:$Y$11)>0,SUMPRODUCT('STAF scores'!F47:Y47,'STAF scores'!$F$7:$Y$7,'STAF scores'!$F$11:$Y$11)/(15*SUMPRODUCT('STAF scores'!$F$7:$Y$7,'STAF scores'!$F$11:$Y$11)),NA()) | H37: =SUMPRODUCT('STAF scores'!$F$11:$Y$11*(1-ISNUMBER('STAF scores'!F47:Y47))) | I37: =IF(H37>0,NA(),(E37+F37+G37)/3) | J37: =IF(ISNUMBER(I37),IF(ROUND(I37,2)<=0.39,"Non-Functioning",IF(ROUND(I37,2)<=0.69,"Functioning-at-Risk","Functioning")),"") | K37: =IF(ISNUMBER('STAF scores'!E47),'STAF scores'!E47,NA()) | L37: =I37*K37
B38: ='STAF scores'!B48 | C38: ='STAF scores'!C48 | D38: ='STAF scores'!D48 | E38: =IF(SUMPRODUCT('STAF scores'!$F$5:$Y$5,'STAF scores'!$F$11:$Y$11)>0,SUMPRODUCT('STAF scores'!F48:Y48,'STAF scores'!$F$5:$Y$5,'STAF scores'!$F$11:$Y$11)/(15*SUMPRODUCT('STAF scores'!$F$5:$Y$5,'STAF scores'!$F$11:$Y$11)),NA()) | F38: =IF(SUMPRODUCT('STAF scores'!$F$6:$Y$6,'STAF scores'!$F$11:$Y$11)>0,SUMPRODUCT('STAF scores'!F48:Y48,'STAF scores'!$F$6:$Y$6,'STAF scores'!$F$11:$Y$11)/(15*SUMPRODUCT('STAF scores'!$F$6:$Y$6,'STAF scores'!$F$11:$Y$11)),NA()) | G38: =IF(SUMPRODUCT('STAF scores'!$F$7:$Y$7,'STAF scores'!$F$11:$Y$11)>0,SUMPRODUCT('STAF scores'!F48:Y48,'STAF scores'!$F$7:$Y$7,'STAF scores'!$F$11:$Y$11)/(15*SUMPRODUCT('STAF scores'!$F$7:$Y$7,'STAF scores'!$F$11:$Y$11)),NA()) | H38: =SUMPRODUCT('STAF scores'!$F$11:$Y$11*(1-ISNUMBER('STAF scores'!F48:Y48))) | I38: =IF(H38>0,NA(),(E38+F38+G38)/3) | J38: =IF(ISNUMBER(I38),IF(ROUND(I38,2)<=0.39,"Non-Functioning",IF(ROUND(I38,2)<=0.69,"Functioning-at-Risk","Functioning")),"") | K38: =IF(ISNUMBER('STAF scores'!E48),'STAF scores'!E48,NA()) | L38: =I38*K38
B39: ='STAF scores'!B49 | C39: ='STAF scores'!C49 | D39: ='STAF scores'!D49 | E39: =IF(SUMPRODUCT('STAF scores'!$F$5:$Y$5,'STAF scores'!$F$11:$Y$11)>0,SUMPRODUCT('STAF scores'!F49:Y49,'STAF scores'!$F$5:$Y$5,'STAF scores'!$F$11:$Y$11)/(15*SUMPRODUCT('STAF scores'!$F$5:$Y$5,'STAF scores'!$F$11:$Y$11)),NA()) | F39: =IF(SUMPRODUCT('STAF scores'!$F$6:$Y$6,'STAF scores'!$F$11:$Y$11)>0,SUMPRODUCT('STAF scores'!F49:Y49,'STAF scores'!$F$6:$Y$6,'STAF scores'!$F$11:$Y$11)/(15*SUMPRODUCT('STAF scores'!$F$6:$Y$6,'STAF scores'!$F$11:$Y$11)),NA()) | G39: =IF(SUMPRODUCT('STAF scores'!$F$7:$Y$7,'STAF scores'!$F$11:$Y$11)>0,SUMPRODUCT('STAF scores'!F49:Y49,'STAF scores'!$F$7:$Y$7,'STAF scores'!$F$11:$Y$11)/(15*SUMPRODUCT('STAF scores'!$F$7:$Y$7,'STAF scores'!$F$11:$Y$11)),NA()) | H39: =SUMPRODUCT('STAF scores'!$F$11:$Y$11*(1-ISNUMBER('STAF scores'!F49:Y49))) | I39: =IF(H39>0,NA(),(E39+F39+G39)/3) | J39: =IF(ISNUMBER(I39),IF(ROUND(I39,2)<=0.39,"Non-Functioning",IF(ROUND(I39,2)<=0.69,"Functioning-at-Risk","Functioning")),"") | K39: =IF(ISNUMBER('STAF scores'!E49),'STAF scores'!E49,NA()) | L39: =I39*K39
B40: ='STAF scores'!B50 | C40: ='STAF scores'!C50 | D40: ='STAF scores'!D50 | E40: =IF(SUMPRODUCT('STAF scores'!$F$5:$Y$5,'STAF scores'!$F$11:$Y$11)>0,SUMPRODUCT('STAF scores'!F50:Y50,'STAF scores'!$F$5:$Y$5,'STAF scores'!$F$11:$Y$11)/(15*SUMPRODUCT('STAF scores'!$F$5:$Y$5,'STAF scores'!$F$11:$Y$11)),NA()) | F40: =IF(SUMPRODUCT('STAF scores'!$F$6:$Y$6,'STAF scores'!$F$11:$Y$11)>0,SUMPRODUCT('STAF scores'!F50:Y50,'STAF scores'!$F$6:$Y$6,'STAF scores'!$F$11:$Y$11)/(15*SUMPRODUCT('STAF scores'!$F$6:$Y$6,'STAF scores'!$F$11:$Y$11)),NA()) | G40: =IF(SUMPRODUCT('STAF scores'!$F$7:$Y$7,'STAF scores'!$F$11:$Y$11)>0,SUMPRODUCT('STAF scores'!F50:Y50,'STAF scores'!$F$7:$Y$7,'STAF scores'!$F$11:$Y$11)/(15*SUMPRODUCT('STAF scores'!$F$7:$Y$7,'STAF scores'!$F$11:$Y$11)),NA()) | H40: =SUMPRODUCT('STAF scores'!$F$11:$Y$11*(1-ISNUMBER('STAF scores'!F50:Y50))) | I40: =IF(H40>0,NA(),(E40+F40+G40)/3) | J40: =IF(ISNUMBER(I40),IF(ROUND(I40,2)<=0.39,"Non-Functioning",IF(ROUND(I40,2)<=0.69,"Functioning-at-Risk","Functioning")),"") | K40: =IF(ISNUMBER('STAF scores'!E50),'STAF scores'!E50,NA()) | L40: =I40*K40
... B46: ='STAF scores'!B56 | C46: ='STAF scores'!C56 | D46: ='STAF scores'!D56 | E46: =IF(SUMPRODUCT('STAF scores'!$F$5:$Y$5,'STAF scores'!$F$11:$Y$11)>0,SUMPRODUCT('STAF scores'!F56:Y56,'STAF scores'!$F$5:$Y$5,'STAF scores'!$F$11:$Y$11)/(15*SUMPRODUCT('STAF scores'!$F$5:$Y$5,'STAF scores'!$F$11:$Y$11)),NA()) | F46: =IF(SUMPRODUCT('STAF scores'!$F$6:$Y$6,'STAF scores'!$F$11:$Y$11)>0,SUMPRODUCT('STAF scores'!F56:Y56,'STAF scores'!$F$6:$Y$6,'STAF scores'!$F$11:$Y$11)/(15*SUMPRODUCT('STAF scores'!$F$6:$Y$6,'STAF scores'!$F$11:$Y$11)),NA()) | G46: =IF(SUMPRODUCT('STAF scores'!$F$7:$Y$7,'STAF scores'!$F$11:$Y$11)>0,SUMPRODUCT('STAF scores'!F56:Y56,'STAF scores'!$F$7:$Y$7,'STAF scores'!$F$11:$Y$11)/(15*SUMPRODUCT('STAF scores'!$F$7:$Y$7,'STAF scores'!$F$11:$Y$11)),NA()) | H46: =SUMPRODUCT('STAF scores'!$F$11:$Y$11*(1-ISNUMBER('STAF scores'!F56:Y56))) | I46: =IF(H46>0,NA(),(E46+F46+G46)/3) | J46: =IF(ISNUMBER(I46),IF(ROUND(I46,2)<=0.39,"Non-Functioning",IF(ROUND(I46,2)<=0.69,"Functioning-at-Risk","Functioning")),"") | K46: =IF(ISNUMBER('STAF scores'!E56),'STAF scores'!E56,NA()) | L46: =I46*K46
B47: ='STAF scores'!B57 | C47: ='STAF scores'!C57 | D47: ='STAF scores'!D57 | E47: =IF(SUMPRODUCT('STAF scores'!$F$5:$Y$5,'STAF scores'!$F$12:$Y$12)>0,SUMPRODUCT('STAF scores'!F57:Y57,'STAF scores'!$F$5:$Y$5,'STAF scores'!$F$12:$Y$12)/(15*SUMPRODUCT('STAF scores'!$F$5:$Y$5,'STAF scores'!$F$12:$Y$12)),NA()) | F47: =IF(SUMPRODUCT('STAF scores'!$F$6:$Y$6,'STAF scores'!$F$12:$Y$12)>0,SUMPRODUCT('STAF scores'!F57:Y57,'STAF scores'!$F$6:$Y$6,'STAF scores'!$F$12:$Y$12)/(15*SUMPRODUCT('STAF scores'!$F$6:$Y$6,'STAF scores'!$F$12:$Y$12)),NA()) | G47: =IF(SUMPRODUCT('STAF scores'!$F$7:$Y$7,'STAF scores'!$F$12:$Y$12)>0,SUMPRODUCT('STAF scores'!F57:Y57,'STAF scores'!$F$7:$Y$7,'STAF scores'!$F$12:$Y$12)/(15*SUMPRODUCT('STAF scores'!$F$7:$Y$7,'STAF scores'!$F$12:$Y$12)),NA()) | H47: =SUMPRODUCT('STAF scores'!$F$12:$Y$12*(1-ISNUMBER('STAF scores'!F57:Y57))) | I47: =IF(H47>0,NA(),(E47+F47+G47)/3) | J47: =IF(ISNUMBER(I47),IF(ROUND(I47,2)<=0.39,"Non-Functioning",IF(ROUND(I47,2)<=0.69,"Functioning-at-Risk","Functioning")),"") | K47: =IF(ISNUMBER('STAF scores'!E57),'STAF scores'!E57,NA()) | L47: =I47*K47
B48: ='STAF scores'!B58 | C48: ='STAF scores'!C58 | D48: ='STAF scores'!D58 | E48: =IF(SUMPRODUCT('STAF scores'!$F$5:$Y$5,'STAF scores'!$F$12:$Y$12)>0,SUMPRODUCT('STAF scores'!F58:Y58,'STAF scores'!$F$5:$Y$5,'STAF scores'!$F$12:$Y$12)/(15*SUMPRODUCT('STAF scores'!$F$5:$Y$5,'STAF scores'!$F$12:$Y$12)),NA()) | F48: =IF(SUMPRODUCT('STAF scores'!$F$6:$Y$6,'STAF scores'!$F$12:$Y$12)>0,SUMPRODUCT('STAF scores'!F58:Y58,'STAF scores'!$F$6:$Y$6,'STAF scores'!$F$12:$Y$12)/(15*SUMPRODUCT('STAF scores'!$F$6:$Y$6,'STAF scores'!$F$12:$Y$12)),NA()) | G48: =IF(SUMPRODUCT('STAF scores'!$F$7:$Y$7,'STAF scores'!$F$12:$Y$12)>0,SUMPRODUCT('STAF scores'!F58:Y58,'STAF scores'!$F$7:$Y$7,'STAF scores'!$F$12:$Y$12)/(15*SUMPRODUCT('STAF scores'!$F$7:$Y$7,'STAF scores'!$F$12:$Y$12)),NA()) | H48: =SUMPRODUCT('STAF scores'!$F$12:$Y$12*(1-ISNUMBER('STAF scores'!F58:Y58))) | I48: =IF(H48>0,NA(),(E48+F48+G48)/3) | J48: =IF(ISNUMBER(I48),IF(ROUND(I48,2)<=0.39,"Non-Functioning",IF(ROUND(I48,2)<=0.69,"Functioning-at-Risk","Functioning")),"") | K48: =IF(ISNUMBER('STAF scores'!E58),'STAF scores'!E58,NA()) | L48: =I48*K48
B49: ='STAF scores'!B59 | C49: ='STAF scores'!C59 | D49: ='STAF scores'!D59 | E49: =IF(SUMPRODUCT('STAF scores'!$F$5:$Y$5,'STAF scores'!$F$12:$Y$12)>0,SUMPRODUCT('STAF scores'!F59:Y59,'STAF scores'!$F$5:$Y$5,'STAF scores'!$F$12:$Y$12)/(15*SUMPRODUCT('STAF scores'!$F$5:$Y$5,'STAF scores'!$F$12:$Y$12)),NA()) | F49: =IF(SUMPRODUCT('STAF scores'!$F$6:$Y$6,'STAF scores'!$F$12:$Y$12)>0,SUMPRODUCT('STAF scores'!F59:Y59,'STAF scores'!$F$6:$Y$6,'STAF scores'!$F$12:$Y$12)/(15*SUMPRODUCT('STAF scores'!$F$6:$Y$6,'STAF scores'!$F$12:$Y$12)),NA()) | G49: =IF(SUMPRODUCT('STAF scores'!$F$7:$Y$7,'STAF scores'!$F$12:$Y$12)>0,SUMPRODUCT('STAF scores'!F59:Y59,'STAF scores'!$F$7:$Y$7,'STAF scores'!$F$12:$Y$12)/(15*SUMPRODUCT('STAF scores'!$F$7:$Y$7,'STAF scores'!$F$12:$Y$12)),NA()) | H49: =SUMPRODUCT('STAF scores'!$F$12:$Y$12*(1-ISNUMBER('STAF scores'!F59:Y59))) | I49: =IF(H49>0,NA(),(E49+F49+G49)/3) | J49: =IF(ISNUMBER(I49),IF(ROUND(I49,2)<=0.39,"Non-Functioning",IF(ROUND(I49,2)<=0.69,"Functioning-at-Risk","Functioning")),"") | K49: =IF(ISNUMBER('STAF scores'!E59),'STAF scores'!E59,NA()) | L49: =I49*K49
B50: ='STAF scores'!B60 | C50: ='STAF scores'!C60 | D50: ='STAF scores'!D60 | E50: =IF(SUMPRODUCT('STAF scores'!$F$5:$Y$5,'STAF scores'!$F$12:$Y$12)>0,SUMPRODUCT('STAF scores'!F60:Y60,'STAF scores'!$F$5:$Y$5,'STAF scores'!$F$12:$Y$12)/(15*SUMPRODUCT('STAF scores'!$F$5:$Y$5,'STAF scores'!$F$12:$Y$12)),NA()) | F50: =IF(SUMPRODUCT('STAF scores'!$F$6:$Y$6,'STAF scores'!$F$12:$Y$12)>0,SUMPRODUCT('STAF scores'!F60:Y60,'STAF scores'!$F$6:$Y$6,'STAF scores'!$F$12:$Y$12)/(15*SUMPRODUCT('STAF scores'!$F$6:$Y$6,'STAF scores'!$F$12:$Y$12)),NA()) | G50: =IF(SUMPRODUCT('STAF scores'!$F$7:$Y$7,'STAF scores'!$F$12:$Y$12)>0,SUMPRODUCT('STAF scores'!F60:Y60,'STAF scores'!$F$7:$Y$7,'STAF scores'!$F$12:$Y$12)/(15*SUMPRODUCT('STAF scores'!$F$7:$Y$7,'STAF scores'!$F$12:$Y$12)),NA()) | H50: =SUMPRODUCT('STAF scores'!$F$12:$Y$12*(1-ISNUMBER('STAF scores'!F60:Y60))) | I50: =IF(H50>0,NA(),(E50+F50+G50)/3) | J50: =IF(ISNUMBER(I50),IF(ROUND(I50,2)<=0.39,"Non-Functioning",IF(ROUND(I50,2)<=0.69,"Functioning-at-Risk","Functioning")),"") | K50: =IF(ISNUMBER('STAF scores'!E60),'STAF scores'!E60,NA()) | L50: =I50*K50
B51: ='STAF scores'!B61 | C51: ='STAF scores'!C61 | D51: ='STAF scores'!D61 | E51: =IF(SUMPRODUCT('STAF scores'!$F$5:$Y$5,'STAF scores'!$F$12:$Y$12)>0,SUMPRODUCT('STAF scores'!F61:Y61,'STAF scores'!$F$5:$Y$5,'STAF scores'!$F$12:$Y$12)/(15*SUMPRODUCT('STAF scores'!$F$5:$Y$5,'STAF scores'!$F$12:$Y$12)),NA()) | F51: =IF(SUMPRODUCT('STAF scores'!$F$6:$Y$6,'STAF scores'!$F$12:$Y$12)>0,SUMPRODUCT('STAF scores'!F61:Y61,'STAF scores'!$F$6:$Y$6,'STAF scores'!$F$12:$Y$12)/(15*SUMPRODUCT('STAF scores'!$F$6:$Y$6,'STAF scores'!$F$12:$Y$12)),NA()) | G51: =IF(SUMPRODUCT('STAF scores'!$F$7:$Y$7,'STAF scores'!$F$12:$Y$12)>0,SUMPRODUCT('STAF scores'!F61:Y61,'STAF scores'!$F$7:$Y$7,'STAF scores'!$F$12:$Y$12)/(15*SUMPRODUCT('STAF scores'!$F$7:$Y$7,'STAF scores'!$F$12:$Y$12)),NA()) | H51: =SUMPRODUCT('STAF scores'!$F$12:$Y$12*(1-ISNUMBER('STAF scores'!F61:Y61))) | I51: =IF(H51>0,NA(),(E51+F51+G51)/3) | J51: =IF(ISNUMBER(I51),IF(ROUND(I51,2)<=0.39,"Non-Functioning",IF(ROUND(I51,2)<=0.69,"Functioning-at-Risk","Functioning")),"") | K51: =IF(ISNUMBER('STAF scores'!E61),'STAF scores'!E61,NA()) | L51: =I51*K51
B52: ='STAF scores'!B62 | C52: ='STAF scores'!C62 | D52: ='STAF scores'!D62 | E52: =IF(SUMPRODUCT('STAF scores'!$F$5:$Y$5,'STAF scores'!$F$12:$Y$12)>0,SUMPRODUCT('STAF scores'!F62:Y62,'STAF scores'!$F$5:$Y$5,'STAF scores'!$F$12:$Y$12)/(15*SUMPRODUCT('STAF scores'!$F$5:$Y$5,'STAF scores'!$F$12:$Y$12)),NA()) | F52: =IF(SUMPRODUCT('STAF scores'!$F$6:$Y$6,'STAF scores'!$F$12:$Y$12)>0,SUMPRODUCT('STAF scores'!F62:Y62,'STAF scores'!$F$6:$Y$6,'STAF scores'!$F$12:$Y$12)/(15*SUMPRODUCT('STAF scores'!$F$6:$Y$6,'STAF scores'!$F$12:$Y$12)),NA()) | G52: =IF(SUMPRODUCT('STAF scores'!$F$7:$Y$7,'STAF scores'!$F$12:$Y$12)>0,SUMPRODUCT('STAF scores'!F62:Y62,'STAF scores'!$F$7:$Y$7,'STAF scores'!$F$12:$Y$12)/(15*SUMPRODUCT('STAF scores'!$F$7:$Y$7,'STAF scores'!$F$12:$Y$12)),NA()) | H52: =SUMPRODUCT('STAF scores'!$F$12:$Y$12*(1-ISNUMBER('STAF scores'!F62:Y62))) | I52: =IF(H52>0,NA(),(E52+F52+G52)/3) | J52: =IF(ISNUMBER(I52),IF(ROUND(I52,2)<=0.39,"Non-Functioning",IF(ROUND(I52,2)<=0.69,"Functioning-at-Risk","Functioning")),"") | K52: =IF(ISNUMBER('STAF scores'!E62),'STAF scores'!E62,NA()) | L52: =I52*K52
B53: ='STAF scores'!B63 | C53: ='STAF scores'!C63 | D53: ='STAF scores'!D63 | E53: =IF(SUMPRODUCT('STAF scores'!$F$5:$Y$5,'STAF scores'!$F$12:$Y$12)>0,SUMPRODUCT('STAF scores'!F63:Y63,'STAF scores'!$F$5:$Y$5,'STAF scores'!$F$12:$Y$12)/(15*SUMPRODUCT('STAF scores'!$F$5:$Y$5,'STAF scores'!$F$12:$Y$12)),NA()) | F53: =IF(SUMPRODUCT('STAF scores'!$F$6:$Y$6,'STAF scores'!$F$12:$Y$12)>0,SUMPRODUCT('STAF scores'!F63:Y63,'STAF scores'!$F$6:$Y$6,'STAF scores'!$F$12:$Y$12)/(15*SUMPRODUCT('STAF scores'!$F$6:$Y$6,'STAF scores'!$F$12:$Y$12)),NA()) | G53: =IF(SUMPRODUCT('STAF scores'!$F$7:$Y$7,'STAF scores'!$F$12:$Y$12)>0,SUMPRODUCT('STAF scores'!F63:Y63,'STAF scores'!$F$7:$Y$7,'STAF scores'!$F$12:$Y$12)/(15*SUMPRODUCT('STAF scores'!$F$7:$Y$7,'STAF scores'!$F$12:$Y$12)),NA()) | H53: =SUMPRODUCT('STAF scores'!$F$12:$Y$12*(1-ISNUMBER('STAF scores'!F63:Y63))) | I53: =IF(H53>0,NA(),(E53+F53+G53)/3) | J53: =IF(ISNUMBER(I53),IF(ROUND(I53,2)<=0.39,"Non-Functioning",IF(ROUND(I53,2)<=0.69,"Functioning-at-Risk","Functioning")),"") | K53: =IF(ISNUMBER('STAF scores'!E63),'STAF scores'!E63,NA()) | L53: =I53*K53
B54: ='STAF scores'!B64 | C54: ='STAF scores'!C64 | D54: ='STAF scores'!D64 | E54: =IF(SUMPRODUCT('STAF scores'!$F$5:$Y$5,'STAF scores'!$F$12:$Y$12)>0,SUMPRODUCT('STAF scores'!F64:Y64,'STAF scores'!$F$5:$Y$5,'STAF scores'!$F$12:$Y$12)/(15*SUMPRODUCT('STAF scores'!$F$5:$Y$5,'STAF scores'!$F$12:$Y$12)),NA()) | F54: =IF(SUMPRODUCT('STAF scores'!$F$6:$Y$6,'STAF scores'!$F$12:$Y$12)>0,SUMPRODUCT('STAF scores'!F64:Y64,'STAF scores'!$F$6:$Y$6,'STAF scores'!$F$12:$Y$12)/(15*SUMPRODUCT('STAF scores'!$F$6:$Y$6,'STAF scores'!$F$12:$Y$12)),NA()) | G54: =IF(SUMPRODUCT('STAF scores'!$F$7:$Y$7,'STAF scores'!$F$12:$Y$12)>0,SUMPRODUCT('STAF scores'!F64:Y64,'STAF scores'!$F$7:$Y$7,'STAF scores'!$F$12:$Y$12)/(15*SUMPRODUCT('STAF scores'!$F$7:$Y$7,'STAF scores'!$F$12:$Y$12)),NA()) | H54: =SUMPRODUCT('STAF scores'!$F$12:$Y$12*(1-ISNUMBER('STAF scores'!F64:Y64))) | I54: =IF(H54>0,NA(),(E54+F54+G54)/3) | J54: =IF(ISNUMBER(I54),IF(ROUND(I54,2)<=0.39,"Non-Functioning",IF(ROUND(I54,2)<=0.69,"Functioning-at-Risk","Functioning")),"") | K54: =IF(ISNUMBER('STAF scores'!E64),'STAF scores'!E64,NA()) | L54: =I54*K54
B55: ='STAF scores'!B65 | C55: ='STAF scores'!C65 | D55: ='STAF scores'!D65 | E55: =IF(SUMPRODUCT('STAF scores'!$F$5:$Y$5,'STAF scores'!$F$12:$Y$12)>0,SUMPRODUCT('STAF scores'!F65:Y65,'STAF scores'!$F$5:$Y$5,'STAF scores'!$F$12:$Y$12)/(15*SUMPRODUCT('STAF scores'!$F$5:$Y$5,'STAF scores'!$F$12:$Y$12)),NA()) | F55: =IF(SUMPRODUCT('STAF scores'!$F$6:$Y$6,'STAF scores'!$F$12:$Y$12)>0,SUMPRODUCT('STAF scores'!F65:Y65,'STAF scores'!$F$6:$Y$6,'STAF scores'!$F$12:$Y$12)/(15*SUMPRODUCT('STAF scores'!$F$6:$Y$6,'STAF scores'!$F$12:$Y$12)),NA()) | G55: =IF(SUMPRODUCT('STAF scores'!$F$7:$Y$7,'STAF scores'!$F$12:$Y$12)>0,SUMPRODUCT('STAF scores'!F65:Y65,'STAF scores'!$F$7:$Y$7,'STAF scores'!$F$12:$Y$12)/(15*SUMPRODUCT('STAF scores'!$F$7:$Y$7,'STAF scores'!$F$12:$Y$12)),NA()) | H55: =SUMPRODUCT('STAF scores'!$F$12:$Y$12*(1-ISNUMBER('STAF scores'!F65:Y65))) | I55: =IF(H55>0,NA(),(E55+F55+G55)/3) | J55: =IF(ISNUMBER(I55),IF(ROUND(I55,2)<=0.39,"Non-Functioning",IF(ROUND(I55,2)<=0.69,"Functioning-at-Risk","Functioning")),"") | K55: =IF(ISNUMBER('STAF scores'!E65),'STAF scores'!E65,NA()) | L55: =I55*K55
B56: ='STAF scores'!B66 | C56: ='STAF scores'!C66 | D56: ='STAF scores'!D66 | E56: =IF(SUMPRODUCT('STAF scores'!$F$5:$Y$5,'STAF scores'!$F$12:$Y$12)>0,SUMPRODUCT('STAF scores'!F66:Y66,'STAF scores'!$F$5:$Y$5,'STAF scores'!$F$12:$Y$12)/(15*SUMPRODUCT('STAF scores'!$F$5:$Y$5,'STAF scores'!$F$12:$Y$12)),NA()) | F56: =IF(SUMPRODUCT('STAF scores'!$F$6:$Y$6,'STAF scores'!$F$12:$Y$12)>0,SUMPRODUCT('STAF scores'!F66:Y66,'STAF scores'!$F$6:$Y$6,'STAF scores'!$F$12:$Y$12)/(15*SUMPRODUCT('STAF scores'!$F$6:$Y$6,'STAF scores'!$F$12:$Y$12)),NA()) | G56: =IF(SUMPRODUCT('STAF scores'!$F$7:$Y$7,'STAF scores'!$F$12:$Y$12)>0,SUMPRODUCT('STAF scores'!F66:Y66,'STAF scores'!$F$7:$Y$7,'STAF scores'!$F$12:$Y$12)/(15*SUMPRODUCT('STAF scores'!$F$7:$Y$7,'STAF scores'!$F$12:$Y$12)),NA()) | H56: =SUMPRODUCT('STAF scores'!$F$12:$Y$12*(1-ISNUMBER('STAF scores'!F66:Y66))) | I56: =IF(H56>0,NA(),(E56+F56+G56)/3) | J56: =IF(ISNUMBER(I56),IF(ROUND(I56,2)<=0.39,"Non-Functioning",IF(ROUND(I56,2)<=0.69,"Functioning-at-Risk","Functioning")),"") | K56: =IF(ISNUMBER('STAF scores'!E66),'STAF scores'!E66,NA()) | L56: =I56*K56
B57: ='STAF scores'!B67 | C57: ='STAF scores'!C67 | D57: ='STAF scores'!D67 | E57: =IF(SUMPRODUCT('STAF scores'!$F$5:$Y$5,'STAF scores'!$F$12:$Y$12)>0,SUMPRODUCT('STAF scores'!F67:Y67,'STAF scores'!$F$5:$Y$5,'STAF scores'!$F$12:$Y$12)/(15*SUMPRODUCT('STAF scores'!$F$5:$Y$5,'STAF scores'!$F$12:$Y$12)),NA()) | F57: =IF(SUMPRODUCT('STAF scores'!$F$6:$Y$6,'STAF scores'!$F$12:$Y$12)>0,SUMPRODUCT('STAF scores'!F67:Y67,'STAF scores'!$F$6:$Y$6,'STAF scores'!$F$12:$Y$12)/(15*SUMPRODUCT('STAF scores'!$F$6:$Y$6,'STAF scores'!$F$12:$Y$12)),NA()) | G57: =IF(SUMPRODUCT('STAF scores'!$F$7:$Y$7,'STAF scores'!$F$12:$Y$12)>0,SUMPRODUCT('STAF scores'!F67:Y67,'STAF scores'!$F$7:$Y$7,'STAF scores'!$F$12:$Y$12)/(15*SUMPRODUCT('STAF scores'!$F$7:$Y$7,'STAF scores'!$F$12:$Y$12)),NA()) | H57: =SUMPRODUCT('STAF scores'!$F$12:$Y$12*(1-ISNUMBER('STAF scores'!F67:Y67))) | I57: =IF(H57>0,NA(),(E57+F57+G57)/3) | J57: =IF(ISNUMBER(I57),IF(ROUND(I57,2)<=0.39,"Non-Functioning",IF(ROUND(I57,2)<=0.69,"Functioning-at-Risk","Functioning")),"") | K57: =IF(ISNUMBER('STAF scores'!E67),'STAF scores'!E67,NA()) | L57: =I57*K57
...

Sheet Benefits
A1: Benefits: condition units at each target year
A2: STAF mode: condition units (ECI x quantity) at each target year, from the STAF roll-up sheet.
A4: Key | B4: Site | C4: Alternative | D4: Component | E4: Condition units (CU) | K4: Average (AACU)
E5: =Parameters!$B$14 | F5: =Parameters!$C$14 | G5: =Parameters!$D$14 | H5: =Parameters!$E$14 | I5: =Parameters!$F$14 | J5: =Parameters!$G$14
A6: =B6&"|"&C6 | B6: R1 | C6: FWOP | D6: Condition units | E6: ='STAF roll-up'!L5 | F6: ='STAF roll-up'!L6 | G6: ='STAF roll-up'!L7 | H6: ='STAF roll-up'!L8 | I6: ='STAF roll-up'!L9 | J6: ='STAF roll-up'!L10 | K6: =SUMPRODUCT($F$5:$J$5-$E$5:$I$5,(F6:J6+E6:I6)/2)/($J$5-$E$5)
A7: =B7&"|"&C7 | B7: R1 | C7: A1 | D7: Condition units | E7: ='STAF roll-up'!L11 | F7: ='STAF roll-up'!L12 | G7: ='STAF roll-up'!L13 | H7: ='STAF roll-up'!L14 | I7: ='STAF roll-up'!L15 | J7: ='STAF roll-up'!L16 | K7: =SUMPRODUCT($F$5:$J$5-$E$5:$I$5,(F7:J7+E7:I7)/2)/($J$5-$E$5)
A8: =B8&"|"&C8 | B8: R1 | C8: A2 | D8: Condition units | E8: ='STAF roll-up'!L17 | F8: ='STAF roll-up'!L18 | G8: ='STAF roll-up'!L19 | H8: ='STAF roll-up'!L20 | I8: ='STAF roll-up'!L21 | J8: ='STAF roll-up'!L22 | K8: =SUMPRODUCT($F$5:$J$5-$E$5:$I$5,(F8:J8+E8:I8)/2)/($J$5-$E$5)
A9: =B9&"|"&C9 | B9: R1 | C9: A3 | D9: Condition units | E9: ='STAF roll-up'!L23 | F9: ='STAF roll-up'!L24 | G9: ='STAF roll-up'!L25 | H9: ='STAF roll-up'!L26 | I9: ='STAF roll-up'!L27 | J9: ='STAF roll-up'!L28 | K9: =SUMPRODUCT($F$5:$J$5-$E$5:$I$5,(F9:J9+E9:I9)/2)/($J$5-$E$5)
A10: =B10&"|"&C10 | B10: R2 | C10: FWOP | D10: Condition units | E10: ='STAF roll-up'!L29 | F10: ='STAF roll-up'!L30 | G10: ='STAF roll-up'!L31 | H10: ='STAF roll-up'!L32 | I10: ='STAF roll-up'!L33 | J10: ='STAF roll-up'!L34 | K10: =SUMPRODUCT($F$5:$J$5-$E$5:$I$5,(F10:J10+E10:I10)/2)/($J$5-$E$5)
A11: =B11&"|"&C11 | B11: R2 | C11: A1 | D11: Condition units | E11: ='STAF roll-up'!L35 | F11: ='STAF roll-up'!L36 | G11: ='STAF roll-up'!L37 | H11: ='STAF roll-up'!L38 | I11: ='STAF roll-up'!L39 | J11: ='STAF roll-up'!L40 | K11: =SUMPRODUCT($F$5:$J$5-$E$5:$I$5,(F11:J11+E11:I11)/2)/($J$5-$E$5)
A12: =B12&"|"&C12 | B12: R2 | C12: A2 | D12: Condition units | E12: ='STAF roll-up'!L41 | F12: ='STAF roll-up'!L42 | G12: ='STAF roll-up'!L43 | H12: ='STAF roll-up'!L44 | I12: ='STAF roll-up'!L45 | J12: ='STAF roll-up'!L46 | K12: =SUMPRODUCT($F$5:$J$5-$E$5:$I$5,(F12:J12+E12:I12)/2)/($J$5-$E$5)
A13: =B13&"|"&C13 | B13: R3 | C13: FWOP | D13: Condition units | E13: ='STAF roll-up'!L47 | F13: ='STAF roll-up'!L48 | G13: ='STAF roll-up'!L49 | H13: ='STAF roll-up'!L50 | I13: ='STAF roll-up'!L51 | J13: ='STAF roll-up'!L52 | K13: =SUMPRODUCT($F$5:$J$5-$E$5:$I$5,(F13:J13+E13:I13)/2)/($J$5-$E$5)
