Workbook
Name in_rate: Parameters!$B$4
Name in_poa: Parameters!$B$5
Name in_ppy: Parameters!$B$6
Name in_idc_method: Parameters!$B$7
Name in_timing: Parameters!$B$8
Name in_cost_dp: Parameters!$B$9
Name in_out_dp: Parameters!$B$10
Name calc_crf: Parameters!$B$11
Name out_status: 'Read me'!$B$10
Name out_changed: 'Read me'!$B$11
Name out_mismatch: 'Read me'!$B$12

Sheet Read me
A1: Small test: CE/ICA calculator
A2: Cost-effectiveness and incremental cost analysis, as live formulas.
A4: Study | B4: Small test
A5: Generated by | B5: CEICA 0.1.0 (engine 1)
A6: Project digest | B6: f4d289ead17a
A7: Discount rate | B7: 3 percent
A8: Period of analysis | B8: 50 years
A10: Status | B10: =IF(B11=0,IF(B12=0,"Unchanged: matches the CEICA export","ERROR: results differ from the export although no input changed"),"Edited: "&B11&" input cells changed since the export")
A11: Inputs changed | B11: =(SUMPRODUCT(1*(Parameters!B4:B10<>'snap Parameters'!B4:B10))+SUMPRODUCT(1*(Parameters!B14:D14<>'snap Parameters'!B14:D14))+SUMPRODUCT(1*(Benefits!F6:H14<>'snap Benefits'!F6:H14))+SUMPRODUCT(1*(Costs!D6:G14<>'snap Costs'!D6:G14))+SUMPRODUCT(1*(Costs!L6:L14<>'snap Costs'!L6:L14))+SUMPRODUCT(1*(OMRRR!F5:M8<>'snap OMRRR'!F5:M8))+SUMPRODUCT(1*(Sites!C5:C7<>'snap Sites'!C5:C7))+SUMPRODUCT(1*('Watershed plans'!AA12:AA19<>'snap Watershed plans'!AA12:AA19))+SUMPRODUCT(1*('Watershed summary'!K50:L89<>'snap Watershed summary'!K50:L89))+SUMPRODUCT(1*('Watershed summary'!B93:B93<>'snap Watershed summary'!B93:B93)))
A12: Results that differ from the export | B12: =(SUMPRODUCT(1*(ABS(Summary!G5:G13-'snap Summary'!G5:G13)>1e-06))+SUMPRODUCT(1*(ABS(Summary!L5:L13-'snap Summary'!L5:L13)>0.0001))+SUMPRODUCT(1*('Site CE-ICA'!L6:L8<>'snap Site CE-ICA'!L6:L8))+SUMPRODUCT(1*('Site CE-ICA'!P6:P8<>'snap Site CE-ICA'!P6:P8))+SUMPRODUCT(1*('Site CE-ICA'!L11:L14<>'snap Site CE-ICA'!L11:L14))+SUMPRODUCT(1*('Site CE-ICA'!P11:P14<>'snap Site CE-ICA'!P11:P14))+SUMPRODUCT(1*('Site CE-ICA'!L17:L18<>'snap Site CE-ICA'!L17:L18))+SUMPRODUCT(1*('Site CE-ICA'!P17:P18<>'snap Site CE-ICA'!P17:P18))+SUMPRODUCT(1*('Watershed plans'!O12:O19<>'snap Watershed plans'!O12:O19))+SUMPRODUCT(1*('Watershed plans'!S12:S19<>'snap Watershed plans'!S12:S19)))
A14: How to use
A15: - Orange cells are inputs; grey cells are formulas. Sheets are protected (password 'ceica') only to prevent accidental edits.
A16: - Change any orange cell: annualization, site CE/ICA, the watershed plans and the summary update. Changed inputs turn yellow.
A17: - To add sites, alternatives or years, make the change in CEICA and export again.
A18: - Import this workbook in CEICA to bring your changes back into the project.
A20: Legend
A21: Input
A22: Formula
A23: Changed since export

Sheet Parameters
A1: Parameters
A2: Economics and conventions. Orange cells are inputs.
A3: Parameter | B3: Value
A4: Discount rate | B4: 0.03
A5: Period of analysis (years) | B5: 50
A6: Interest during construction: periods per year | B6: 12
A7: Interest during construction: spending in each period (END, MIDDLE or START) | B7: END
A8: OMRRR discounting (END_OF_YEAR or MID_YEAR) | B8: END_OF_YEAR
A9: Cost decimals kept for CE/ICA | B9: 2
A10: Output decimals kept for CE/ICA | B10: 3
A11: Capital recovery factor | B11: =IF(in_rate=0,1/in_poa,in_rate*(1+in_rate)^in_poa/((1+in_rate)^in_poa-1))
A13: Target years | B13: Year 1 | C13: Year 2 | D13: Year 3
A14: Years (first to last) | B14: 0 | C14: 5 | D14: 50

Sheet Benefits
A1: Benefits: habitat units by module
A2: One row per module, site and alternative; the Summary adds the modules' averages. Total: habitat units entered at each target year. Averages are the area under straight lines between target years.
A4: Key | B4: Site | C4: Alternative | D4: Module | E4: Method | F4: Habitat units (HU) | I4: Average (AAHU)
F5: =Parameters!$B$14 | G5: =Parameters!$C$14 | H5: =Parameters!$D$14
A6: =B6&"|"&C6 | B6: A | C6: NA | D6: Total | E6: Habitat units | F6: 1 | G6: 1 | H6: 1 | I6: =SUMPRODUCT($G$5:$H$5-$F$5:$G$5,(G6:H6+F6:G6)/2)/($H$5-$F$5)
A7: =B7&"|"&C7 | B7: A | C7: A1 | D7: Total | E7: Habitat units | F7: 1 | G7: 5 | H7: 6 | I7: =SUMPRODUCT($G$5:$H$5-$F$5:$G$5,(G7:H7+F7:G7)/2)/($H$5-$F$5)
A8: =B8&"|"&C8 | B8: A | C8: A2 | D8: Total | E8: Habitat units | F8: 1 | G8: 3 | H8: 3.5 | I8: =SUMPRODUCT($G$5:$H$5-$F$5:$G$5,(G8:H8+F8:G8)/2)/($H$5-$F$5)
A9: =B9&"|"&C9 | B9: B | C9: NA | D9: Total | E9: Habitat units | F9: 2 | G9: 2 | H9: 2 | I9: =SUMPRODUCT($G$5:$H$5-$F$5:$G$5,(G9:H9+F9:G9)/2)/($H$5-$F$5)
A10: =B10&"|"&C10 | B10: B | C10: B1 | D10: Total | E10: Habitat units | F10: 2 | G10: 4 | H10: 4 | I10: =SUMPRODUCT($G$5:$H$5-$F$5:$G$5,(G10:H10+F10:G10)/2)/($H$5-$F$5)
A11: =B11&"|"&C11 | B11: B | C11: B2 | D11: Total | E11: Habitat units | F11: 2 | G11: 4 | H11: 4 | I11: =SUMPRODUCT($G$5:$H$5-$F$5:$G$5,(G11:H11+F11:G11)/2)/($H$5-$F$5)
A12: =B12&"|"&C12 | B12: B | C12: B3 | D12: Total | E12: Habitat units | F12: 2 | G12: 6 | H12: 6 | I12: =SUMPRODUCT($G$5:$H$5-$F$5:$G$5,(G12:H12+F12:G12)/2)/($H$5-$F$5)
A13: =B13&"|"&C13 | B13: C | C13: NA | D13: Total | E13: Habitat units | F13: 0.5 | G13: 0.5 | H13: 0.5 | I13: =SUMPRODUCT($G$5:$H$5-$F$5:$G$5,(G13:H13+F13:G13)/2)/($H$5-$F$5)
A14: =B14&"|"&C14 | B14: C | C14: C1 | D14: Total | E14: Habitat units | F14: 0.5 | G14: 2 | H14: 2.5 | I14: =SUMPRODUCT($G$5:$H$5-$F$5:$G$5,(G14:H14+F14:G14)/2)/($H$5-$F$5)

Sheet Costs
A1: Costs: first costs, interest during construction and OMRRR
A2: First costs are base-year lump sums. Interest during construction accrues on the categories marked *, spent evenly over the construction months.
N3: Average annual cost by part
A4: Key | B4: Site | C4: Alternative | D4: Construction * | E4: Monitoring | F4: Adaptive management | G4: Construction months | H4: IDC base | I4: Interest during construction | J4: OMRRR present value | K4: Total present value | L4: Average annual cost entered | M4: Average annual cost | N4: Construction | O4: Monitoring | P4: Adaptive management | Q4: Interest during construction | R4: OMRRR
D5: construction | E5: monitoring | F5: adaptive_management
A6: =B6&"|"&C6 | B6: A | C6: NA | G6: 0 | H6: =D6 | I6: =IF(OR(G6=0,in_rate=0,H6=0),0,H6/G6*(IF(in_idc_method="START",1+((1+in_rate)^(1/in_ppy)-1),IF(in_idc_method="MIDDLE",1+((1+in_rate)^(1/in_ppy)-1)/2,1))*((1+in_rate)^(G6/in_ppy)-1)/((1+in_rate)^(1/in_ppy)-1)-G6)) | J6: =SUMIFS(OMRRR!$S$5:$S$8,OMRRR!$A$5:$A$8,A6) | K6: =SUM(D6:F6)+I6+J6 | M6: =IF(ISNUMBER(L6),L6,calc_crf*K6) | N6: =calc_crf*D6 | O6: =calc_crf*E6 | P6: =calc_crf*F6 | Q6: =calc_crf*I6 | R6: =calc_crf*J6
A7: =B7&"|"&C7 | B7: A | C7: A1 | D7: 300000 | E7: 20000 | G7: 6 | H7: =D7 | I7: =IF(OR(G7=0,in_rate=0,H7=0),0,H7/G7*(IF(in_idc_method="START",1+((1+in_rate)^(1/in_ppy)-1),IF(in_idc_method="MIDDLE",1+((1+in_rate)^(1/in_ppy)-1)/2,1))*((1+in_rate)^(G7/in_ppy)-1)/((1+in_rate)^(1/in_ppy)-1)-G7)) | J7: =SUMIFS(OMRRR!$S$5:$S$8,OMRRR!$A$5:$A$8,A7) | K7: =SUM(D7:F7)+I7+J7 | M7: =IF(ISNUMBER(L7),L7,calc_crf*K7) | N7: =calc_crf*D7 | O7: =calc_crf*E7 | P7: =calc_crf*F7 | Q7: =calc_crf*I7 | R7: =calc_crf*J7
A8: =B8&"|"&C8 | B8: A | C8: A2 | D8: 150000 | G8: 6 | H8: =D8 | I8: =IF(OR(G8=0,in_rate=0,H8=0),0,H8/G8*(IF(in_idc_method="START",1+((1+in_rate)^(1/in_ppy)-1),IF(in_idc_method="MIDDLE",1+((1+in_rate)^(1/in_ppy)-1)/2,1))*((1+in_rate)^(G8/in_ppy)-1)/((1+in_rate)^(1/in_ppy)-1)-G8)) | J8: =SUMIFS(OMRRR!$S$5:$S$8,OMRRR!$A$5:$A$8,A8) | K8: =SUM(D8:F8)+I8+J8 | M8: =IF(ISNUMBER(L8),L8,calc_crf*K8) | N8: =calc_crf*D8 | O8: =calc_crf*E8 | P8: =calc_crf*F8 | Q8: =calc_crf*I8 | R8: =calc_crf*J8
A9: =B9&"|"&C9 | B9: B | C9: NA | G9: 0 | H9: =D9 | I9: =IF(OR(G9=0,in_rate=0,H9=0),0,H9/G9*(IF(in_idc_method="START",1+((1+in_rate)^(1/in_ppy)-1),IF(in_idc_method="MIDDLE",1+((1+in_rate)^(1/in_ppy)-1)/2,1))*((1+in_rate)^(G9/in_ppy)-1)/((1+in_rate)^(1/in_ppy)-1)-G9)) | J9: =SUMIFS(OMRRR!$S$5:$S$8,OMRRR!$A$5:$A$8,A9) | K9: =SUM(D9:F9)+I9+J9 | M9: =IF(ISNUMBER(L9),L9,calc_crf*K9) | N9: =calc_crf*D9 | O9: =calc_crf*E9 | P9: =calc_crf*F9 | Q9: =calc_crf*I9 | R9: =calc_crf*J9
A10: =B10&"|"&C10 | B10: B | C10: B1 | D10: 100000 | G10: 3 | H10: =D10 | I10: =IF(OR(G10=0,in_rate=0,H10=0),0,H10/G10*(IF(in_idc_method="START",1+((1+in_rate)^(1/in_ppy)-1),IF(in_idc_method="MIDDLE",1+((1+in_rate)^(1/in_ppy)-1)/2,1))*((1+in_rate)^(G10/in_ppy)-1)/((1+in_rate)^(1/in_ppy)-1)-G10)) | J10: =SUMIFS(OMRRR!$S$5:$S$8,OMRRR!$A$5:$A$8,A10) | K10: =SUM(D10:F10)+I10+J10 | M10: =IF(ISNUMBER(L10),L10,calc_crf*K10) | N10: =calc_crf*D10 | O10: =calc_crf*E10 | P10: =calc_crf*F10 | Q10: =calc_crf*I10 | R10: =calc_crf*J10
A11: =B11&"|"&C11 | B11: B | C11: B2 | D11: 100000 | G11: 3 | H11: =D11 | I11: =IF(OR(G11=0,in_rate=0,H11=0),0,H11/G11*(IF(in_idc_method="START",1+((1+in_rate)^(1/in_ppy)-1),IF(in_idc_method="MIDDLE",1+((1+in_rate)^(1/in_ppy)-1)/2,1))*((1+in_rate)^(G11/in_ppy)-1)/((1+in_rate)^(1/in_ppy)-1)-G11)) | J11: =SUMIFS(OMRRR!$S$5:$S$8,OMRRR!$A$5:$A$8,A11) | K11: =SUM(D11:F11)+I11+J11 | M11: =IF(ISNUMBER(L11),L11,calc_crf*K11) | N11: =calc_crf*D11 | O11: =calc_crf*E11 | P11: =calc_crf*F11 | Q11: =calc_crf*I11 | R11: =calc_crf*J11
A12: =B12&"|"&C12 | B12: B | C12: B3 | D12: 200000 | G12: 3 | H12: =D12 | I12: =IF(OR(G12=0,in_rate=0,H12=0),0,H12/G12*(IF(in_idc_method="START",1+((1+in_rate)^(1/in_ppy)-1),IF(in_idc_method="MIDDLE",1+((1+in_rate)^(1/in_ppy)-1)/2,1))*((1+in_rate)^(G12/in_ppy)-1)/((1+in_rate)^(1/in_ppy)-1)-G12)) | J12: =SUMIFS(OMRRR!$S$5:$S$8,OMRRR!$A$5:$A$8,A12) | K12: =SUM(D12:F12)+I12+J12 | M12: =IF(ISNUMBER(L12),L12,calc_crf*K12) | N12: =calc_crf*D12 | O12: =calc_crf*E12 | P12: =calc_crf*F12 | Q12: =calc_crf*I12 | R12: =calc_crf*J12
A13: =B13&"|"&C13 | B13: C | C13: NA | G13: 0 | H13: =D13 | I13: =IF(OR(G13=0,in_rate=0,H13=0),0,H13/G13*(IF(in_idc_method="START",1+((1+in_rate)^(1/in_ppy)-1),IF(in_idc_method="MIDDLE",1+((1+in_rate)^(1/in_ppy)-1)/2,1))*((1+in_rate)^(G13/in_ppy)-1)/((1+in_rate)^(1/in_ppy)-1)-G13)) | J13: =SUMIFS(OMRRR!$S$5:$S$8,OMRRR!$A$5:$A$8,A13) | K13: =SUM(D13:F13)+I13+J13 | M13: =IF(ISNUMBER(L13),L13,calc_crf*K13) | N13: =calc_crf*D13 | O13: =calc_crf*E13 | P13: =calc_crf*F13 | Q13: =calc_crf*I13 | R13: =calc_crf*J13
A14: =B14&"|"&C14 | B14: C | C14: C1 | D14: 90000 | G14: 6 | H14: =D14 | I14: =IF(OR(G14=0,in_rate=0,H14=0),0,H14/G14*(IF(in_idc_method="START",1+((1+in_rate)^(1/in_ppy)-1),IF(in_idc_method="MIDDLE",1+((1+in_rate)^(1/in_ppy)-1)/2,1))*((1+in_rate)^(G14/in_ppy)-1)/((1+in_rate)^(1/in_ppy)-1)-G14)) | J14: =SUMIFS(OMRRR!$S$5:$S$8,OMRRR!$A$5:$A$8,A14) | K14: =SUM(D14:F14)+I14+J14 | M14: =IF(ISNUMBER(L14),L14,calc_crf*K14) | N14: =calc_crf*D14 | O14: =calc_crf*E14 | P14: =calc_crf*F14 | Q14: =calc_crf*I14 | R14: =calc_crf*J14

Sheet OMRRR
A1: OMRRR: recurring operation, maintenance, repair, replacement and rehabilitation
A2: Each item costs the amount per occurrence every N years from the first year to the last (blank: every N years through the period of analysis). Basis: FIXED amount, PERCENT of a first-cost category, or RATE x quantity.
A4: Key | B4: Site | C4: Alternative | D4: Item | E4: Basis | F4: Amount | G4: Percent | H4: Category | I4: Unit rate | J4: Quantity | K4: Every N years | L4: First year | M4: Last year | N4: Amount per occurrence | O4: First | P4: Last | Q4: Occurrences | R4: Present value, end of year | S4: Present value
A5: =B5&"|"&C5 | B5: A | C5: A1 | D5: Annual O&M | E5: FIXED | F5: 2500 | K5: 1 | N5: =IF(E5="FIXED",F5,IF(E5="PERCENT",G5*IFERROR(INDEX(Costs!$D$6:$F$14,MATCH(A5,Costs!$A$6:$A$14,0),MATCH(H5,Costs!$D$5:$F$5,0)),0),I5*J5)) | O5: =IF(ISNUMBER(L5),L5,K5) | P5: =IF(ISNUMBER(M5),MIN(M5,in_poa),in_poa) | Q5: =IF(P5<O5,0,INT((P5-O5)/K5)+1) | R5: =IF(Q5=0,0,IF(in_rate=0,N5*Q5,N5*(1+in_rate)^(-O5)*(1-(1+in_rate)^(-K5*Q5))/(1-(1+in_rate)^(-K5)))) | S5: =IF(in_timing="MID_YEAR",IF(O5=0,IF(Q5=0,0,N5+(R5-N5)*(1+in_rate)^0.5),R5*(1+in_rate)^0.5),R5)
A6: =B6&"|"&C6 | B6: A | C6: A2 | D6: Repair | E6: PERCENT | G6: 0.1 | H6: construction | K6: 20 | N6: =IF(E6="FIXED",F6,IF(E6="PERCENT",G6*IFERROR(INDEX(Costs!$D$6:$F$14,MATCH(A6,Costs!$A$6:$A$14,0),MATCH(H6,Costs!$D$5:$F$5,0)),0),I6*J6)) | O6: =IF(ISNUMBER(L6),L6,K6) | P6: =IF(ISNUMBER(M6),MIN(M6,in_poa),in_poa) | Q6: =IF(P6<O6,0,INT((P6-O6)/K6)+1) | R6: =IF(Q6=0,0,IF(in_rate=0,N6*Q6,N6*(1+in_rate)^(-O6)*(1-(1+in_rate)^(-K6*Q6))/(1-(1+in_rate)^(-K6)))) | S6: =IF(in_timing="MID_YEAR",IF(O6=0,IF(Q6=0,0,N6+(R6-N6)*(1+in_rate)^0.5),R6*(1+in_rate)^0.5),R6)
A7: =B7&"|"&C7 | B7: A | C7: A2 | D7: Inspection | E7: RATE | I7: 4 | J7: 1200 | K7: 2 | N7: =IF(E7="FIXED",F7,IF(E7="PERCENT",G7*IFERROR(INDEX(Costs!$D$6:$F$14,MATCH(A7,Costs!$A$6:$A$14,0),MATCH(H7,Costs!$D$5:$F$5,0)),0),I7*J7)) | O7: =IF(ISNUMBER(L7),L7,K7) | P7: =IF(ISNUMBER(M7),MIN(M7,in_poa),in_poa) | Q7: =IF(P7<O7,0,INT((P7-O7)/K7)+1) | R7: =IF(Q7=0,0,IF(in_rate=0,N7*Q7,N7*(1+in_rate)^(-O7)*(1-(1+in_rate)^(-K7*Q7))/(1-(1+in_rate)^(-K7)))) | S7: =IF(in_timing="MID_YEAR",IF(O7=0,IF(Q7=0,0,N7+(R7-N7)*(1+in_rate)^0.5),R7*(1+in_rate)^0.5),R7)
A8: =B8&"|"&C8 | B8: C | C8: C1 | D8: Annual O&M | E8: FIXED | F8: 2500 | K8: 1 | N8: =IF(E8="FIXED",F8,IF(E8="PERCENT",G8*IFERROR(INDEX(Costs!$D$6:$F$14,MATCH(A8,Costs!$A$6:$A$14,0),MATCH(H8,Costs!$D$5:$F$5,0)),0),I8*J8)) | O8: =IF(ISNUMBER(L8),L8,K8) | P8: =IF(ISNUMBER(M8),MIN(M8,in_poa),in_poa) | Q8: =IF(P8<O8,0,INT((P8-O8)/K8)+1) | R8: =IF(Q8=0,0,IF(in_rate=0,N8*Q8,N8*(1+in_rate)^(-O8)*(1-(1+in_rate)^(-K8*Q8))/(1-(1+in_rate)^(-K8)))) | S8: =IF(in_timing="MID_YEAR",IF(O8=0,IF(Q8=0,0,N8+(R8-N8)*(1+in_rate)^0.5),R8*(1+in_rate)^0.5),R8)

Sheet Summary
A1: Summary of inputs to CE/ICA
A2: Lift is each alternative's AAHU above No Action; the CE/ICA cost is its average annual cost above No Action.
A4: Key | B4: Site | C4: Alternative | D4: Name | E4: No Action | F4: Outputs (AAHU) | G4: Lift (AAHU) | H4: Construction cost | I4: First costs | J4: Interest during construction | K4: OMRRR present value | L4: Average annual cost | M4: Cost above No Action | N4: Unit cost ($/AAHU)
A5: =B5&"|"&C5 | B5: A | C5: NA | D5: NA | E5: 1 | F5: =SUMIFS(Benefits!$I$6:$I$14,Benefits!$A$6:$A$14,A5) | G5: =F5-$F$5 | H5: =Costs!D6 | I5: =SUM(Costs!D6:F6) | J5: =Costs!I6 | K5: =Costs!J6 | L5: =Costs!M6 | M5: =L5-$L$5 | N5: =IF(G5>0,M5/G5,"n/a")
A6: =B6&"|"&C6 | B6: A | C6: A1 | D6: A1 | E6: 0 | F6: =SUMIFS(Benefits!$I$6:$I$14,Benefits!$A$6:$A$14,A6) | G6: =F6-$F$5 | H6: =Costs!D7 | I6: =SUM(Costs!D7:F7) | J6: =Costs!I7 | K6: =Costs!J7 | L6: =Costs!M7 | M6: =L6-$L$5 | N6: =IF(G6>0,M6/G6,"n/a")
A7: =B7&"|"&C7 | B7: A | C7: A2 | D7: A2 | E7: 0 | F7: =SUMIFS(Benefits!$I$6:$I$14,Benefits!$A$6:$A$14,A7) | G7: =F7-$F$5 | H7: =Costs!D8 | I7: =SUM(Costs!D8:F8) | J7: =Costs!I8 | K7: =Costs!J8 | L7: =Costs!M8 | M7: =L7-$L$5 | N7: =IF(G7>0,M7/G7,"n/a")
A8: =B8&"|"&C8 | B8: B | C8: NA | D8: NA | E8: 1 | F8: =SUMIFS(Benefits!$I$6:$I$14,Benefits!$A$6:$A$14,A8) | G8: =F8-$F$8 | H8: =Costs!D9 | I8: =SUM(Costs!D9:F9) | J8: =Costs!I9 | K8: =Costs!J9 | L8: =Costs!M9 | M8: =L8-$L$8 | N8: =IF(G8>0,M8/G8,"n/a")
A9: =B9&"|"&C9 | B9: B | C9: B1 | D9: B1 | E9: 0 | F9: =SUMIFS(Benefits!$I$6:$I$14,Benefits!$A$6:$A$14,A9) | G9: =F9-$F$8 | H9: =Costs!D10 | I9: =SUM(Costs!D10:F10) | J9: =Costs!I10 | K9: =Costs!J10 | L9: =Costs!M10 | M9: =L9-$L$8 | N9: =IF(G9>0,M9/G9,"n/a")
A10: =B10&"|"&C10 | B10: B | C10: B2 | D10: B2 | E10: 0 | F10: =SUMIFS(Benefits!$I$6:$I$14,Benefits!$A$6:$A$14,A10) | G10: =F10-$F$8 | H10: =Costs!D11 | I10: =SUM(Costs!D11:F11) | J10: =Costs!I11 | K10: =Costs!J11 | L10: =Costs!M11 | M10: =L10-$L$8 | N10: =IF(G10>0,M10/G10,"n/a")
A11: =B11&"|"&C11 | B11: B | C11: B3 | D11: B3 | E11: 0 | F11: =SUMIFS(Benefits!$I$6:$I$14,Benefits!$A$6:$A$14,A11) | G11: =F11-$F$8 | H11: =Costs!D12 | I11: =SUM(Costs!D12:F12) | J11: =Costs!I12 | K11: =Costs!J12 | L11: =Costs!M12 | M11: =L11-$L$8 | N11: =IF(G11>0,M11/G11,"n/a")
A12: =B12&"|"&C12 | B12: C | C12: NA | D12: NA | E12: 1 | F12: =SUMIFS(Benefits!$I$6:$I$14,Benefits!$A$6:$A$14,A12) | G12: =F12-$F$12 | H12: =Costs!D13 | I12: =SUM(Costs!D13:F13) | J12: =Costs!I13 | K12: =Costs!J13 | L12: =Costs!M13 | M12: =L12-$L$12 | N12: =IF(G12>0,M12/G12,"n/a")
A13: =B13&"|"&C13 | B13: C | C13: C1 | D13: C1 | E13: 0 | F13: =SUMIFS(Benefits!$I$6:$I$14,Benefits!$A$6:$A$14,A13) | G13: =F13-$F$12 | H13: =Costs!D14 | I13: =SUM(Costs!D14:F14) | J13: =Costs!I14 | K13: =Costs!J14 | L13: =Costs!M14 | M13: =L13-$L$12 | N13: =IF(G13>0,M13/G13,"n/a")

Sheet Site CE-ICA
A1: Site-by-site CE/ICA
A2: Cost-effective: no alternative gives the same output for less, or more output for no more. Best buy: on the lower hull from No Action (IWR Planning Suite II rules).
A4: Key | B4: Site | C4: Alternative | D4: Name | E4: No Action | F4: Ordinal | G4: Lift (AAHU) | H4: Cost above No Action | I4: Lift (scaled) | J4: Cost (scaled) | K4: Dominated by | L4: Cost-effective | M4: Candidate | N4: Slope in (max) | O4: Slope out (min) | P4: Best buy | Q4: Best-buy step | R4: Previous lift (scaled) | S4: Previous cost (scaled) | T4: Incremental output | U4: Incremental cost | V4: Incremental cost per unit | W4: Unit cost | X4: Recommended
B5: A Upper
A6: =B6&"|"&C6 | B6: A | C6: NA | D6: NA | E6: 1 | F6: 1 | G6: =Summary!G5 | H6: =Summary!M5 | I6: =ROUND(G6*10^in_out_dp,0) | J6: =ROUND(H6*10^in_cost_dp,0) | K6: =SUMPRODUCT(($I$6:$I$8=I6)*($J$6:$J$8<J6)+($I$6:$I$8>I6)*($J$6:$J$8<=J6)) | L6: =IF(OR(E6=1,K6=0),1,0) | M6: =IF(AND(L6=1,E6=0,I6>0),1,0) | N6: =IF(M6=1,MAX(J6/I6,SUMPRODUCT(MAX(((J6-$J$6:$J$8)*($M$6:$M$8*($I$6:$I$8<I6)))/((I6-$I$6:$I$8)*($M$6:$M$8*($I$6:$I$8<I6))+1-($M$6:$M$8*($I$6:$I$8<I6)))-(1-($M$6:$M$8*($I$6:$I$8<I6)))*1E+300))),0) | O6: =IF(M6=1,SUMPRODUCT(MIN(((($J$6:$J$8-J6)*($M$6:$M$8*($I$6:$I$8>I6)))/(($I$6:$I$8-I6)*($M$6:$M$8*($I$6:$I$8>I6))+1-($M$6:$M$8*($I$6:$I$8>I6)))+(1-($M$6:$M$8*($I$6:$I$8>I6)))*1E+300))),0) | P6: =IF(E6=1,1,IF(AND(M6=1,N6<=O6),1,0)) | Q6: =IF(P6=1,1+SUMPRODUCT($P$6:$P$8*(($I$6:$I$8<I6)+($I$6:$I$8=I6)*($F$6:$F$8<F6))),0) | R6: =IF(Q6<=1,0,SUMPRODUCT(($Q$6:$Q$8=Q6-1)*$I$6:$I$8)) | S6: =IF(Q6<=1,0,SUMPRODUCT(($Q$6:$Q$8=Q6-1)*$J$6:$J$8)) | T6: =IF(Q6=0,"",(I6-R6)/10^in_out_dp) | U6: =IF(Q6=0,"",(J6-S6)/10^in_cost_dp) | V6: =IF(Q6=0,"",IF(I6=R6,0,U6/T6)) | W6: =IF(I6>0,(J6/10^in_cost_dp)/(I6/10^in_out_dp),"n/a") | X6: =IF(Sites!$C$5=C6,1,0)
A7: =B7&"|"&C7 | B7: A | C7: A1 | D7: A1 | E7: 0 | F7: 2 | G7: =Summary!G6 | H7: =Summary!M6 | I7: =ROUND(G7*10^in_out_dp,0) | J7: =ROUND(H7*10^in_cost_dp,0) | K7: =SUMPRODUCT(($I$6:$I$8=I7)*($J$6:$J$8<J7)+($I$6:$I$8>I7)*($J$6:$J$8<=J7)) | L7: =IF(OR(E7=1,K7=0),1,0) | M7: =IF(AND(L7=1,E7=0,I7>0),1,0) | N7: =IF(M7=1,MAX(J7/I7,SUMPRODUCT(MAX(((J7-$J$6:$J$8)*($M$6:$M$8*($I$6:$I$8<I7)))/((I7-$I$6:$I$8)*($M$6:$M$8*($I$6:$I$8<I7))+1-($M$6:$M$8*($I$6:$I$8<I7)))-(1-($M$6:$M$8*($I$6:$I$8<I7)))*1E+300))),0) | O7: =IF(M7=1,SUMPRODUCT(MIN(((($J$6:$J$8-J7)*($M$6:$M$8*($I$6:$I$8>I7)))/(($I$6:$I$8-I7)*($M$6:$M$8*($I$6:$I$8>I7))+1-($M$6:$M$8*($I$6:$I$8>I7)))+(1-($M$6:$M$8*($I$6:$I$8>I7)))*1E+300))),0) | P7: =IF(E7=1,1,IF(AND(M7=1,N7<=O7),1,0)) | Q7: =IF(P7=1,1+SUMPRODUCT($P$6:$P$8*(($I$6:$I$8<I7)+($I$6:$I$8=I7)*($F$6:$F$8<F7))),0) | R7: =IF(Q7<=1,0,SUMPRODUCT(($Q$6:$Q$8=Q7-1)*$I$6:$I$8)) | S7: =IF(Q7<=1,0,SUMPRODUCT(($Q$6:$Q$8=Q7-1)*$J$6:$J$8)) | T7: =IF(Q7=0,"",(I7-R7)/10^in_out_dp) | U7: =IF(Q7=0,"",(J7-S7)/10^in_cost_dp) | V7: =IF(Q7=0,"",IF(I7=R7,0,U7/T7)) | W7: =IF(I7>0,(J7/10^in_cost_dp)/(I7/10^in_out_dp),"n/a") | X7: =IF(Sites!$C$5=C7,1,0)
A8: =B8&"|"&C8 | B8: A | C8: A2 | D8: A2 | E8: 0 | F8: 3 | G8: =Summary!G7 | H8: =Summary!M7 | I8: =ROUND(G8*10^in_out_dp,0) | J8: =ROUND(H8*10^in_cost_dp,0) | K8: =SUMPRODUCT(($I$6:$I$8=I8)*($J$6:$J$8<J8)+($I$6:$I$8>I8)*($J$6:$J$8<=J8)) | L8: =IF(OR(E8=1,K8=0),1,0) | M8: =IF(AND(L8=1,E8=0,I8>0),1,0) | N8: =IF(M8=1,MAX(J8/I8,SUMPRODUCT(MAX(((J8-$J$6:$J$8)*($M$6:$M$8*($I$6:$I$8<I8)))/((I8-$I$6:$I$8)*($M$6:$M$8*($I$6:$I$8<I8))+1-($M$6:$M$8*($I$6:$I$8<I8)))-(1-($M$6:$M$8*($I$6:$I$8<I8)))*1E+300))),0) | O8: =IF(M8=1,SUMPRODUCT(MIN(((($J$6:$J$8-J8)*($M$6:$M$8*($I$6:$I$8>I8)))/(($I$6:$I$8-I8)*($M$6:$M$8*($I$6:$I$8>I8))+1-($M$6:$M$8*($I$6:$I$8>I8)))+(1-($M$6:$M$8*($I$6:$I$8>I8)))*1E+300))),0) | P8: =IF(E8=1,1,IF(AND(M8=1,N8<=O8),1,0)) | Q8: =IF(P8=1,1+SUMPRODUCT($P$6:$P$8*(($I$6:$I$8<I8)+($I$6:$I$8=I8)*($F$6:$F$8<F8))),0) | R8: =IF(Q8<=1,0,SUMPRODUCT(($Q$6:$Q$8=Q8-1)*$I$6:$I$8)) | S8: =IF(Q8<=1,0,SUMPRODUCT(($Q$6:$Q$8=Q8-1)*$J$6:$J$8)) | T8: =IF(Q8=0,"",(I8-R8)/10^in_out_dp) | U8: =IF(Q8=0,"",(J8-S8)/10^in_cost_dp) | V8: =IF(Q8=0,"",IF(I8=R8,0,U8/T8)) | W8: =IF(I8>0,(J8/10^in_cost_dp)/(I8/10^in_out_dp),"n/a") | X8: =IF(Sites!$C$5=C8,1,0)
B10: B Middle
A11: =B11&"|"&C11 | B11: B | C11: NA | D11: NA | E11: 1 | F11: 1 | G11: =Summary!G8 | H11: =Summary!M8 | I11: =ROUND(G11*10^in_out_dp,0) | J11: =ROUND(H11*10^in_cost_dp,0) | K11: =SUMPRODUCT(($I$11:$I$14=I11)*($J$11:$J$14<J11)+($I$11:$I$14>I11)*($J$11:$J$14<=J11)) | L11: =IF(OR(E11=1,K11=0),1,0) | M11: =IF(AND(L11=1,E11=0,I11>0),1,0) | N11: =IF(M11=1,MAX(J11/I11,SUMPRODUCT(MAX(((J11-$J$11:$J$14)*($M$11:$M$14*($I$11:$I$14<I11)))/((I11-$I$11:$I$14)*($M$11:$M$14*($I$11:$I$14<I11))+1-($M$11:$M$14*($I$11:$I$14<I11)))-(1-($M$11:$M$14*($I$11:$I$14<I11)))*1E+300))),0) | O11: =IF(M11=1,SUMPRODUCT(MIN(((($J$11:$J$14-J11)*($M$11:$M$14*($I$11:$I$14>I11)))/(($I$11:$I$14-I11)*($M$11:$M$14*($I$11:$I$14>I11))+1-($M$11:$M$14*($I$11:$I$14>I11)))+(1-($M$11:$M$14*($I$11:$I$14>I11)))*1E+300))),0) | P11: =IF(E11=1,1,IF(AND(M11=1,N11<=O11),1,0)) | Q11: =IF(P11=1,1+SUMPRODUCT($P$11:$P$14*(($I$11:$I$14<I11)+($I$11:$I$14=I11)*($F$11:$F$14<F11))),0) | R11: =IF(Q11<=1,0,SUMPRODUCT(($Q$11:$Q$14=Q11-1)*$I$11:$I$14)) | S11: =IF(Q11<=1,0,SUMPRODUCT(($Q$11:$Q$14=Q11-1)*$J$11:$J$14)) | T11: =IF(Q11=0,"",(I11-R11)/10^in_out_dp) | U11: =IF(Q11=0,"",(J11-S11)/10^in_cost_dp) | V11: =IF(Q11=0,"",IF(I11=R11,0,U11/T11)) | W11: =IF(I11>0,(J11/10^in_cost_dp)/(I11/10^in_out_dp),"n/a") | X11: =IF(Sites!$C$6=C11,1,0)
A12: =B12&"|"&C12 | B12: B | C12: B1 | D12: B1 | E12: 0 | F12: 2 | G12: =Summary!G9 | H12: =Summary!M9 | I12: =ROUND(G12*10^in_out_dp,0) | J12: =ROUND(H12*10^in_cost_dp,0) | K12: =SUMPRODUCT(($I$11:$I$14=I12)*($J$11:$J$14<J12)+($I$11:$I$14>I12)*($J$11:$J$14<=J12)) | L12: =IF(OR(E12=1,K12=0),1,0) | M12: =IF(AND(L12=1,E12=0,I12>0),1,0) | N12: =IF(M12=1,MAX(J12/I12,SUMPRODUCT(MAX(((J12-$J$11:$J$14)*($M$11:$M$14*($I$11:$I$14<I12)))/((I12-$I$11:$I$14)*($M$11:$M$14*($I$11:$I$14<I12))+1-($M$11:$M$14*($I$11:$I$14<I12)))-(1-($M$11:$M$14*($I$11:$I$14<I12)))*1E+300))),0) | O12: =IF(M12=1,SUMPRODUCT(MIN(((($J$11:$J$14-J12)*($M$11:$M$14*($I$11:$I$14>I12)))/(($I$11:$I$14-I12)*($M$11:$M$14*($I$11:$I$14>I12))+1-($M$11:$M$14*($I$11:$I$14>I12)))+(1-($M$11:$M$14*($I$11:$I$14>I12)))*1E+300))),0) | P12: =IF(E12=1,1,IF(AND(M12=1,N12<=O12),1,0)) | Q12: =IF(P12=1,1+SUMPRODUCT($P$11:$P$14*(($I$11:$I$14<I12)+($I$11:$I$14=I12)*($F$11:$F$14<F12))),0) | R12: =IF(Q12<=1,0,SUMPRODUCT(($Q$11:$Q$14=Q12-1)*$I$11:$I$14)) | S12: =IF(Q12<=1,0,SUMPRODUCT(($Q$11:$Q$14=Q12-1)*$J$11:$J$14)) | T12: =IF(Q12=0,"",(I12-R12)/10^in_out_dp) | U12: =IF(Q12=0,"",(J12-S12)/10^in_cost_dp) | V12: =IF(Q12=0,"",IF(I12=R12,0,U12/T12)) | W12: =IF(I12>0,(J12/10^in_cost_dp)/(I12/10^in_out_dp),"n/a") | X12: =IF(Sites!$C$6=C12,1,0)
A13: =B13&"|"&C13 | B13: B | C13: B2 | D13: B2 | E13: 0 | F13: 3 | G13: =Summary!G10 | H13: =Summary!M10 | I13: =ROUND(G13*10^in_out_dp,0) | J13: =ROUND(H13*10^in_cost_dp,0) | K13: =SUMPRODUCT(($I$11:$I$14=I13)*($J$11:$J$14<J13)+($I$11:$I$14>I13)*($J$11:$J$14<=J13)) | L13: =IF(OR(E13=1,K13=0),1,0) | M13: =IF(AND(L13=1,E13=0,I13>0),1,0) | N13: =IF(M13=1,MAX(J13/I13,SUMPRODUCT(MAX(((J13-$J$11:$J$14)*($M$11:$M$14*($I$11:$I$14<I13)))/((I13-$I$11:$I$14)*($M$11:$M$14*($I$11:$I$14<I13))+1-($M$11:$M$14*($I$11:$I$14<I13)))-(1-($M$11:$M$14*($I$11:$I$14<I13)))*1E+300))),0) | O13: =IF(M13=1,SUMPRODUCT(MIN(((($J$11:$J$14-J13)*($M$11:$M$14*($I$11:$I$14>I13)))/(($I$11:$I$14-I13)*($M$11:$M$14*($I$11:$I$14>I13))+1-($M$11:$M$14*($I$11:$I$14>I13)))+(1-($M$11:$M$14*($I$11:$I$14>I13)))*1E+300))),0) | P13: =IF(E13=1,1,IF(AND(M13=1,N13<=O13),1,0)) | Q13: =IF(P13=1,1+SUMPRODUCT($P$11:$P$14*(($I$11:$I$14<I13)+($I$11:$I$14=I13)*($F$11:$F$14<F13))),0) | R13: =IF(Q13<=1,0,SUMPRODUCT(($Q$11:$Q$14=Q13-1)*$I$11:$I$14)) | S13: =IF(Q13<=1,0,SUMPRODUCT(($Q$11:$Q$14=Q13-1)*$J$11:$J$14)) | T13: =IF(Q13=0,"",(I13-R13)/10^in_out_dp) | U13: =IF(Q13=0,"",(J13-S13)/10^in_cost_dp) | V13: =IF(Q13=0,"",IF(I13=R13,0,U13/T13)) | W13: =IF(I13>0,(J13/10^in_cost_dp)/(I13/10^in_out_dp),"n/a") | X13: =IF(Sites!$C$6=C13,1,0)
A14: =B14&"|"&C14 | B14: B | C14: B3 | D14: B3 | E14: 0 | F14: 4 | G14: =Summary!G11 | H14: =Summary!M11 | I14: =ROUND(G14*10^in_out_dp,0) | J14: =ROUND(H14*10^in_cost_dp,0) | K14: =SUMPRODUCT(($I$11:$I$14=I14)*($J$11:$J$14<J14)+($I$11:$I$14>I14)*($J$11:$J$14<=J14)) | L14: =IF(OR(E14=1,K14=0),1,0) | M14: =IF(AND(L14=1,E14=0,I14>0),1,0) | N14: =IF(M14=1,MAX(J14/I14,SUMPRODUCT(MAX(((J14-$J$11:$J$14)*($M$11:$M$14*($I$11:$I$14<I14)))/((I14-$I$11:$I$14)*($M$11:$M$14*($I$11:$I$14<I14))+1-($M$11:$M$14*($I$11:$I$14<I14)))-(1-($M$11:$M$14*($I$11:$I$14<I14)))*1E+300))),0) | O14: =IF(M14=1,SUMPRODUCT(MIN(((($J$11:$J$14-J14)*($M$11:$M$14*($I$11:$I$14>I14)))/(($I$11:$I$14-I14)*($M$11:$M$14*($I$11:$I$14>I14))+1-($M$11:$M$14*($I$11:$I$14>I14)))+(1-($M$11:$M$14*($I$11:$I$14>I14)))*1E+300))),0) | P14: =IF(E14=1,1,IF(AND(M14=1,N14<=O14),1,0)) | Q14: =IF(P14=1,1+SUMPRODUCT($P$11:$P$14*(($I$11:$I$14<I14)+($I$11:$I$14=I14)*($F$11:$F$14<F14))),0) | R14: =IF(Q14<=1,0,SUMPRODUCT(($Q$11:$Q$14=Q14-1)*$I$11:$I$14)) | S14: =IF(Q14<=1,0,SUMPRODUCT(($Q$11:$Q$14=Q14-1)*$J$11:$J$14)) | T14: =IF(Q14=0,"",(I14-R14)/10^in_out_dp) | U14: =IF(Q14=0,"",(J14-S14)/10^in_cost_dp) | V14: =IF(Q14=0,"",IF(I14=R14,0,U14/T14)) | W14: =IF(I14>0,(J14/10^in_cost_dp)/(I14/10^in_out_dp),"n/a") | X14: =IF(Sites!$C$6=C14,1,0)
B16: C Lower
A17: =B17&"|"&C17 | B17: C | C17: NA | D17: NA | E17: 1 | F17: 1 | G17: =Summary!G12 | H17: =Summary!M12 | I17: =ROUND(G17*10^in_out_dp,0) | J17: =ROUND(H17*10^in_cost_dp,0) | K17: =SUMPRODUCT(($I$17:$I$18=I17)*($J$17:$J$18<J17)+($I$17:$I$18>I17)*($J$17:$J$18<=J17)) | L17: =IF(OR(E17=1,K17=0),1,0) | M17: =IF(AND(L17=1,E17=0,I17>0),1,0) | N17: =IF(M17=1,MAX(J17/I17,SUMPRODUCT(MAX(((J17-$J$17:$J$18)*($M$17:$M$18*($I$17:$I$18<I17)))/((I17-$I$17:$I$18)*($M$17:$M$18*($I$17:$I$18<I17))+1-($M$17:$M$18*($I$17:$I$18<I17)))-(1-($M$17:$M$18*($I$17:$I$18<I17)))*1E+300))),0) | O17: =IF(M17=1,SUMPRODUCT(MIN(((($J$17:$J$18-J17)*($M$17:$M$18*($I$17:$I$18>I17)))/(($I$17:$I$18-I17)*($M$17:$M$18*($I$17:$I$18>I17))+1-($M$17:$M$18*($I$17:$I$18>I17)))+(1-($M$17:$M$18*($I$17:$I$18>I17)))*1E+300))),0) | P17: =IF(E17=1,1,IF(AND(M17=1,N17<=O17),1,0)) | Q17: =IF(P17=1,1+SUMPRODUCT($P$17:$P$18*(($I$17:$I$18<I17)+($I$17:$I$18=I17)*($F$17:$F$18<F17))),0) | R17: =IF(Q17<=1,0,SUMPRODUCT(($Q$17:$Q$18=Q17-1)*$I$17:$I$18)) | S17: =IF(Q17<=1,0,SUMPRODUCT(($Q$17:$Q$18=Q17-1)*$J$17:$J$18)) | T17: =IF(Q17=0,"",(I17-R17)/10^in_out_dp) | U17: =IF(Q17=0,"",(J17-S17)/10^in_cost_dp) | V17: =IF(Q17=0,"",IF(I17=R17,0,U17/T17)) | W17: =IF(I17>0,(J17/10^in_cost_dp)/(I17/10^in_out_dp),"n/a") | X17: =IF(Sites!$C$7=C17,1,0)
A18: =B18&"|"&C18 | B18: C | C18: C1 | D18: C1 | E18: 0 | F18: 2 | G18: =Summary!G13 | H18: =Summary!M13 | I18: =ROUND(G18*10^in_out_dp,0) | J18: =ROUND(H18*10^in_cost_dp,0) | K18: =SUMPRODUCT(($I$17:$I$18=I18)*($J$17:$J$18<J18)+($I$17:$I$18>I18)*($J$17:$J$18<=J18)) | L18: =IF(OR(E18=1,K18=0),1,0) | M18: =IF(AND(L18=1,E18=0,I18>0),1,0) | N18: =IF(M18=1,MAX(J18/I18,SUMPRODUCT(MAX(((J18-$J$17:$J$18)*($M$17:$M$18*($I$17:$I$18<I18)))/((I18-$I$17:$I$18)*($M$17:$M$18*($I$17:$I$18<I18))+1-($M$17:$M$18*($I$17:$I$18<I18)))-(1-($M$17:$M$18*($I$17:$I$18<I18)))*1E+300))),0) | O18: =IF(M18=1,SUMPRODUCT(MIN(((($J$17:$J$18-J18)*($M$17:$M$18*($I$17:$I$18>I18)))/(($I$17:$I$18-I18)*($M$17:$M$18*($I$17:$I$18>I18))+1-($M$17:$M$18*($I$17:$I$18>I18)))+(1-($M$17:$M$18*($I$17:$I$18>I18)))*1E+300))),0) | P18: =IF(E18=1,1,IF(AND(M18=1,N18<=O18),1,0)) | Q18: =IF(P18=1,1+SUMPRODUCT($P$17:$P$18*(($I$17:$I$18<I18)+($I$17:$I$18=I18)*($F$17:$F$18<F18))),0) | R18: =IF(Q18<=1,0,SUMPRODUCT(($Q$17:$Q$18=Q18-1)*$I$17:$I$18)) | S18: =IF(Q18<=1,0,SUMPRODUCT(($Q$17:$Q$18=Q18-1)*$J$17:$J$18)) | T18: =IF(Q18=0,"",(I18-R18)/10^in_out_dp) | U18: =IF(Q18=0,"",(J18-S18)/10^in_cost_dp) | V18: =IF(Q18=0,"",IF(I18=R18,0,U18/T18)) | W18: =IF(I18>0,(J18/10^in_cost_dp)/(I18/10^in_out_dp),"n/a") | X18: =IF(Sites!$C$7=C18,1,0)

Sheet Sites
A1: Sites: the alternative carried to the watershed plans
A2: Choose each site's recommended alternative. No Action leaves the site out of every watershed plan.
A4: Site | B4: Name | C4: Recommended alternative | D4: No Action | E4: Carried | F4: Lift (AAHU) | G4: Cost above No Action | H4: Construction cost | I4: Lift (scaled) | J4: Cost (scaled) | K4: Cost-effective | L4: Best buy | M4: Decided by
A5: A | B5: Upper | C5: A1 | D5: NA | E5: =IF(C5<>D5,1,0) | F5: =IFERROR(INDEX('Site CE-ICA'!$G$5:$G$18,MATCH(A5&"|"&C5,'Site CE-ICA'!$A$5:$A$18,0)),0) | G5: =IFERROR(INDEX('Site CE-ICA'!$H$5:$H$18,MATCH(A5&"|"&C5,'Site CE-ICA'!$A$5:$A$18,0)),0) | H5: =IFERROR(INDEX(Summary!$H$5:$H$7,MATCH(C5,Summary!$C$5:$C$7,0)),0) | I5: =IF(E5=1,IFERROR(INDEX('Site CE-ICA'!$I$5:$I$18,MATCH(A5&"|"&C5,'Site CE-ICA'!$A$5:$A$18,0)),0),0) | J5: =IF(E5=1,IFERROR(INDEX('Site CE-ICA'!$J$5:$J$18,MATCH(A5&"|"&C5,'Site CE-ICA'!$A$5:$A$18,0)),0),0) | K5: =IFERROR(INDEX('Site CE-ICA'!$L$5:$L$18,MATCH(A5&"|"&C5,'Site CE-ICA'!$A$5:$A$18,0)),0) | L5: =IFERROR(INDEX('Site CE-ICA'!$P$5:$P$18,MATCH(A5&"|"&C5,'Site CE-ICA'!$A$5:$A$18,0)),0) | M5: Suggested
A6: B | B6: Middle | C6: B3 | D6: NA | E6: =IF(C6<>D6,1,0) | F6: =IFERROR(INDEX('Site CE-ICA'!$G$5:$G$18,MATCH(A6&"|"&C6,'Site CE-ICA'!$A$5:$A$18,0)),0) | G6: =IFERROR(INDEX('Site CE-ICA'!$H$5:$H$18,MATCH(A6&"|"&C6,'Site CE-ICA'!$A$5:$A$18,0)),0) | H6: =IFERROR(INDEX(Summary!$H$8:$H$11,MATCH(C6,Summary!$C$8:$C$11,0)),0) | I6: =IF(E6=1,IFERROR(INDEX('Site CE-ICA'!$I$5:$I$18,MATCH(A6&"|"&C6,'Site CE-ICA'!$A$5:$A$18,0)),0),0) | J6: =IF(E6=1,IFERROR(INDEX('Site CE-ICA'!$J$5:$J$18,MATCH(A6&"|"&C6,'Site CE-ICA'!$A$5:$A$18,0)),0),0) | K6: =IFERROR(INDEX('Site CE-ICA'!$L$5:$L$18,MATCH(A6&"|"&C6,'Site CE-ICA'!$A$5:$A$18,0)),0) | L6: =IFERROR(INDEX('Site CE-ICA'!$P$5:$P$18,MATCH(A6&"|"&C6,'Site CE-ICA'!$A$5:$A$18,0)),0) | M6: Suggested
A7: C | B7: Lower | C7: C1 | D7: NA | E7: =IF(C7<>D7,1,0) | F7: =IFERROR(INDEX('Site CE-ICA'!$G$5:$G$18,MATCH(A7&"|"&C7,'Site CE-ICA'!$A$5:$A$18,0)),0) | G7: =IFERROR(INDEX('Site CE-ICA'!$H$5:$H$18,MATCH(A7&"|"&C7,'Site CE-ICA'!$A$5:$A$18,0)),0) | H7: =IFERROR(INDEX(Summary!$H$12:$H$13,MATCH(C7,Summary!$C$12:$C$13,0)),0) | I7: =IF(E7=1,IFERROR(INDEX('Site CE-ICA'!$I$5:$I$18,MATCH(A7&"|"&C7,'Site CE-ICA'!$A$5:$A$18,0)),0),0) | J7: =IF(E7=1,IFERROR(INDEX('Site CE-ICA'!$J$5:$J$18,MATCH(A7&"|"&C7,'Site CE-ICA'!$A$5:$A$18,0)),0),0) | K7: =IFERROR(INDEX('Site CE-ICA'!$L$5:$L$18,MATCH(A7&"|"&C7,'Site CE-ICA'!$A$5:$A$18,0)),0) | L7: =IFERROR(INDEX('Site CE-ICA'!$P$5:$P$18,MATCH(A7&"|"&C7,'Site CE-ICA'!$A$5:$A$18,0)),0) | M7: Suggested

Sheet Watershed plans
A1: Watershed plans: every combination of the recommended site actions
A2: 1 and 0 mark a site included or excluded. Rows that include a site whose recommendation is No Action are not valid plans.
C4: Site | D4: A | E4: B | F4: C
C5: Carried | D5: =Sites!E5 | E5: =Sites!E6 | F5: =Sites!E7
C6: Lift (scaled) | D6: =Sites!I5 | E6: =Sites!I6 | F6: =Sites!I7
C7: Cost (scaled) | D7: =Sites!J5 | E7: =Sites!J6 | F7: =Sites!J7
C8: Construction cost | D8: =Sites!H5 | E8: =Sites!H6 | F8: =Sites!H7
C9: Weight | D9: =IF(D5=1,2^SUM(E5:$F$5),0) | E9: =IF(E5=1,2^SUM(F5:$F$5),0) | F9: =IF(F5=1,1,0)
A11: Row | B11: Plan | C11: Valid | D11: A | E11: B | F11: C | G11: Plan number | H11: Lift (scaled) | I11: Cost (scaled) | J11: Construction cost | K11: Lift (AAHU) | L11: Average annual cost | M11: No Action | N11: Dominated by | O11: Cost-effective | P11: Candidate | Q11: Slope in (max) | R11: Slope out (min) | S11: Best buy | T11: Best-buy step | U11: Previous lift (scaled) | V11: Previous cost (scaled) | W11: Incremental output | X11: Incremental cost | Y11: Incremental cost per unit | Z11: Unit cost | AA11: Final array | AB11: Final array order
A12: 1 | B12: No Action | C12: =IF(SUMPRODUCT(D12:F12,1-$D$5:$F$5)=0,1,0) | D12: 0 | E12: 0 | F12: 0 | G12: =IF(C12=1,1+SUMPRODUCT(D12:F12,$D$9:$F$9),"") | H12: =SUMPRODUCT(D12:F12,$D$6:$F$6) | I12: =SUMPRODUCT(D12:F12,$D$7:$F$7) | J12: =SUMPRODUCT(D12:F12,$D$8:$F$8) | K12: =H12/10^in_out_dp | L12: =I12/10^in_cost_dp | M12: =IF(SUM(D12:F12)=0,1,0) | N12: =SUMPRODUCT($C$12:$C$19*(($H$12:$H$19=H12)*($I$12:$I$19<I12)+($H$12:$H$19>H12)*($I$12:$I$19<=I12))) | O12: =IF(C12=0,0,IF(OR(M12=1,N12=0),1,0)) | P12: =IF(AND(O12=1,M12=0,H12>0),1,0) | Q12: =IF(P12=1,MAX(I12/H12,SUMPRODUCT(MAX(((I12-$I$12:$I$19)*($P$12:$P$19*($H$12:$H$19<H12)))/((H12-$H$12:$H$19)*($P$12:$P$19*($H$12:$H$19<H12))+1-($P$12:$P$19*($H$12:$H$19<H12)))-(1-($P$12:$P$19*($H$12:$H$19<H12)))*1E+300))),0) | R12: =IF(P12=1,SUMPRODUCT(MIN(((($I$12:$I$19-I12)*($P$12:$P$19*($H$12:$H$19>H12)))/(($H$12:$H$19-H12)*($P$12:$P$19*($H$12:$H$19>H12))+1-($P$12:$P$19*($H$12:$H$19>H12)))+(1-($P$12:$P$19*($H$12:$H$19>H12)))*1E+300))),0) | S12: =IF(C12=0,0,IF(M12=1,1,IF(AND(P12=1,Q12<=R12),1,0))) | T12: =IF(S12=1,1+SUMPRODUCT($S$12:$S$19*(($H$12:$H$19<H12)+($H$12:$H$19=H12)*($A$12:$A$19<A12))),0) | U12: =IF(T12<=1,0,SUMPRODUCT(($T$12:$T$19=T12-1)*$H$12:$H$19)) | V12: =IF(T12<=1,0,SUMPRODUCT(($T$12:$T$19=T12-1)*$I$12:$I$19)) | W12: =IF(T12=0,"",(H12-U12)/10^in_out_dp) | X12: =IF(T12=0,"",(I12-V12)/10^in_cost_dp) | Y12: =IF(T12=0,"",IF(H12=U12,0,X12/W12)) | Z12: =IF(AND(C12=1,H12>0),L12/K12,"n/a") | AA12: 1 | AB12: =IF(AND(C12=1,AA12=1),1+SUMPRODUCT($C$12:$C$19*$AA$12:$AA$19*(($H$12:$H$19<H12)+($H$12:$H$19=H12)*($I$12:$I$19<I12)+($H$12:$H$19=H12)*($I$12:$I$19=I12)*($A$12:$A$19<A12))),0)
A13: 2 | B13: C | C13: =IF(SUMPRODUCT(D13:F13,1-$D$5:$F$5)=0,1,0) | D13: 0 | E13: 0 | F13: 1 | G13: =IF(C13=1,1+SUMPRODUCT(D13:F13,$D$9:$F$9),"") | H13: =SUMPRODUCT(D13:F13,$D$6:$F$6) | I13: =SUMPRODUCT(D13:F13,$D$7:$F$7) | J13: =SUMPRODUCT(D13:F13,$D$8:$F$8) | K13: =H13/10^in_out_dp | L13: =I13/10^in_cost_dp | M13: =IF(SUM(D13:F13)=0,1,0) | N13: =SUMPRODUCT($C$12:$C$19*(($H$12:$H$19=H13)*($I$12:$I$19<I13)+($H$12:$H$19>H13)*($I$12:$I$19<=I13))) | O13: =IF(C13=0,0,IF(OR(M13=1,N13=0),1,0)) | P13: =IF(AND(O13=1,M13=0,H13>0),1,0) | Q13: =IF(P13=1,MAX(I13/H13,SUMPRODUCT(MAX(((I13-$I$12:$I$19)*($P$12:$P$19*($H$12:$H$19<H13)))/((H13-$H$12:$H$19)*($P$12:$P$19*($H$12:$H$19<H13))+1-($P$12:$P$19*($H$12:$H$19<H13)))-(1-($P$12:$P$19*($H$12:$H$19<H13)))*1E+300))),0) | R13: =IF(P13=1,SUMPRODUCT(MIN(((($I$12:$I$19-I13)*($P$12:$P$19*($H$12:$H$19>H13)))/(($H$12:$H$19-H13)*($P$12:$P$19*($H$12:$H$19>H13))+1-($P$12:$P$19*($H$12:$H$19>H13)))+(1-($P$12:$P$19*($H$12:$H$19>H13)))*1E+300))),0) | S13: =IF(C13=0,0,IF(M13=1,1,IF(AND(P13=1,Q13<=R13),1,0))) | T13: =IF(S13=1,1+SUMPRODUCT($S$12:$S$19*(($H$12:$H$19<H13)+($H$12:$H$19=H13)*($A$12:$A$19<A13))),0) | U13: =IF(T13<=1,0,SUMPRODUCT(($T$12:$T$19=T13-1)*$H$12:$H$19)) | V13: =IF(T13<=1,0,SUMPRODUCT(($T$12:$T$19=T13-1)*$I$12:$I$19)) | W13: =IF(T13=0,"",(H13-U13)/10^in_out_dp) | X13: =IF(T13=0,"",(I13-V13)/10^in_cost_dp) | Y13: =IF(T13=0,"",IF(H13=U13,0,X13/W13)) | Z13: =IF(AND(C13=1,H13>0),L13/K13,"n/a") | AA13: 0 | AB13: =IF(AND(C13=1,AA13=1),1+SUMPRODUCT($C$12:$C$19*$AA$12:$AA$19*(($H$12:$H$19<H13)+($H$12:$H$19=H13)*($I$12:$I$19<I13)+($H$12:$H$19=H13)*($I$12:$I$19=I13)*($A$12:$A$19<A13))),0)
A14: 3 | B14: B | C14: =IF(SUMPRODUCT(D14:F14,1-$D$5:$F$5)=0,1,0) | D14: 0 | E14: 1 | F14: 0 | G14: =IF(C14=1,1+SUMPRODUCT(D14:F14,$D$9:$F$9),"") | H14: =SUMPRODUCT(D14:F14,$D$6:$F$6) | I14: =SUMPRODUCT(D14:F14,$D$7:$F$7) | J14: =SUMPRODUCT(D14:F14,$D$8:$F$8) | K14: =H14/10^in_out_dp | L14: =I14/10^in_cost_dp | M14: =IF(SUM(D14:F14)=0,1,0) | N14: =SUMPRODUCT($C$12:$C$19*(($H$12:$H$19=H14)*($I$12:$I$19<I14)+($H$12:$H$19>H14)*($I$12:$I$19<=I14))) | O14: =IF(C14=0,0,IF(OR(M14=1,N14=0),1,0)) | P14: =IF(AND(O14=1,M14=0,H14>0),1,0) | Q14: =IF(P14=1,MAX(I14/H14,SUMPRODUCT(MAX(((I14-$I$12:$I$19)*($P$12:$P$19*($H$12:$H$19<H14)))/((H14-$H$12:$H$19)*($P$12:$P$19*($H$12:$H$19<H14))+1-($P$12:$P$19*($H$12:$H$19<H14)))-(1-($P$12:$P$19*($H$12:$H$19<H14)))*1E+300))),0) | R14: =IF(P14=1,SUMPRODUCT(MIN(((($I$12:$I$19-I14)*($P$12:$P$19*($H$12:$H$19>H14)))/(($H$12:$H$19-H14)*($P$12:$P$19*($H$12:$H$19>H14))+1-($P$12:$P$19*($H$12:$H$19>H14)))+(1-($P$12:$P$19*($H$12:$H$19>H14)))*1E+300))),0) | S14: =IF(C14=0,0,IF(M14=1,1,IF(AND(P14=1,Q14<=R14),1,0))) | T14: =IF(S14=1,1+SUMPRODUCT($S$12:$S$19*(($H$12:$H$19<H14)+($H$12:$H$19=H14)*($A$12:$A$19<A14))),0) | U14: =IF(T14<=1,0,SUMPRODUCT(($T$12:$T$19=T14-1)*$H$12:$H$19)) | V14: =IF(T14<=1,0,SUMPRODUCT(($T$12:$T$19=T14-1)*$I$12:$I$19)) | W14: =IF(T14=0,"",(H14-U14)/10^in_out_dp) | X14: =IF(T14=0,"",(I14-V14)/10^in_cost_dp) | Y14: =IF(T14=0,"",IF(H14=U14,0,X14/W14)) | Z14: =IF(AND(C14=1,H14>0),L14/K14,"n/a") | AA14: 1 | AB14: =IF(AND(C14=1,AA14=1),1+SUMPRODUCT($C$12:$C$19*$AA$12:$AA$19*(($H$12:$H$19<H14)+($H$12:$H$19=H14)*($I$12:$I$19<I14)+($H$12:$H$19=H14)*($I$12:$I$19=I14)*($A$12:$A$19<A14))),0)
A15: 4 | B15: B + C | C15: =IF(SUMPRODUCT(D15:F15,1-$D$5:$F$5)=0,1,0) | D15: 0 | E15: 1 | F15: 1 | G15: =IF(C15=1,1+SUMPRODUCT(D15:F15,$D$9:$F$9),"") | H15: =SUMPRODUCT(D15:F15,$D$6:$F$6) | I15: =SUMPRODUCT(D15:F15,$D$7:$F$7) | J15: =SUMPRODUCT(D15:F15,$D$8:$F$8) | K15: =H15/10^in_out_dp | L15: =I15/10^in_cost_dp | M15: =IF(SUM(D15:F15)=0,1,0) | N15: =SUMPRODUCT($C$12:$C$19*(($H$12:$H$19=H15)*($I$12:$I$19<I15)+($H$12:$H$19>H15)*($I$12:$I$19<=I15))) | O15: =IF(C15=0,0,IF(OR(M15=1,N15=0),1,0)) | P15: =IF(AND(O15=1,M15=0,H15>0),1,0) | Q15: =IF(P15=1,MAX(I15/H15,SUMPRODUCT(MAX(((I15-$I$12:$I$19)*($P$12:$P$19*($H$12:$H$19<H15)))/((H15-$H$12:$H$19)*($P$12:$P$19*($H$12:$H$19<H15))+1-($P$12:$P$19*($H$12:$H$19<H15)))-(1-($P$12:$P$19*($H$12:$H$19<H15)))*1E+300))),0) | R15: =IF(P15=1,SUMPRODUCT(MIN(((($I$12:$I$19-I15)*($P$12:$P$19*($H$12:$H$19>H15)))/(($H$12:$H$19-H15)*($P$12:$P$19*($H$12:$H$19>H15))+1-($P$12:$P$19*($H$12:$H$19>H15)))+(1-($P$12:$P$19*($H$12:$H$19>H15)))*1E+300))),0) | S15: =IF(C15=0,0,IF(M15=1,1,IF(AND(P15=1,Q15<=R15),1,0))) | T15: =IF(S15=1,1+SUMPRODUCT($S$12:$S$19*(($H$12:$H$19<H15)+($H$12:$H$19=H15)*($A$12:$A$19<A15))),0) | U15: =IF(T15<=1,0,SUMPRODUCT(($T$12:$T$19=T15-1)*$H$12:$H$19)) | V15: =IF(T15<=1,0,SUMPRODUCT(($T$12:$T$19=T15-1)*$I$12:$I$19)) | W15: =IF(T15=0,"",(H15-U15)/10^in_out_dp) | X15: =IF(T15=0,"",(I15-V15)/10^in_cost_dp) | Y15: =IF(T15=0,"",IF(H15=U15,0,X15/W15)) | Z15: =IF(AND(C15=1,H15>0),L15/K15,"n/a") | AA15: 0 | AB15: =IF(AND(C15=1,AA15=1),1+SUMPRODUCT($C$12:$C$19*$AA$12:$AA$19*(($H$12:$H$19<H15)+($H$12:$H$19=H15)*($I$12:$I$19<I15)+($H$12:$H$19=H15)*($I$12:$I$19=I15)*($A$12:$A$19<A15))),0)
A16: 5 | B16: A | C16: =IF(SUMPRODUCT(D16:F16,1-$D$5:$F$5)=0,1,0) | D16: 1 | E16: 0 | F16: 0 | G16: =IF(C16=1,1+SUMPRODUCT(D16:F16,$D$9:$F$9),"") | H16: =SUMPRODUCT(D16:F16,$D$6:$F$6) | I16: =SUMPRODUCT(D16:F16,$D$7:$F$7) | J16: =SUMPRODUCT(D16:F16,$D$8:$F$8) | K16: =H16/10^in_out_dp | L16: =I16/10^in_cost_dp | M16: =IF(SUM(D16:F16)=0,1,0) | N16: =SUMPRODUCT($C$12:$C$19*(($H$12:$H$19=H16)*($I$12:$I$19<I16)+($H$12:$H$19>H16)*($I$12:$I$19<=I16))) | O16: =IF(C16=0,0,IF(OR(M16=1,N16=0),1,0)) | P16: =IF(AND(O16=1,M16=0,H16>0),1,0) | Q16: =IF(P16=1,MAX(I16/H16,SUMPRODUCT(MAX(((I16-$I$12:$I$19)*($P$12:$P$19*($H$12:$H$19<H16)))/((H16-$H$12:$H$19)*($P$12:$P$19*($H$12:$H$19<H16))+1-($P$12:$P$19*($H$12:$H$19<H16)))-(1-($P$12:$P$19*($H$12:$H$19<H16)))*1E+300))),0) | R16: =IF(P16=1,SUMPRODUCT(MIN(((($I$12:$I$19-I16)*($P$12:$P$19*($H$12:$H$19>H16)))/(($H$12:$H$19-H16)*($P$12:$P$19*($H$12:$H$19>H16))+1-($P$12:$P$19*($H$12:$H$19>H16)))+(1-($P$12:$P$19*($H$12:$H$19>H16)))*1E+300))),0) | S16: =IF(C16=0,0,IF(M16=1,1,IF(AND(P16=1,Q16<=R16),1,0))) | T16: =IF(S16=1,1+SUMPRODUCT($S$12:$S$19*(($H$12:$H$19<H16)+($H$12:$H$19=H16)*($A$12:$A$19<A16))),0) | U16: =IF(T16<=1,0,SUMPRODUCT(($T$12:$T$19=T16-1)*$H$12:$H$19)) | V16: =IF(T16<=1,0,SUMPRODUCT(($T$12:$T$19=T16-1)*$I$12:$I$19)) | W16: =IF(T16=0,"",(H16-U16)/10^in_out_dp) | X16: =IF(T16=0,"",(I16-V16)/10^in_cost_dp) | Y16: =IF(T16=0,"",IF(H16=U16,0,X16/W16)) | Z16: =IF(AND(C16=1,H16>0),L16/K16,"n/a") | AA16: 0 | AB16: =IF(AND(C16=1,AA16=1),1+SUMPRODUCT($C$12:$C$19*$AA$12:$AA$19*(($H$12:$H$19<H16)+($H$12:$H$19=H16)*($I$12:$I$19<I16)+($H$12:$H$19=H16)*($I$12:$I$19=I16)*($A$12:$A$19<A16))),0)
A17: 6 | B17: A + C | C17: =IF(SUMPRODUCT(D17:F17,1-$D$5:$F$5)=0,1,0) | D17: 1 | E17: 0 | F17: 1 | G17: =IF(C17=1,1+SUMPRODUCT(D17:F17,$D$9:$F$9),"") | H17: =SUMPRODUCT(D17:F17,$D$6:$F$6) | I17: =SUMPRODUCT(D17:F17,$D$7:$F$7) | J17: =SUMPRODUCT(D17:F17,$D$8:$F$8) | K17: =H17/10^in_out_dp | L17: =I17/10^in_cost_dp | M17: =IF(SUM(D17:F17)=0,1,0) | N17: =SUMPRODUCT($C$12:$C$19*(($H$12:$H$19=H17)*($I$12:$I$19<I17)+($H$12:$H$19>H17)*($I$12:$I$19<=I17))) | O17: =IF(C17=0,0,IF(OR(M17=1,N17=0),1,0)) | P17: =IF(AND(O17=1,M17=0,H17>0),1,0) | Q17: =IF(P17=1,MAX(I17/H17,SUMPRODUCT(MAX(((I17-$I$12:$I$19)*($P$12:$P$19*($H$12:$H$19<H17)))/((H17-$H$12:$H$19)*($P$12:$P$19*($H$12:$H$19<H17))+1-($P$12:$P$19*($H$12:$H$19<H17)))-(1-($P$12:$P$19*($H$12:$H$19<H17)))*1E+300))),0) | R17: =IF(P17=1,SUMPRODUCT(MIN(((($I$12:$I$19-I17)*($P$12:$P$19*($H$12:$H$19>H17)))/(($H$12:$H$19-H17)*($P$12:$P$19*($H$12:$H$19>H17))+1-($P$12:$P$19*($H$12:$H$19>H17)))+(1-($P$12:$P$19*($H$12:$H$19>H17)))*1E+300))),0) | S17: =IF(C17=0,0,IF(M17=1,1,IF(AND(P17=1,Q17<=R17),1,0))) | T17: =IF(S17=1,1+SUMPRODUCT($S$12:$S$19*(($H$12:$H$19<H17)+($H$12:$H$19=H17)*($A$12:$A$19<A17))),0) | U17: =IF(T17<=1,0,SUMPRODUCT(($T$12:$T$19=T17-1)*$H$12:$H$19)) | V17: =IF(T17<=1,0,SUMPRODUCT(($T$12:$T$19=T17-1)*$I$12:$I$19)) | W17: =IF(T17=0,"",(H17-U17)/10^in_out_dp) | X17: =IF(T17=0,"",(I17-V17)/10^in_cost_dp) | Y17: =IF(T17=0,"",IF(H17=U17,0,X17/W17)) | Z17: =IF(AND(C17=1,H17>0),L17/K17,"n/a") | AA17: 0 | AB17: =IF(AND(C17=1,AA17=1),1+SUMPRODUCT($C$12:$C$19*$AA$12:$AA$19*(($H$12:$H$19<H17)+($H$12:$H$19=H17)*($I$12:$I$19<I17)+($H$12:$H$19=H17)*($I$12:$I$19=I17)*($A$12:$A$19<A17))),0)
A18: 7 | B18: A + B | C18: =IF(SUMPRODUCT(D18:F18,1-$D$5:$F$5)=0,1,0) | D18: 1 | E18: 1 | F18: 0 | G18: =IF(C18=1,1+SUMPRODUCT(D18:F18,$D$9:$F$9),"") | H18: =SUMPRODUCT(D18:F18,$D$6:$F$6) | I18: =SUMPRODUCT(D18:F18,$D$7:$F$7) | J18: =SUMPRODUCT(D18:F18,$D$8:$F$8) | K18: =H18/10^in_out_dp | L18: =I18/10^in_cost_dp | M18: =IF(SUM(D18:F18)=0,1,0) | N18: =SUMPRODUCT($C$12:$C$19*(($H$12:$H$19=H18)*($I$12:$I$19<I18)+($H$12:$H$19>H18)*($I$12:$I$19<=I18))) | O18: =IF(C18=0,0,IF(OR(M18=1,N18=0),1,0)) | P18: =IF(AND(O18=1,M18=0,H18>0),1,0) | Q18: =IF(P18=1,MAX(I18/H18,SUMPRODUCT(MAX(((I18-$I$12:$I$19)*($P$12:$P$19*($H$12:$H$19<H18)))/((H18-$H$12:$H$19)*($P$12:$P$19*($H$12:$H$19<H18))+1-($P$12:$P$19*($H$12:$H$19<H18)))-(1-($P$12:$P$19*($H$12:$H$19<H18)))*1E+300))),0) | R18: =IF(P18=1,SUMPRODUCT(MIN(((($I$12:$I$19-I18)*($P$12:$P$19*($H$12:$H$19>H18)))/(($H$12:$H$19-H18)*($P$12:$P$19*($H$12:$H$19>H18))+1-($P$12:$P$19*($H$12:$H$19>H18)))+(1-($P$12:$P$19*($H$12:$H$19>H18)))*1E+300))),0) | S18: =IF(C18=0,0,IF(M18=1,1,IF(AND(P18=1,Q18<=R18),1,0))) | T18: =IF(S18=1,1+SUMPRODUCT($S$12:$S$19*(($H$12:$H$19<H18)+($H$12:$H$19=H18)*($A$12:$A$19<A18))),0) | U18: =IF(T18<=1,0,SUMPRODUCT(($T$12:$T$19=T18-1)*$H$12:$H$19)) | V18: =IF(T18<=1,0,SUMPRODUCT(($T$12:$T$19=T18-1)*$I$12:$I$19)) | W18: =IF(T18=0,"",(H18-U18)/10^in_out_dp) | X18: =IF(T18=0,"",(I18-V18)/10^in_cost_dp) | Y18: =IF(T18=0,"",IF(H18=U18,0,X18/W18)) | Z18: =IF(AND(C18=1,H18>0),L18/K18,"n/a") | AA18: 1 | AB18: =IF(AND(C18=1,AA18=1),1+SUMPRODUCT($C$12:$C$19*$AA$12:$AA$19*(($H$12:$H$19<H18)+($H$12:$H$19=H18)*($I$12:$I$19<I18)+($H$12:$H$19=H18)*($I$12:$I$19=I18)*($A$12:$A$19<A18))),0)
A19: 8 | B19: A + B + C | C19: =IF(SUMPRODUCT(D19:F19,1-$D$5:$F$5)=0,1,0) | D19: 1 | E19: 1 | F19: 1 | G19: =IF(C19=1,1+SUMPRODUCT(D19:F19,$D$9:$F$9),"") | H19: =SUMPRODUCT(D19:F19,$D$6:$F$6) | I19: =SUMPRODUCT(D19:F19,$D$7:$F$7) | J19: =SUMPRODUCT(D19:F19,$D$8:$F$8) | K19: =H19/10^in_out_dp | L19: =I19/10^in_cost_dp | M19: =IF(SUM(D19:F19)=0,1,0) | N19: =SUMPRODUCT($C$12:$C$19*(($H$12:$H$19=H19)*($I$12:$I$19<I19)+($H$12:$H$19>H19)*($I$12:$I$19<=I19))) | O19: =IF(C19=0,0,IF(OR(M19=1,N19=0),1,0)) | P19: =IF(AND(O19=1,M19=0,H19>0),1,0) | Q19: =IF(P19=1,MAX(I19/H19,SUMPRODUCT(MAX(((I19-$I$12:$I$19)*($P$12:$P$19*($H$12:$H$19<H19)))/((H19-$H$12:$H$19)*($P$12:$P$19*($H$12:$H$19<H19))+1-($P$12:$P$19*($H$12:$H$19<H19)))-(1-($P$12:$P$19*($H$12:$H$19<H19)))*1E+300))),0) | R19: =IF(P19=1,SUMPRODUCT(MIN(((($I$12:$I$19-I19)*($P$12:$P$19*($H$12:$H$19>H19)))/(($H$12:$H$19-H19)*($P$12:$P$19*($H$12:$H$19>H19))+1-($P$12:$P$19*($H$12:$H$19>H19)))+(1-($P$12:$P$19*($H$12:$H$19>H19)))*1E+300))),0) | S19: =IF(C19=0,0,IF(M19=1,1,IF(AND(P19=1,Q19<=R19),1,0))) | T19: =IF(S19=1,1+SUMPRODUCT($S$12:$S$19*(($H$12:$H$19<H19)+($H$12:$H$19=H19)*($A$12:$A$19<A19))),0) | U19: =IF(T19<=1,0,SUMPRODUCT(($T$12:$T$19=T19-1)*$H$12:$H$19)) | V19: =IF(T19<=1,0,SUMPRODUCT(($T$12:$T$19=T19-1)*$I$12:$I$19)) | W19: =IF(T19=0,"",(H19-U19)/10^in_out_dp) | X19: =IF(T19=0,"",(I19-V19)/10^in_cost_dp) | Y19: =IF(T19=0,"",IF(H19=U19,0,X19/W19)) | Z19: =IF(AND(C19=1,H19>0),L19/K19,"n/a") | AA19: 1 | AB19: =IF(AND(C19=1,AA19=1),1+SUMPRODUCT($C$12:$C$19*$AA$12:$AA$19*(($H$12:$H$19<H19)+($H$12:$H$19=H19)*($I$12:$I$19<I19)+($H$12:$H$19=H19)*($I$12:$I$19=I19)*($A$12:$A$19<A19))),0)

Sheet Watershed summary
A1: Watershed summary: best buys, final array and the tentatively selected plan
A2: Tables read the watershed plans sheet. Choose the TSP from the final array.
A4: Best buys
A5: Step | B5: Plan number | C5: Plan | D5: Lift (AAHU) | E5: Average annual cost | F5: Construction cost | G5: Unit cost | H5: Incremental cost per unit
A6: 1 | B6: =IFERROR(INDEX('Watershed plans'!$G$12:$G$19,MATCH(1,'Watershed plans'!$T$12:$T$19,0)),"") | C6: =IFERROR(INDEX('Watershed plans'!$B$12:$B$19,MATCH(1,'Watershed plans'!$T$12:$T$19,0)),"") | D6: =IFERROR(INDEX('Watershed plans'!$K$12:$K$19,MATCH(1,'Watershed plans'!$T$12:$T$19,0)),"") | E6: =IFERROR(INDEX('Watershed plans'!$L$12:$L$19,MATCH(1,'Watershed plans'!$T$12:$T$19,0)),"") | F6: =IFERROR(INDEX('Watershed plans'!$J$12:$J$19,MATCH(1,'Watershed plans'!$T$12:$T$19,0)),"") | G6: =IFERROR(INDEX('Watershed plans'!$Z$12:$Z$19,MATCH(1,'Watershed plans'!$T$12:$T$19,0)),"") | H6: =IFERROR(INDEX('Watershed plans'!$Y$12:$Y$19,MATCH(1,'Watershed plans'!$T$12:$T$19,0)),"")
A7: 2 | B7: =IFERROR(INDEX('Watershed plans'!$G$12:$G$19,MATCH(2,'Watershed plans'!$T$12:$T$19,0)),"") | C7: =IFERROR(INDEX('Watershed plans'!$B$12:$B$19,MATCH(2,'Watershed plans'!$T$12:$T$19,0)),"") | D7: =IFERROR(INDEX('Watershed plans'!$K$12:$K$19,MATCH(2,'Watershed plans'!$T$12:$T$19,0)),"") | E7: =IFERROR(INDEX('Watershed plans'!$L$12:$L$19,MATCH(2,'Watershed plans'!$T$12:$T$19,0)),"") | F7: =IFERROR(INDEX('Watershed plans'!$J$12:$J$19,MATCH(2,'Watershed plans'!$T$12:$T$19,0)),"") | G7: =IFERROR(INDEX('Watershed plans'!$Z$12:$Z$19,MATCH(2,'Watershed plans'!$T$12:$T$19,0)),"") | H7: =IFERROR(INDEX('Watershed plans'!$Y$12:$Y$19,MATCH(2,'Watershed plans'!$T$12:$T$19,0)),"")
A8: 3 | B8: =IFERROR(INDEX('Watershed plans'!$G$12:$G$19,MATCH(3,'Watershed plans'!$T$12:$T$19,0)),"") | C8: =IFERROR(INDEX('Watershed plans'!$B$12:$B$19,MATCH(3,'Watershed plans'!$T$12:$T$19,0)),"") | D8: =IFERROR(INDEX('Watershed plans'!$K$12:$K$19,MATCH(3,'Watershed plans'!$T$12:$T$19,0)),"") | E8: =IFERROR(INDEX('Watershed plans'!$L$12:$L$19,MATCH(3,'Watershed plans'!$T$12:$T$19,0)),"") | F8: =IFERROR(INDEX('Watershed plans'!$J$12:$J$19,MATCH(3,'Watershed plans'!$T$12:$T$19,0)),"") | G8: =IFERROR(INDEX('Watershed plans'!$Z$12:$Z$19,MATCH(3,'Watershed plans'!$T$12:$T$19,0)),"") | H8: =IFERROR(INDEX('Watershed plans'!$Y$12:$Y$19,MATCH(3,'Watershed plans'!$T$12:$T$19,0)),"")
A9: 4 | B9: =IFERROR(INDEX('Watershed plans'!$G$12:$G$19,MATCH(4,'Watershed plans'!$T$12:$T$19,0)),"") | C9: =IFERROR(INDEX('Watershed plans'!$B$12:$B$19,MATCH(4,'Watershed plans'!$T$12:$T$19,0)),"") | D9: =IFERROR(INDEX('Watershed plans'!$K$12:$K$19,MATCH(4,'Watershed plans'!$T$12:$T$19,0)),"") | E9: =IFERROR(INDEX('Watershed plans'!$L$12:$L$19,MATCH(4,'Watershed plans'!$T$12:$T$19,0)),"") | F9: =IFERROR(INDEX('Watershed plans'!$J$12:$J$19,MATCH(4,'Watershed plans'!$T$12:$T$19,0)),"") | G9: =IFERROR(INDEX('Watershed plans'!$Z$12:$Z$19,MATCH(4,'Watershed plans'!$T$12:$T$19,0)),"") | H9: =IFERROR(INDEX('Watershed plans'!$Y$12:$Y$19,MATCH(4,'Watershed plans'!$T$12:$T$19,0)),"")
A10: 5 | B10: =IFERROR(INDEX('Watershed plans'!$G$12:$G$19,MATCH(5,'Watershed plans'!$T$12:$T$19,0)),"") | C10: =IFERROR(INDEX('Watershed plans'!$B$12:$B$19,MATCH(5,'Watershed plans'!$T$12:$T$19,0)),"") | D10: =IFERROR(INDEX('Watershed plans'!$K$12:$K$19,MATCH(5,'Watershed plans'!$T$12:$T$19,0)),"") | E10: =IFERROR(INDEX('Watershed plans'!$L$12:$L$19,MATCH(5,'Watershed plans'!$T$12:$T$19,0)),"") | F10: =IFERROR(INDEX('Watershed plans'!$J$12:$J$19,MATCH(5,'Watershed plans'!$T$12:$T$19,0)),"") | G10: =IFERROR(INDEX('Watershed plans'!$Z$12:$Z$19,MATCH(5,'Watershed plans'!$T$12:$T$19,0)),"") | H10: =IFERROR(INDEX('Watershed plans'!$Y$12:$Y$19,MATCH(5,'Watershed plans'!$T$12:$T$19,0)),"")
A11: 6 | B11: =IFERROR(INDEX('Watershed plans'!$G$12:$G$19,MATCH(6,'Watershed plans'!$T$12:$T$19,0)),"") | C11: =IFERROR(INDEX('Watershed plans'!$B$12:$B$19,MATCH(6,'Watershed plans'!$T$12:$T$19,0)),"") | D11: =IFERROR(INDEX('Watershed plans'!$K$12:$K$19,MATCH(6,'Watershed plans'!$T$12:$T$19,0)),"") | E11: =IFERROR(INDEX('Watershed plans'!$L$12:$L$19,MATCH(6,'Watershed plans'!$T$12:$T$19,0)),"") | F11: =IFERROR(INDEX('Watershed plans'!$J$12:$J$19,MATCH(6,'Watershed plans'!$T$12:$T$19,0)),"") | G11: =IFERROR(INDEX('Watershed plans'!$Z$12:$Z$19,MATCH(6,'Watershed plans'!$T$12:$T$19,0)),"") | H11: =IFERROR(INDEX('Watershed plans'!$Y$12:$Y$19,MATCH(6,'Watershed plans'!$T$12:$T$19,0)),"")
A12: 7 | B12: =IFERROR(INDEX('Watershed plans'!$G$12:$G$19,MATCH(7,'Watershed plans'!$T$12:$T$19,0)),"") | C12: =IFERROR(INDEX('Watershed plans'!$B$12:$B$19,MATCH(7,'Watershed plans'!$T$12:$T$19,0)),"") | D12: =IFERROR(INDEX('Watershed plans'!$K$12:$K$19,MATCH(7,'Watershed plans'!$T$12:$T$19,0)),"") | E12: =IFERROR(INDEX('Watershed plans'!$L$12:$L$19,MATCH(7,'Watershed plans'!$T$12:$T$19,0)),"") | F12: =IFERROR(INDEX('Watershed plans'!$J$12:$J$19,MATCH(7,'Watershed plans'!$T$12:$T$19,0)),"") | G12: =IFERROR(INDEX('Watershed plans'!$Z$12:$Z$19,MATCH(7,'Watershed plans'!$T$12:$T$19,0)),"") | H12: =IFERROR(INDEX('Watershed plans'!$Y$12:$Y$19,MATCH(7,'Watershed plans'!$T$12:$T$19,0)),"")
A13: 8 | B13: =IFERROR(INDEX('Watershed plans'!$G$12:$G$19,MATCH(8,'Watershed plans'!$T$12:$T$19,0)),"") | C13: =IFERROR(INDEX('Watershed plans'!$B$12:$B$19,MATCH(8,'Watershed plans'!$T$12:$T$19,0)),"") | D13: =IFERROR(INDEX('Watershed plans'!$K$12:$K$19,MATCH(8,'Watershed plans'!$T$12:$T$19,0)),"") | E13: =IFERROR(INDEX('Watershed plans'!$L$12:$L$19,MATCH(8,'Watershed plans'!$T$12:$T$19,0)),"") | F13: =IFERROR(INDEX('Watershed plans'!$J$12:$J$19,MATCH(8,'Watershed plans'!$T$12:$T$19,0)),"") | G13: =IFERROR(INDEX('Watershed plans'!$Z$12:$Z$19,MATCH(8,'Watershed plans'!$T$12:$T$19,0)),"") | H13: =IFERROR(INDEX('Watershed plans'!$Y$12:$Y$19,MATCH(8,'Watershed plans'!$T$12:$T$19,0)),"")
A14: 9 | B14: =IFERROR(INDEX('Watershed plans'!$G$12:$G$19,MATCH(9,'Watershed plans'!$T$12:$T$19,0)),"") | C14: =IFERROR(INDEX('Watershed plans'!$B$12:$B$19,MATCH(9,'Watershed plans'!$T$12:$T$19,0)),"") | D14: =IFERROR(INDEX('Watershed plans'!$K$12:$K$19,MATCH(9,'Watershed plans'!$T$12:$T$19,0)),"") | E14: =IFERROR(INDEX('Watershed plans'!$L$12:$L$19,MATCH(9,'Watershed plans'!$T$12:$T$19,0)),"") | F14: =IFERROR(INDEX('Watershed plans'!$J$12:$J$19,MATCH(9,'Watershed plans'!$T$12:$T$19,0)),"") | G14: =IFERROR(INDEX('Watershed plans'!$Z$12:$Z$19,MATCH(9,'Watershed plans'!$T$12:$T$19,0)),"") | H14: =IFERROR(INDEX('Watershed plans'!$Y$12:$Y$19,MATCH(9,'Watershed plans'!$T$12:$T$19,0)),"")
A15: 10 | B15: =IFERROR(INDEX('Watershed plans'!$G$12:$G$19,MATCH(10,'Watershed plans'!$T$12:$T$19,0)),"") | C15: =IFERROR(INDEX('Watershed plans'!$B$12:$B$19,MATCH(10,'Watershed plans'!$T$12:$T$19,0)),"") | D15: =IFERROR(INDEX('Watershed plans'!$K$12:$K$19,MATCH(10,'Watershed plans'!$T$12:$T$19,0)),"") | E15: =IFERROR(INDEX('Watershed plans'!$L$12:$L$19,MATCH(10,'Watershed plans'!$T$12:$T$19,0)),"") | F15: =IFERROR(INDEX('Watershed plans'!$J$12:$J$19,MATCH(10,'Watershed plans'!$T$12:$T$19,0)),"") | G15: =IFERROR(INDEX('Watershed plans'!$Z$12:$Z$19,MATCH(10,'Watershed plans'!$T$12:$T$19,0)),"") | H15: =IFERROR(INDEX('Watershed plans'!$Y$12:$Y$19,MATCH(10,'Watershed plans'!$T$12:$T$19,0)),"")
A16: 11 | B16: =IFERROR(INDEX('Watershed plans'!$G$12:$G$19,MATCH(11,'Watershed plans'!$T$12:$T$19,0)),"") | C16: =IFERROR(INDEX('Watershed plans'!$B$12:$B$19,MATCH(11,'Watershed plans'!$T$12:$T$19,0)),"") | D16: =IFERROR(INDEX('Watershed plans'!$K$12:$K$19,MATCH(11,'Watershed plans'!$T$12:$T$19,0)),"") | E16: =IFERROR(INDEX('Watershed plans'!$L$12:$L$19,MATCH(11,'Watershed plans'!$T$12:$T$19,0)),"") | F16: =IFERROR(INDEX('Watershed plans'!$J$12:$J$19,MATCH(11,'Watershed plans'!$T$12:$T$19,0)),"") | G16: =IFERROR(INDEX('Watershed plans'!$Z$12:$Z$19,MATCH(11,'Watershed plans'!$T$12:$T$19,0)),"") | H16: =IFERROR(INDEX('Watershed plans'!$Y$12:$Y$19,MATCH(11,'Watershed plans'!$T$12:$T$19,0)),"")
A17: 12 | B17: =IFERROR(INDEX('Watershed plans'!$G$12:$G$19,MATCH(12,'Watershed plans'!$T$12:$T$19,0)),"") | C17: =IFERROR(INDEX('Watershed plans'!$B$12:$B$19,MATCH(12,'Watershed plans'!$T$12:$T$19,0)),"") | D17: =IFERROR(INDEX('Watershed plans'!$K$12:$K$19,MATCH(12,'Watershed plans'!$T$12:$T$19,0)),"") | E17: =IFERROR(INDEX('Watershed plans'!$L$12:$L$19,MATCH(12,'Watershed plans'!$T$12:$T$19,0)),"") | F17: =IFERROR(INDEX('Watershed plans'!$J$12:$J$19,MATCH(12,'Watershed plans'!$T$12:$T$19,0)),"") | G17: =IFERROR(INDEX('Watershed plans'!$Z$12:$Z$19,MATCH(12,'Watershed plans'!$T$12:$T$19,0)),"") | H17: =IFERROR(INDEX('Watershed plans'!$Y$12:$Y$19,MATCH(12,'Watershed plans'!$T$12:$T$19,0)),"")
A18: 13 | B18: =IFERROR(INDEX('Watershed plans'!$G$12:$G$19,MATCH(13,'Watershed plans'!$T$12:$T$19,0)),"") | C18: =IFERROR(INDEX('Watershed plans'!$B$12:$B$19,MATCH(13,'Watershed plans'!$T$12:$T$19,0)),"") | D18: =IFERROR(INDEX('Watershed plans'!$K$12:$K$19,MATCH(13,'Watershed plans'!$T$12:$T$19,0)),"") | E18: =IFERROR(INDEX('Watershed plans'!$L$12:$L$19,MATCH(13,'Watershed plans'!$T$12:$T$19,0)),"") | F18: =IFERROR(INDEX('Watershed plans'!$J$12:$J$19,MATCH(13,'Watershed plans'!$T$12:$T$19,0)),"") | G18: =IFERROR(INDEX('Watershed plans'!$Z$12:$Z$19,MATCH(13,'Watershed plans'!$T$12:$T$19,0)),"") | H18: =IFERROR(INDEX('Watershed plans'!$Y$12:$Y$19,MATCH(13,'Watershed plans'!$T$12:$T$19,0)),"")
A19: 14 | B19: =IFERROR(INDEX('Watershed plans'!$G$12:$G$19,MATCH(14,'Watershed plans'!$T$12:$T$19,0)),"") | C19: =IFERROR(INDEX('Watershed plans'!$B$12:$B$19,MATCH(14,'Watershed plans'!$T$12:$T$19,0)),"") | D19: =IFERROR(INDEX('Watershed plans'!$K$12:$K$19,MATCH(14,'Watershed plans'!$T$12:$T$19,0)),"") | E19: =IFERROR(INDEX('Watershed plans'!$L$12:$L$19,MATCH(14,'Watershed plans'!$T$12:$T$19,0)),"") | F19: =IFERROR(INDEX('Watershed plans'!$J$12:$J$19,MATCH(14,'Watershed plans'!$T$12:$T$19,0)),"") | G19: =IFERROR(INDEX('Watershed plans'!$Z$12:$Z$19,MATCH(14,'Watershed plans'!$T$12:$T$19,0)),"") | H19: =IFERROR(INDEX('Watershed plans'!$Y$12:$Y$19,MATCH(14,'Watershed plans'!$T$12:$T$19,0)),"")
A20: 15 | B20: =IFERROR(INDEX('Watershed plans'!$G$12:$G$19,MATCH(15,'Watershed plans'!$T$12:$T$19,0)),"") | C20: =IFERROR(INDEX('Watershed plans'!$B$12:$B$19,MATCH(15,'Watershed plans'!$T$12:$T$19,0)),"") | D20: =IFERROR(INDEX('Watershed plans'!$K$12:$K$19,MATCH(15,'Watershed plans'!$T$12:$T$19,0)),"") | E20: =IFERROR(INDEX('Watershed plans'!$L$12:$L$19,MATCH(15,'Watershed plans'!$T$12:$T$19,0)),"") | F20: =IFERROR(INDEX('Watershed plans'!$J$12:$J$19,MATCH(15,'Watershed plans'!$T$12:$T$19,0)),"") | G20: =IFERROR(INDEX('Watershed plans'!$Z$12:$Z$19,MATCH(15,'Watershed plans'!$T$12:$T$19,0)),"") | H20: =IFERROR(INDEX('Watershed plans'!$Y$12:$Y$19,MATCH(15,'Watershed plans'!$T$12:$T$19,0)),"")
A21: 16 | B21: =IFERROR(INDEX('Watershed plans'!$G$12:$G$19,MATCH(16,'Watershed plans'!$T$12:$T$19,0)),"") | C21: =IFERROR(INDEX('Watershed plans'!$B$12:$B$19,MATCH(16,'Watershed plans'!$T$12:$T$19,0)),"") | D21: =IFERROR(INDEX('Watershed plans'!$K$12:$K$19,MATCH(16,'Watershed plans'!$T$12:$T$19,0)),"") | E21: =IFERROR(INDEX('Watershed plans'!$L$12:$L$19,MATCH(16,'Watershed plans'!$T$12:$T$19,0)),"") | F21: =IFERROR(INDEX('Watershed plans'!$J$12:$J$19,MATCH(16,'Watershed plans'!$T$12:$T$19,0)),"") | G21: =IFERROR(INDEX('Watershed plans'!$Z$12:$Z$19,MATCH(16,'Watershed plans'!$T$12:$T$19,0)),"") | H21: =IFERROR(INDEX('Watershed plans'!$Y$12:$Y$19,MATCH(16,'Watershed plans'!$T$12:$T$19,0)),"")
A22: 17 | B22: =IFERROR(INDEX('Watershed plans'!$G$12:$G$19,MATCH(17,'Watershed plans'!$T$12:$T$19,0)),"") | C22: =IFERROR(INDEX('Watershed plans'!$B$12:$B$19,MATCH(17,'Watershed plans'!$T$12:$T$19,0)),"") | D22: =IFERROR(INDEX('Watershed plans'!$K$12:$K$19,MATCH(17,'Watershed plans'!$T$12:$T$19,0)),"") | E22: =IFERROR(INDEX('Watershed plans'!$L$12:$L$19,MATCH(17,'Watershed plans'!$T$12:$T$19,0)),"") | F22: =IFERROR(INDEX('Watershed plans'!$J$12:$J$19,MATCH(17,'Watershed plans'!$T$12:$T$19,0)),"") | G22: =IFERROR(INDEX('Watershed plans'!$Z$12:$Z$19,MATCH(17,'Watershed plans'!$T$12:$T$19,0)),"") | H22: =IFERROR(INDEX('Watershed plans'!$Y$12:$Y$19,MATCH(17,'Watershed plans'!$T$12:$T$19,0)),"")
A23: 18 | B23: =IFERROR(INDEX('Watershed plans'!$G$12:$G$19,MATCH(18,'Watershed plans'!$T$12:$T$19,0)),"") | C23: =IFERROR(INDEX('Watershed plans'!$B$12:$B$19,MATCH(18,'Watershed plans'!$T$12:$T$19,0)),"") | D23: =IFERROR(INDEX('Watershed plans'!$K$12:$K$19,MATCH(18,'Watershed plans'!$T$12:$T$19,0)),"") | E23: =IFERROR(INDEX('Watershed plans'!$L$12:$L$19,MATCH(18,'Watershed plans'!$T$12:$T$19,0)),"") | F23: =IFERROR(INDEX('Watershed plans'!$J$12:$J$19,MATCH(18,'Watershed plans'!$T$12:$T$19,0)),"") | G23: =IFERROR(INDEX('Watershed plans'!$Z$12:$Z$19,MATCH(18,'Watershed plans'!$T$12:$T$19,0)),"") | H23: =IFERROR(INDEX('Watershed plans'!$Y$12:$Y$19,MATCH(18,'Watershed plans'!$T$12:$T$19,0)),"")
A24: 19 | B24: =IFERROR(INDEX('Watershed plans'!$G$12:$G$19,MATCH(19,'Watershed plans'!$T$12:$T$19,0)),"") | C24: =IFERROR(INDEX('Watershed plans'!$B$12:$B$19,MATCH(19,'Watershed plans'!$T$12:$T$19,0)),"") | D24: =IFERROR(INDEX('Watershed plans'!$K$12:$K$19,MATCH(19,'Watershed plans'!$T$12:$T$19,0)),"") | E24: =IFERROR(INDEX('Watershed plans'!$L$12:$L$19,MATCH(19,'Watershed plans'!$T$12:$T$19,0)),"") | F24: =IFERROR(INDEX('Watershed plans'!$J$12:$J$19,MATCH(19,'Watershed plans'!$T$12:$T$19,0)),"") | G24: =IFERROR(INDEX('Watershed plans'!$Z$12:$Z$19,MATCH(19,'Watershed plans'!$T$12:$T$19,0)),"") | H24: =IFERROR(INDEX('Watershed plans'!$Y$12:$Y$19,MATCH(19,'Watershed plans'!$T$12:$T$19,0)),"")
A25: 20 | B25: =IFERROR(INDEX('Watershed plans'!$G$12:$G$19,MATCH(20,'Watershed plans'!$T$12:$T$19,0)),"") | C25: =IFERROR(INDEX('Watershed plans'!$B$12:$B$19,MATCH(20,'Watershed plans'!$T$12:$T$19,0)),"") | D25: =IFERROR(INDEX('Watershed plans'!$K$12:$K$19,MATCH(20,'Watershed plans'!$T$12:$T$19,0)),"") | E25: =IFERROR(INDEX('Watershed plans'!$L$12:$L$19,MATCH(20,'Watershed plans'!$T$12:$T$19,0)),"") | F25: =IFERROR(INDEX('Watershed plans'!$J$12:$J$19,MATCH(20,'Watershed plans'!$T$12:$T$19,0)),"") | G25: =IFERROR(INDEX('Watershed plans'!$Z$12:$Z$19,MATCH(20,'Watershed plans'!$T$12:$T$19,0)),"") | H25: =IFERROR(INDEX('Watershed plans'!$Y$12:$Y$19,MATCH(20,'Watershed plans'!$T$12:$T$19,0)),"")
